Workbook
Name TRANSMUTATION_TABLE: 'DO NOT DELETE'!$G$2:$J$42

Sheet INPUT DATA
A1: Input Data Sheet for E-Class Record
C4: REGION | G4: III | L4: DIVISION | O4: CITY OF SAN FDO. | T4: DISTRICT | X4: NORTH
B5: SCHOOL NAME | G5: TELABASTAGAN INTEGRATED SCHOOL | T5: SCHOOL ID | X5: 500144 | AD5: SCHOOL YEAR | AG5: 2025-2026
F7: GRADE & SECTION: | K7: IV-RIZAL | Q7: TEACHER: | S7: ADELIA M. MANARANG | AC7: SUBJECT: | AG7: GMRC
B8: LEARNERS' NAMES
B11: MALE
A12: 1 | B12: Aranquez, Elemerson Jacob Quito | D12: 0 | E12: 0
A13: 2 | B13: Bautisa, France Kiel Lacon | D13: 0 | E13: 0
A14: 3 | B14: Candelario, Nylan Esto | D14: 0 | E14: 0
A15: 4 | B15: Dalangin, Lorenz Salvador | D15: 0 | E15: 0
A16: 5 | B16: De Jesus, Benjamin Tyga Liscano | D16: 0 | E16: 0
A17: 6 | B17: Cortez, Xyron Credo
A18: 7 | B18: Garong Shemuelle Jones L.
A19: 8 | B19: Gonzales, Hadrian Consulta
A20: 9 | B20: Mabana, Terrence Navarro
A21: 10 | B21: Mangao, John Carlo Tarroza
A22: 11 | B22: Manuel, Mathias Manzanes
A23: 12 | B23: Pleno, James Andrei Dizon
A24: 13 | B24: Reyes, Brionne Ysmael
A25: 14 | B25: Rosales, John Mc Brandon Patubo
A26: 15 | B26: Rosales, Jhon Vinvie Felicidad
A27: 16 | B27: Tolentino, John Noel Cabrera
A28: 17 | B28: Traya, John Romeo Villanueva
... A30: 19 | B30: Pangilinan, David Dweyn
A31: 20
A32: 21
A33: 22
A34: 23
A35: 24
A36: 25
A37: 26
A38: 27
A39: 28
A40: 29
A41: 30
A42: 31
... A61: 50
A63: 1 | B63: Boiser, Janiella Dampil
A64: 2 | B64: Buan, Zia Tolentino
A65: 3 | B65: Cordon, Haven Joy Sevilla
...

Sheet GMRC Q1
A1: Official E-Class Record in K to 12 Curriculum
C4: REGION | G4: ='INPUT DATA'!G4 -> III | L4: DIVISION | O4: ='INPUT DATA'!O4 -> CITY OF SAN FDO. | T4: DISTRICT | X4: ='INPUT DATA'!X4 -> NORTH
B5: SCHOOL NAME | G5: ='INPUT DATA'!G5 -> TELABASTAGAN INTEGRATED SCHOOL | T5: SCHOOL ID | X5: ='INPUT DATA'!X5 -> 500144 | AD5: SCHOOL YEAR | AG5: ='INPUT DATA'!AG5 -> 2025-2026
A7: FIRST QUARTER | F7: GRADE & SECTION: | K7: ='INPUT DATA'!K7 -> IV-RIZAL | Q7: TEACHER: | S7: ='INPUT DATA'!S7 -> ADELIA M. MANARANG | AC7: SUBJECT: | AG7: ='INPUT DATA'!AG7 -> GMRC
B8: LEARNERS' NAMES | F8: WRITTEN WORKS (20%) | S8: PERFORMANCE TASKS (60%) | AF8: QUARTERLY ASSESSMENT (20%) | AI8: Initial | AJ8: Quarterly
F9: 1 | G9: 2 | H9: 3 | I9: 4 | J9: 5 | K9: 6 | L9: 7 | M9: 8 | N9: 9 | O9: 10 | P9: Total | Q9: PS | R9: WS | S9: 1 | T9: 2 | U9: 3 | V9: 4 | W9: 5 | X9: 6 | Y9: 7 | Z9: 8 | AA9: 9 | AB9: 10 | AC9: Total | AD9: PS | AE9: WS | AF9: 1 | AG9: PS | AH9: WS | AI9: Grade | AJ9: Grade
B10: HIGHEST POSSIBLE SCORE | F10: 10 | G10: 10 | H10: 10 | I10: 10 | J10: 10 | K10: 20 | P10: =IF(COUNT($F10:$O10)=0,"",SUM($F10:$O10)) -> 70 | Q10: 100 | R10: 0.2 | S10: 10 | T10: 20 | U10: 10 | V10: 20 | W10: 10 | X10: 10 | AC10: =IF(COUNT($S10:$AB10)=0,"",SUM($S10:$AB10)) -> 80 | AD10: 100 | AE10: 0.6 | AF10: 40 | AG10: 100 | AH10: 0.2
B11: MALE
A12: 1 | B12: ='INPUT DATA'!B12 -> Aranquez, Elemerson Jacob Quito | F12: 8 | G12: 6 | H12: 9 | I12: 9 | J12: 10 | K12: 17 | P12: =IF(COUNT($F12:$O12)=0,"",SUM($F12:$O12)) -> 59 | Q12: =IF(ISERROR(IF($P12="","",ROUND(($P12/$P$10)*$Q$10,2))),"",IF($P12="","",ROUND(($P12/$P$10)*$Q$10,2))) -> 84.29 | R12: =IF($Q12="","",ROUND($Q12*$R$10,2)) -> 16.86 | S12: 9 | T12: 5 | U12: 9 | V12: 18 | W12: 8 | X12: 10 | AC12: =IF(COUNT($S12:$AB12)=0,"",SUM($S12:$AB12)) -> 59 | AD12: =IF(ISERROR(IF($AC12="","",ROUND(($AC12/$AC$10)*$AD$10,2))),"",IF($AC12="","",ROUND(($AC12/$AC$10)*$AD$10,2))) -> 73.75 | AE12: =IF($AD12="","",ROUND($AD12*$AE$10,2)) -> 44.25 | AF12: 27 | AG12: =IF(ISERROR(IF($AF12="","",ROUND(($AF12/$AF$10)*$AG$10,2))),"",IF($AF12="","",ROUND(($AF12/$AF$10)*$AG$10,2))) -> 67.5 | AH12: =IF($AG12="","",ROUND($AG12*$AH$10,2)) -> 13.5 | AI12: =IF(ISERROR(IF($AF12="","",ROUND(SUM($R12,$AE12,$AH12),2))),"",IF($AF12="","",ROUND(SUM($R12,$AE12,$AH12),2))) -> 74.61 | AJ12: =IF(ISERROR(IF($AF12="","",VLOOKUP(AI12,TRANSMUTATION_TABLE,4,TRUE))),"",IF($AF12="","",VLOOKUP(AI12,TRANSMUTATION_TABLE,4,TRUE))) -> 84
A13: 2 | B13: ='INPUT DATA'!B13 -> Bautisa, France Kiel Lacon | F13: 9 | G13: 8 | H13: 10 | I13: 10 | J13: 10 | K13: 5 | P13: =IF(COUNT($F13:$O13)=0,"",SUM($F13:$O13)) -> 52 | Q13: =IF(ISERROR(IF($P13="","",ROUND(($P13/$P$10)*$Q$10,2))),"",IF($P13="","",ROUND(($P13/$P$10)*$Q$10,2))) -> 74.29 | R13: =IF($Q13="","",ROUND($Q13*$R$10,2)) -> 14.86 | S13: 8 | T13: 10 | U13: 9 | V13: 18 | W13: 10 | X13: 9 | AC13: =IF(COUNT($S13:$AB13)=0,"",SUM($S13:$AB13)) -> 64 | AD13: =IF(ISERROR(IF($AC13="","",ROUND(($AC13/$AC$10)*$AD$10,2))),"",IF($AC13="","",ROUND(($AC13/$AC$10)*$AD$10,2))) -> 80 | AE13: =IF($AD13="","",ROUND($AD13*$AE$10,2)) -> 48 | AF13: 11 | AG13: =IF(ISERROR(IF($AF13="","",ROUND(($AF13/$AF$10)*$AG$10,2))),"",IF($AF13="","",ROUND(($AF13/$AF$10)*$AG$10,2))) -> 27.5 | AH13: =IF($AG13="","",ROUND($AG13*$AH$10,2)) -> 5.5 | AI13: =IF(ISERROR(IF($AF13="","",ROUND(SUM($R13,$AE13,$AH13),2))),"",IF($AF13="","",ROUND(SUM($R13,$AE13,$AH13),2))) -> 68.36 | AJ13: =IF(ISERROR(IF($AF13="","",VLOOKUP(AI13,TRANSMUTATION_TABLE,4,TRUE))),"",IF($AF13="","",VLOOKUP(AI13,TRANSMUTATION_TABLE,4,TRUE))) -> 80
A14: 3 | B14: ='INPUT DATA'!B14 -> Candelario, Nylan Esto | F14: 8 | G14: 10 | H14: 8 | I14: 8 | J14: 10 | K14: 20 | P14: =IF(COUNT($F14:$O14)=0,"",SUM($F14:$O14)) -> 64 | Q14: =IF(ISERROR(IF($P14="","",ROUND(($P14/$P$10)*$Q$10,2))),"",IF($P14="","",ROUND(($P14/$P$10)*$Q$10,2))) -> 91.43 | R14: =IF($Q14="","",ROUND($Q14*$R$10,2)) -> 18.29 | S14: 7 | T14: 20 | U14: 9 | V14: 14 | W14: 9 | X14: 10 | AC14: =IF(COUNT($S14:$AB14)=0,"",SUM($S14:$AB14)) -> 69 | AD14: =IF(ISERROR(IF($AC14="","",ROUND(($AC14/$AC$10)*$AD$10,2))),"",IF($AC14="","",ROUND(($AC14/$AC$10)*$AD$10,2))) -> 86.25 | AE14: =IF($AD14="","",ROUND($AD14*$AE$10,2)) -> 51.75 | AF14: 29 | AG14: =IF(ISERROR(IF($AF14="","",ROUND(($AF14/$AF$10)*$AG$10,2))),"",IF($AF14="","",ROUND(($AF14/$AF$10)*$AG$10,2))) -> 72.5 | AH14: =IF($AG14="","",ROUND($AG14*$AH$10,2)) -> 14.5 | AI14: =IF(ISERROR(IF($AF14="","",ROUND(SUM($R14,$AE14,$AH14),2))),"",IF($AF14="","",ROUND(SUM($R14,$AE14,$AH14),2))) -> 84.54 | AJ14: =IF(ISERROR(IF($AF14="","",VLOOKUP(AI14,TRANSMUTATION_TABLE,4,TRUE))),"",IF($AF14="","",VLOOKUP(AI14,TRANSMUTATION_TABLE,4,TRUE))) -> 90
A15: 4 | B15: ='INPUT DATA'!B15 -> Dalangin, Lorenz Salvador | F15: 7 | G15: 9 | H15: 7 | I15: 9 | J15: 10 | K15: 19 | P15: =IF(COUNT($F15:$O15)=0,"",SUM($F15:$O15)) -> 61 | Q15: =IF(ISERROR(IF($P15="","",ROUND(($P15/$P$10)*$Q$10,2))),"",IF($P15="","",ROUND(($P15/$P$10)*$Q$10,2))) -> 87.14 | R15: =IF($Q15="","",ROUND($Q15*$R$10,2)) -> 17.43 | S15: 8 | T15: 20 | U15: 8 | V15: 20 | W15: 9 | X15: 10 | AC15: =IF(COUNT($S15:$AB15)=0,"",SUM($S15:$AB15)) -> 75 | AD15: =IF(ISERROR(IF($AC15="","",ROUND(($AC15/$AC$10)*$AD$10,2))),"",IF($AC15="","",ROUND(($AC15/$AC$10)*$AD$10,2))) -> 93.75 | AE15: =IF($AD15="","",ROUND($AD15*$AE$10,2)) -> 56.25 | AF15: 17 | AG15: =IF(ISERROR(IF($AF15="","",ROUND(($AF15/$AF$10)*$AG$10,2))),"",IF($AF15="","",ROUND(($AF15/$AF$10)*$AG$10,2))) -> 42.5 | AH15: =IF($AG15="","",ROUND($AG15*$AH$10,2)) -> 8.5 | AI15: =IF(ISERROR(IF($AF15="","",ROUND(SUM($R15,$AE15,$AH15),2))),"",IF($AF15="","",ROUND(SUM($R15,$AE15,$AH15),2))) -> 82.18 | AJ15: =IF(ISERROR(IF($AF15="","",VLOOKUP(AI15,TRANSMUTATION_TABLE,4,TRUE))),"",IF($AF15="","",VLOOKUP(AI15,TRANSMUTATION_TABLE,4,TRUE))) -> 88
A16: 5 | B16: ='INPUT DATA'!B16 -> De Jesus, Benjamin Tyga Liscano | F16: 8 | G16: 10 | H16: 2 | I16: 8 | J16: 10 | K16: 20 | P16: =IF(COUNT($F16:$O16)=0,"",SUM($F16:$O16)) -> 58 | Q16: =IF(ISERROR(IF($P16="","",ROUND(($P16/$P$10)*$Q$10,2))),"",IF($P16="","",ROUND(($P16/$P$10)*$Q$10,2))) -> 82.86 | R16: =IF($Q16="","",ROUND($Q16*$R$10,2)) -> 16.57 | S16: 7 | T16: 10 | U16: 9 | V16: 14 | W16: 7 | X16: 5 | AC16: =IF(COUNT($S16:$AB16)=0,"",SUM($S16:$AB16)) -> 52 | AD16: =IF(ISERROR(IF($AC16="","",ROUND(($AC16/$AC$10)*$AD$10,2))),"",IF($AC16="","",ROUND(($AC16/$AC$10)*$AD$10,2))) -> 65 | AE16: =IF($AD16="","",ROUND($AD16*$AE$10,2)) -> 39 | AF16: 17 | AG16: =IF(ISERROR(IF($AF16="","",ROUND(($AF16/$AF$10)*$AG$10,2))),"",IF($AF16="","",ROUND(($AF16/$AF$10)*$AG$10,2))) -> 42.5 | AH16: =IF($AG16="","",ROUND($AG16*$AH$10,2)) -> 8.5 | AI16: =IF(ISERROR(IF($AF16="","",ROUND(SUM($R16,$AE16,$AH16),2))),"",IF($AF16="","",ROUND(SUM($R16,$AE16,$AH16),2))) -> 64.07 | AJ16: =IF(ISERROR(IF($AF16="","",VLOOKUP(AI16,TRANSMUTATION_TABLE,4,TRUE))),"",IF($AF16="","",VLOOKUP(AI16,TRANSMUTATION_TABLE,4,TRUE))) -> 77
A17: 6 | B17: ='INPUT DATA'!B17 -> Cortez, Xyron Credo | F17: 8 | G17: 10 | H17: 8 | I17: 9 | J17: 9 | K17: 19 | P17: =IF(COUNT($F17:$O17)=0,"",SUM($F17:$O17)) -> 63 | Q17: =IF(ISERROR(IF($P17="","",ROUND(($P17/$P$10)*$Q$10,2))),"",IF($P17="","",ROUND(($P17/$P$10)*$Q$10,2))) -> 90 | R17: =IF($Q17="","",ROUND($Q17*$R$10,2)) -> 18 | S17: 9 | T17: 20 | U17: 9 | V17: 20 | W17: 9 | X17: 7 | AC17: =IF(COUNT($S17:$AB17)=0,"",SUM($S17:$AB17)) -> 74 | AD17: =IF(ISERROR(IF($AC17="","",ROUND(($AC17/$AC$10)*$AD$10,2))),"",IF($AC17="","",ROUND(($AC17/$AC$10)*$AD$10,2))) -> 92.5 | AE17: =IF($AD17="","",ROUND($AD17*$AE$10,2)) -> 55.5 | AF17: 21 | AG17: =IF(ISERROR(IF($AF17="","",ROUND(($AF17/$AF$10)*$AG$10,2))),"",IF($AF17="","",ROUND(($AF17/$AF$10)*$AG$10,2))) -> 52.5 | AH17: =IF($AG17="","",ROUND($AG17*$AH$10,2)) -> 10.5 | AI17: =IF(ISERROR(IF($AF17="","",ROUND(SUM($R17,$AE17,$AH17),2))),"",IF($AF17="","",ROUND(SUM($R17,$AE17,$AH17),2))) -> 84 | AJ17: =IF(ISERROR(IF($AF17="","",VLOOKUP(AI17,TRANSMUTATION_TABLE,4,TRUE))),"",IF($AF17="","",VLOOKUP(AI17,TRANSMUTATION_TABLE,4,TRUE))) -> 90
A18: 7 | B18: ='INPUT DATA'!B18 -> Garong Shemuelle Jones L. | F18: 9 | G18: 9 | H18: 10 | I18: 8 | J18: 9 | K18: 19 | P18: =IF(COUNT($F18:$O18)=0,"",SUM($F18:$O18)) -> 64 | Q18: =IF(ISERROR(IF($P18="","",ROUND(($P18/$P$10)*$Q$10,2))),"",IF($P18="","",ROUND(($P18/$P$10)*$Q$10,2))) -> 91.43 | R18: =IF($Q18="","",ROUND($Q18*$R$10,2)) -> 18.29 | S18: 8 | T18: 20 | U18: 8 | V18: 20 | W18: 7 | X18: 6 | AC18: =IF(COUNT($S18:$AB18)=0,"",SUM($S18:$AB18)) -> 69 | AD18: =IF(ISERROR(IF($AC18="","",ROUND(($AC18/$AC$10)*$AD$10,2))),"",IF($AC18="","",ROUND(($AC18/$AC$10)*$AD$10,2))) -> 86.25 | AE18: =IF($AD18="","",ROUND($AD18*$AE$10,2)) -> 51.75 | AF18: 26 | AG18: =IF(ISERROR(IF($AF18="","",ROUND(($AF18/$AF$10)*$AG$10,2))),"",IF($AF18="","",ROUND(($AF18/$AF$10)*$AG$10,2))) -> 65 | AH18: =IF($AG18="","",ROUND($AG18*$AH$10,2)) -> 13 | AI18: =IF(ISERROR(IF($AF18="","",ROUND(SUM($R18,$AE18,$AH18),2))),"",IF($AF18="","",ROUND(SUM($R18,$AE18,$AH18),2))) -> 83.04 | AJ18: =IF(ISERROR(IF($AF18="","",VLOOKUP(AI18,TRANSMUTATION_TABLE,4,TRUE))),"",IF($AF18="","",VLOOKUP(AI18,TRANSMUTATION_TABLE,4,TRUE))) -> 89
A19: 8 | B19: ='INPUT DATA'!B19 -> Gonzales, Hadrian Consulta | D19: 0 | F19: 9 | G19: 8 | H19: 8 | I19: 9 | J19: 10 | K19: 18 | P19: =IF(COUNT($F19:$O19)=0,"",SUM($F19:$O19)) -> 62 | Q19: =IF(ISERROR(IF($P19="","",ROUND(($P19/$P$10)*$Q$10,2))),"",IF($P19="","",ROUND(($P19/$P$10)*$Q$10,2))) -> 88.57 | R19: =IF($Q19="","",ROUND($Q19*$R$10,2)) -> 17.71 | S19: 9 | T19: 10 | U19: 9 | V19: 15 | W19: 10 | X19: 8 | AC19: =IF(COUNT($S19:$AB19)=0,"",SUM($S19:$AB19)) -> 61 | AD19: =IF(ISERROR(IF($AC19="","",ROUND(($AC19/$AC$10)*$AD$10,2))),"",IF($AC19="","",ROUND(($AC19/$AC$10)*$AD$10,2))) -> 76.25 | AE19: =IF($AD19="","",ROUND($AD19*$AE$10,2)) -> 45.75 | AF19: 25 | AG19: =IF(ISERROR(IF($AF19="","",ROUND(($AF19/$AF$10)*$AG$10,2))),"",IF($AF19="","",ROUND(($AF19/$AF$10)*$AG$10,2))) -> 62.5 | AH19: =IF($AG19="","",ROUND($AG19*$AH$10,2)) -> 12.5 | AI19: =IF(ISERROR(IF($AF19="","",ROUND(SUM($R19,$AE19,$AH19),2))),"",IF($AF19="","",ROUND(SUM($R19,$AE19,$AH19),2))) -> 75.96 | AJ19: =IF(ISERROR(IF($AF19="","",VLOOKUP(AI19,TRANSMUTATION_TABLE,4,TRUE))),"",IF($AF19="","",VLOOKUP(AI19,TRANSMUTATION_TABLE,4,TRUE))) -> 84
A20: 9 | B20: ='INPUT DATA'!B20 -> Mabana, Terrence Navarro | F20: 8 | G20: 10 | H20: 4 | I20: 8 | J20: 10 | K20: 17 | P20: =IF(COUNT($F20:$O20)=0,"",SUM($F20:$O20)) -> 57 | Q20: =IF(ISERROR(IF($P20="","",ROUND(($P20/$P$10)*$Q$10,2))),"",IF($P20="","",ROUND(($P20/$P$10)*$Q$10,2))) -> 81.43 | R20: =IF($Q20="","",ROUND($Q20*$R$10,2)) -> 16.29 | S20: 6 | T20: 15 | U20: 6 | V20: 18 | W20: 6 | X20: 9 | AC20: =IF(COUNT($S20:$AB20)=0,"",SUM($S20:$AB20)) -> 60 | AD20: =IF(ISERROR(IF($AC20="","",ROUND(($AC20/$AC$10)*$AD$10,2))),"",IF($AC20="","",ROUND(($AC20/$AC$10)*$AD$10,2))) -> 75 | AE20: =IF($AD20="","",ROUND($AD20*$AE$10,2)) -> 45 | AF20: 34 | AG20: =IF(ISERROR(IF($AF20="","",ROUND(($AF20/$AF$10)*$AG$10,2))),"",IF($AF20="","",ROUND(($AF20/$AF$10)*$AG$10,2))) -> 85 | AH20: =IF($AG20="","",ROUND($AG20*$AH$10,2)) -> 17 | AI20: =IF(ISERROR(IF($AF20="","",ROUND(SUM($R20,$AE20,$AH20),2))),"",IF($AF20="","",ROUND(SUM($R20,$AE20,$AH20),2))) -> 78.29 | AJ20: =IF(ISERROR(IF($AF20="","",VLOOKUP(AI20,TRANSMUTATION_TABLE,4,TRUE))),"",IF($AF20="","",VLOOKUP(AI20,TRANSMUTATION_TABLE,4,TRUE))) -> 86
A21: 10 | B21: ='INPUT DATA'!B21 -> Mangao, John Carlo Tarroza | F21: 9 | G21: 9 | H21: 8 | I21: 7 | J21: 10 | K21: 5 | P21: =IF(COUNT($F21:$O21)=0,"",SUM($F21:$O21)) -> 48 | Q21: =IF(ISERROR(IF($P21="","",ROUND(($P21/$P$10)*$Q$10,2))),"",IF($P21="","",ROUND(($P21/$P$10)*$Q$10,2))) -> 68.57 | R21: =IF($Q21="","",ROUND($Q21*$R$10,2)) -> 13.71 | S21: 9 | T21: 15 | U21: 6 | V21: 13 | W21: 7 | X21: 5 | AC21: =IF(COUNT($S21:$AB21)=0,"",SUM($S21:$AB21)) -> 55 | AD21: =IF(ISERROR(IF($AC21="","",ROUND(($AC21/$AC$10)*$AD$10,2))),"",IF($AC21="","",ROUND(($AC21/$AC$10)*$AD$10,2))) -> 68.75 | AE21: =IF($AD21="","",ROUND($AD21*$AE$10,2)) -> 41.25 | AF21: 21 | AG21: =IF(ISERROR(IF($AF21="","",ROUND(($AF21/$AF$10)*$AG$10,2))),"",IF($AF21="","",ROUND(($AF21/$AF$10)*$AG$10,2))) -> 52.5 | AH21: =IF($AG21="","",ROUND($AG21*$AH$10,2)) -> 10.5 | AI21: =IF(ISERROR(IF($AF21="","",ROUND(SUM($R21,$AE21,$AH21),2))),"",IF($AF21="","",ROUND(SUM($R21,$AE21,$AH21),2))) -> 65.46 | AJ21: =IF(ISERROR(IF($AF21="","",VLOOKUP(AI21,TRANSMUTATION_TABLE,4,TRUE))),"",IF($AF21="","",VLOOKUP(AI21,TRANSMUTATION_TABLE,4,TRUE))) -> 78
A22: 11 | B22: ='INPUT DATA'!B22 -> Manuel, Mathias Manzanes | D22: 0 | F22: 9 | G22: 2 | H22: 10 | I22: 7 | J22: 10 | K22: 18 | P22: =IF(COUNT($F22:$O22)=0,"",SUM($F22:$O22)) -> 56 | Q22: =IF(ISERROR(IF($P22="","",ROUND(($P22/$P$10)*$Q$10,2))),"",IF($P22="","",ROUND(($P22/$P$10)*$Q$10,2))) -> 80 | R22: =IF($Q22="","",ROUND($Q22*$R$10,2)) -> 16 | S22: 8 | T22: 10 | U22: 9 | V22: 15 | W22: 6 | X22: 8 | AC22: =IF(COUNT($S22:$AB22)=0,"",SUM($S22:$AB22)) -> 56 | AD22: =IF(ISERROR(IF($AC22="","",ROUND(($AC22/$AC$10)*$AD$10,2))),"",IF($AC22="","",ROUND(($AC22/$AC$10)*$AD$10,2))) -> 70 | AE22: =IF($AD22="","",ROUND($AD22*$AE$10,2)) -> 42 | AF22: 24 | AG22: =IF(ISERROR(IF($AF22="","",ROUND(($AF22/$AF$10)*$AG$10,2))),"",IF($AF22="","",ROUND(($AF22/$AF$10)*$AG$10,2))) -> 60 | AH22: =IF($AG22="","",ROUND($AG22*$AH$10,2)) -> 12 | AI22: =IF(ISERROR(IF($AF22="","",ROUND(SUM($R22,$AE22,$AH22),2))),"",IF($AF22="","",ROUND(SUM($R22,$AE22,$AH22),2))) -> 70 | AJ22: =IF(ISERROR(IF($AF22="","",VLOOKUP(AI22,TRANSMUTATION_TABLE,4,TRUE))),"",IF($AF22="","",VLOOKUP(AI22,TRANSMUTATION_TABLE,4,TRUE))) -> 81
A23: 12 | B23: ='INPUT DATA'!B23 -> Pleno, James Andrei Dizon | F23: 8 | G23: 9 | H23: 6 | I23: 8 | J23: 9 | K23: 18 | P23: =IF(COUNT($F23:$O23)=0,"",SUM($F23:$O23)) -> 58 | Q23: =IF(ISERROR(IF($P23="","",ROUND(($P23/$P$10)*$Q$10,2))),"",IF($P23="","",ROUND(($P23/$P$10)*$Q$10,2))) -> 82.86 | R23: =IF($Q23="","",ROUND($Q23*$R$10,2)) -> 16.57 | S23: 9 | T23: 20 | U23: 8 | V23: 20 | W23: 7 | X23: 8 | AC23: =IF(COUNT($S23:$AB23)=0,"",SUM($S23:$AB23)) -> 72 | AD23: =IF(ISERROR(IF($AC23="","",ROUND(($AC23/$AC$10)*$AD$10,2))),"",IF($AC23="","",ROUND(($AC23/$AC$10)*$AD$10,2))) -> 90 | AE23: =IF($AD23="","",ROUND($AD23*$AE$10,2)) -> 54 | AF23: 20 | AG23: =IF(ISERROR(IF($AF23="","",ROUND(($AF23/$AF$10)*$AG$10,2))),"",IF($AF23="","",ROUND(($AF23/$AF$10)*$AG$10,2))) -> 50 | AH23: =IF($AG23="","",ROUND($AG23*$AH$10,2)) -> 10 | AI23: =IF(ISERROR(IF($AF23="","",ROUND(SUM($R23,$AE23,$AH23),2))),"",IF($AF23="","",ROUND(SUM($R23,$AE23,$AH23),2))) -> 80.57 | AJ23: =IF(ISERROR(IF($AF23="","",VLOOKUP(AI23,TRANSMUTATION_TABLE,4,TRUE))),"",IF($AF23="","",VLOOKUP(AI23,TRANSMUTATION_TABLE,4,TRUE))) -> 87
A24: 13 | B24: ='INPUT DATA'!B24 -> Reyes, Brionne Ysmael | F24: 9 | G24: 10 | H24: 8 | I24: 8 | J24: 9 | K24: 20 | P24: =IF(COUNT($F24:$O24)=0,"",SUM($F24:$O24)) -> 64 | Q24: =IF(ISERROR(IF($P24="","",ROUND(($P24/$P$10)*$Q$10,2))),"",IF($P24="","",ROUND(($P24/$P$10)*$Q$10,2))) -> 91.43 | R24: =IF($Q24="","",ROUND($Q24*$R$10,2)) -> 18.29 | S24: 8 | T24: 10 | U24: 9 | V24: 19 | W24: 9 | X24: 8 | AC24: =IF(COUNT($S24:$AB24)=0,"",SUM($S24:$AB24)) -> 63 | AD24: =IF(ISERROR(IF($AC24="","",ROUND(($AC24/$AC$10)*$AD$10,2))),"",IF($AC24="","",ROUND(($AC24/$AC$10)*$AD$10,2))) -> 78.75 | AE24: =IF($AD24="","",ROUND($AD24*$AE$10,2)) -> 47.25 | AF24: 20 | AG24: =IF(ISERROR(IF($AF24="","",ROUND(($AF24/$AF$10)*$AG$10,2))),"",IF($AF24="","",ROUND(($AF24/$AF$10)*$AG$10,2))) -> 50 | AH24: =IF($AG24="","",ROUND($AG24*$AH$10,2)) -> 10 | AI24: =IF(ISERROR(IF($AF24="","",ROUND(SUM($R24,$AE24,$AH24),2))),"",IF($AF24="","",ROUND(SUM($R24,$AE24,$AH24),2))) -> 75.54 | AJ24: =IF(ISERROR(IF($AF24="","",VLOOKUP(AI24,TRANSMUTATION_TABLE,4,TRUE))),"",IF($AF24="","",VLOOKUP(AI24,TRANSMUTATION_TABLE,4,TRUE))) -> 84
A25: 14 | B25: ='INPUT DATA'!B25 -> Rosales, John Mc Brandon Patubo | F25: 8 | G25: 8 | H25: 2 | I25: 7 | J25: 10 | K25: 5 | P25: =IF(COUNT($F25:$O25)=0,"",SUM($F25:$O25)) -> 40 | Q25: =IF(ISERROR(IF($P25="","",ROUND(($P25/$P$10)*$Q$10,2))),"",IF($P25="","",ROUND(($P25/$P$10)*$Q$10,2))) -> 57.14 | R25: =IF($Q25="","",ROUND($Q25*$R$10,2)) -> 11.43 | S25: 10 | T25: 18 | U25: 8 | V25: 20 | W25: 10 | X25: 10 | AC25: =IF(COUNT($S25:$AB25)=0,"",SUM($S25:$AB25)) -> 76 | AD25: =IF(ISERROR(IF($AC25="","",ROUND(($AC25/$AC$10)*$AD$10,2))),"",IF($AC25="","",ROUND(($AC25/$AC$10)*$AD$10,2))) -> 95 | AE25: =IF($AD25="","",ROUND($AD25*$AE$10,2)) -> 57 | AF25: 25 | AG25: =IF(ISERROR(IF($AF25="","",ROUND(($AF25/$AF$10)*$AG$10,2))),"",IF($AF25="","",ROUND(($AF25/$AF$10)*$AG$10,2))) -> 62.5 | AH25: =IF($AG25="","",ROUND($AG25*$AH$10,2)) -> 12.5 | AI25: =IF(ISERROR(IF($AF25="","",ROUND(SUM($R25,$AE25,$AH25),2))),"",IF($AF25="","",ROUND(SUM($R25,$AE25,$AH25),2))) -> 80.93 | AJ25: =IF(ISERROR(IF($AF25="","",VLOOKUP(AI25,TRANSMUTATION_TABLE,4,TRUE))),"",IF($AF25="","",VLOOKUP(AI25,TRANSMUTATION_TABLE,4,TRUE))) -> 88
A26: 15 | B26: ='INPUT DATA'!B26 -> Rosales, Jhon Vinvie Felicidad | F26: 9 | G26: 8 | H26: 10 | I26: 8 | J26: 10 | K26: 17 | P26: =IF(COUNT($F26:$O26)=0,"",SUM($F26:$O26)) -> 62 | Q26: =IF(ISERROR(IF($P26="","",ROUND(($P26/$P$10)*$Q$10,2))),"",IF($P26="","",ROUND(($P26/$P$10)*$Q$10,2))) -> 88.57 | R26: =IF($Q26="","",ROUND($Q26*$R$10,2)) -> 17.71 | S26: 9 | T26: 18 | U26: 7 | V26: 18 | W26: 7 | X26: 7 | AC26: =IF(COUNT($S26:$AB26)=0,"",SUM($S26:$AB26)) -> 66 | AD26: =IF(ISERROR(IF($AC26="","",ROUND(($AC26/$AC$10)*$AD$10,2))),"",IF($AC26="","",ROUND(($AC26/$AC$10)*$AD$10,2))) -> 82.5 | AE26: =IF($AD26="","",ROUND($AD26*$AE$10,2)) -> 49.5 | AF26: 33 | AG26: =IF(ISERROR(IF($AF26="","",ROUND(($AF26/$AF$10)*$AG$10,2))),"",IF($AF26="","",ROUND(($AF26/$AF$10)*$AG$10,2))) -> 82.5 | AH26: =IF($AG26="","",ROUND($AG26*$AH$10,2)) -> 16.5 | AI26: =IF(ISERROR(IF($AF26="","",ROUND(SUM($R26,$AE26,$AH26),2))),"",IF($AF26="","",ROUND(SUM($R26,$AE26,$AH26),2))) -> 83.71 | AJ26: =IF(ISERROR(IF($AF26="","",VLOOKUP(AI26,TRANSMUTATION_TABLE,4,TRUE))),"",IF($AF26="","",VLOOKUP(AI26,TRANSMUTATION_TABLE,4,TRUE))) -> 89
A27: 16 | B27: ='INPUT DATA'!B27 -> Tolentino, John Noel Cabrera | F27: 8 | G27: 9 | H27: 8 | I27: 8 | J27: 10 | K27: 20 | P27: =IF(COUNT($F27:$O27)=0,"",SUM($F27:$O27)) -> 63 | Q27: =IF(ISERROR(IF($P27="","",ROUND(($P27/$P$10)*$Q$10,2))),"",IF($P27="","",ROUND(($P27/$P$10)*$Q$10,2))) -> 90 | R27: =IF($Q27="","",ROUND($Q27*$R$10,2)) -> 18 | S27: 9 | T27: 20 | U27: 8 | V27: 19 | W27: 9 | X27: 7 | AC27: =IF(COUNT($S27:$AB27)=0,"",SUM($S27:$AB27)) -> 72 | AD27: =IF(ISERROR(IF($AC27="","",ROUND(($AC27/$AC$10)*$AD$10,2))),"",IF($AC27="","",ROUND(($AC27/$AC$10)*$AD$10,2))) -> 90 | AE27: =IF($AD27="","",ROUND($AD27*$AE$10,2)) -> 54 | AF27: 23 | AG27: =IF(ISERROR(IF($AF27="","",ROUND(($AF27/$AF$10)*$AG$10,2))),"",IF($AF27="","",ROUND(($AF27/$AF$10)*$AG$10,2))) -> 57.5 | AH27: =IF($AG27="","",ROUND($AG27*$AH$10,2)) -> 11.5 | AI27: =IF(ISERROR(IF($AF27="","",ROUND(SUM($R27,$AE27,$AH27),2))),"",IF($AF27="","",ROUND(SUM($R27,$AE27,$AH27),2))) -> 83.5 | AJ27: =IF(ISERROR(IF($AF27="","",VLOOKUP(AI27,TRANSMUTATION_TABLE,4,TRUE))),"",IF($AF27="","",VLOOKUP(AI27,TRANSMUTATION_TABLE,4,TRUE))) -> 89
A28: 17 | B28: ='INPUT DATA'!B28 -> Traya, John Romeo Villanueva | F28: 9 | G28: 9 | H28: 7 | I28: 8 | J28: 10 | K28: 20 | P28: =IF(COUNT($F28:$O28)=0,"",SUM($F28:$O28)) -> 63 | Q28: =IF(ISERROR(IF($P28="","",ROUND(($P28/$P$10)*$Q$10,2))),"",IF($P28="","",ROUND(($P28/$P$10)*$Q$10,2))) -> 90 | R28: =IF($Q28="","",ROUND($Q28*$R$10,2)) -> 18 | S28: 9 | T28: 10 | U28: 8 | V28: 14 | W28: 7 | X28: 10 | AC28: =IF(COUNT($S28:$AB28)=0,"",SUM($S28:$AB28)) -> 58 | AD28: =IF(ISERROR(IF($AC28="","",ROUND(($AC28/$AC$10)*$AD$10,2))),"",IF($AC28="","",ROUND(($AC28/$AC$10)*$AD$10,2))) -> 72.5 | AE28: =IF($AD28="","",ROUND($AD28*$AE$10,2)) -> 43.5 | AF28: 23 | AG28: =IF(ISERROR(IF($AF28="","",ROUND(($AF28/$AF$10)*$AG$10,2))),"",IF($AF28="","",ROUND(($AF28/$AF$10)*$AG$10,2))) -> 57.5 | AH28: =IF($AG28="","",ROUND($AG28*$AH$10,2)) -> 11.5 | AI28: =IF(ISERROR(IF($AF28="","",ROUND(SUM($R28,$AE28,$AH28),2))),"",IF($AF28="","",ROUND(SUM($R28,$AE28,$AH28),2))) -> 73 | AJ28: =IF(ISERROR(IF($AF28="","",VLOOKUP(AI28,TRANSMUTATION_TABLE,4,TRUE))),"",IF($AF28="","",VLOOKUP(AI28,TRANSMUTATION_TABLE,4,TRUE))) -> 83
A29: 18 | B29: ='INPUT DATA'!B29 -> Villafuerte, Ken Buan | F29: 8 | G29: 10 | H29: 10 | I29: 8 | J29: 10 | K29: 18 | P29: =IF(COUNT($F29:$O29)=0,"",SUM($F29:$O29)) -> 64 | Q29: =IF(ISERROR(IF($P29="","",ROUND(($P29/$P$10)*$Q$10,2))),"",IF($P29="","",ROUND(($P29/$P$10)*$Q$10,2))) -> 91.43 | R29: =IF($Q29="","",ROUND($Q29*$R$10,2)) -> 18.29 | S29: 10 | T29: 18 | U29: 8 | V29: 15 | W29: 7 | X29: 10 | AC29: =IF(COUNT($S29:$AB29)=0,"",SUM($S29:$AB29)) -> 68 | AD29: =IF(ISERROR(IF($AC29="","",ROUND(($AC29/$AC$10)*$AD$10,2))),"",IF($AC29="","",ROUND(($AC29/$AC$10)*$AD$10,2))) -> 85 | AE29: =IF($AD29="","",ROUND($AD29*$AE$10,2)) -> 51 | AF29: 33 | AG29: =IF(ISERROR(IF($AF29="","",ROUND(($AF29/$AF$10)*$AG$10,2))),"",IF($AF29="","",ROUND(($AF29/$AF$10)*$AG$10,2))) -> 82.5 | AH29: =IF($AG29="","",ROUND($AG29*$AH$10,2)) -> 16.5 | AI29: =IF(ISERROR(IF($AF29="","",ROUND(SUM($R29,$AE29,$AH29),2))),"",IF($AF29="","",ROUND(SUM($R29,$AE29,$AH29),2))) -> 85.79 | AJ29: =IF(ISERROR(IF($AF29="","",VLOOKUP(AI29,TRANSMUTATION_TABLE,4,TRUE))),"",IF($AF29="","",VLOOKUP(AI29,TRANSMUTATION_TABLE,4,TRUE))) -> 91
A30: 19 | B30: ='INPUT DATA'!B30 -> Pangilinan, David Dweyn | P30: =IF(COUNT($F30:$O30)=0,"",SUM($F30:$O30)) | Q30: =IF(ISERROR(IF($P30="","",ROUND(($P30/$P$10)*$Q$10,2))),"",IF($P30="","",ROUND(($P30/$P$10)*$Q$10,2))) | R30: =IF($Q30="","",ROUND($Q30*$R$10,2)) | AC30: =IF(COUNT($S30:$AB30)=0,"",SUM($S30:$AB30)) | AD30: =IF(ISERROR(IF($AC30="","",ROUND(($AC30/$AC$10)*$AD$10,2))),"",IF($AC30="","",ROUND(($AC30/$AC$10)*$AD$10,2))) | AE30: =IF($AD30="","",ROUND($AD30*$AE$10,2)) | AG30: =IF(ISERROR(IF($AF30="","",ROUND(($AF30/$AF$10)*$AG$10,2))),"",IF($AF30="","",ROUND(($AF30/$AF$10)*$AG$10,2))) | AH30: =IF($AG30="","",ROUND($AG30*$AH$10,2)) | AI30: =IF(ISERROR(IF($AF30="","",ROUND(SUM($R30,$AE30,$AH30),2))),"",IF($AF30="","",ROUND(SUM($R30,$AE30,$AH30),2))) | AJ30: =IF(ISERROR(IF($AF30="","",VLOOKUP(AI30,TRANSMUTATION_TABLE,4,TRUE))),"",IF($AF30="","",VLOOKUP(AI30,TRANSMUTATION_TABLE,4,TRUE)))
A31: 20 | B31: ='INPUT DATA'!B31 -> 0 | P31: =IF(COUNT($F31:$O31)=0,"",SUM($F31:$O31)) | Q31: =IF(ISERROR(IF($P31="","",ROUND(($P31/$P$10)*$Q$10,2))),"",IF($P31="","",ROUND(($P31/$P$10)*$Q$10,2))) | R31: =IF($Q31="","",ROUND($Q31*$R$10,2)) | AC31: =IF(COUNT($S31:$AB31)=0,"",SUM($S31:$AB31)) | AD31: =IF(ISERROR(IF($AC31="","",ROUND(($AC31/$AC$10)*$AD$10,2))),"",IF($AC31="","",ROUND(($AC31/$AC$10)*$AD$10,2))) | AE31: =IF($AD31="","",ROUND($AD31*$AE$10,2)) | AG31: =IF(ISERROR(IF($AF31="","",ROUND(($AF31/$AF$10)*$AG$10,2))),"",IF($AF31="","",ROUND(($AF31/$AF$10)*$AG$10,2))) | AH31: =IF($AG31="","",ROUND($AG31*$AH$10,2)) | AI31: =IF(ISERROR(IF($AF31="","",ROUND(SUM($R31,$AE31,$AH31),2))),"",IF($AF31="","",ROUND(SUM($R31,$AE31,$AH31),2))) | AJ31: =IF(ISERROR(IF($AF31="","",VLOOKUP(AI31,TRANSMUTATION_TABLE,4,TRUE))),"",IF($AF31="","",VLOOKUP(AI31,TRANSMUTATION_TABLE,4,TRUE)))
A32: 21 | B32: ='INPUT DATA'!B32 -> 0 | P32: =IF(COUNT($F32:$O32)=0,"",SUM($F32:$O32)) | Q32: =IF(ISERROR(IF($P32="","",ROUND(($P32/$P$10)*$Q$10,2))),"",IF($P32="","",ROUND(($P32/$P$10)*$Q$10,2))) | R32: =IF($Q32="","",ROUND($Q32*$R$10,2)) | AC32: =IF(COUNT($S32:$AB32)=0,"",SUM($S32:$AB32)) | AD32: =IF(ISERROR(IF($AC32="","",ROUND(($AC32/$AC$10)*$AD$10,2))),"",IF($AC32="","",ROUND(($AC32/$AC$10)*$AD$10,2))) | AE32: =IF($AD32="","",ROUND($AD32*$AE$10,2)) | AG32: =IF(ISERROR(IF($AF32="","",ROUND(($AF32/$AF$10)*$AG$10,2))),"",IF($AF32="","",ROUND(($AF32/$AF$10)*$AG$10,2))) | AH32: =IF($AG32="","",ROUND($AG32*$AH$10,2)) | AI32: =IF(ISERROR(IF($AF32="","",ROUND(SUM($R32,$AE32,$AH32),2))),"",IF($AF32="","",ROUND(SUM($R32,$AE32,$AH32),2))) | AJ32: =IF(ISERROR(IF($AF32="","",VLOOKUP(AI32,TRANSMUTATION_TABLE,4,TRUE))),"",IF($AF32="","",VLOOKUP(AI32,TRANSMUTATION_TABLE,4,TRUE)))
A33: 22 | B33: ='INPUT DATA'!B33 -> 0 | P33: =IF(COUNT($F33:$O33)=0,"",SUM($F33:$O33)) | Q33: =IF(ISERROR(IF($P33="","",ROUND(($P33/$P$10)*$Q$10,2))),"",IF($P33="","",ROUND(($P33/$P$10)*$Q$10,2))) | R33: =IF($Q33="","",ROUND($Q33*$R$10,2)) | AC33: =IF(COUNT($S33:$AB33)=0,"",SUM($S33:$AB33)) | AD33: =IF(ISERROR(IF($AC33="","",ROUND(($AC33/$AC$10)*$AD$10,2))),"",IF($AC33="","",ROUND(($AC33/$AC$10)*$AD$10,2))) | AE33: =IF($AD33="","",ROUND($AD33*$AE$10,2)) | AG33: =IF(ISERROR(IF($AF33="","",ROUND(($AF33/$AF$10)*$AG$10,2))),"",IF($AF33="","",ROUND(($AF33/$AF$10)*$AG$10,2))) | AH33: =IF($AG33="","",ROUND($AG33*$AH$10,2)) | AI33: =IF(ISERROR(IF($AF33="","",ROUND(SUM($R33,$AE33,$AH33),2))),"",IF($AF33="","",ROUND(SUM($R33,$AE33,$AH33),2))) | AJ33: =IF(ISERROR(IF($AF33="","",VLOOKUP(AI33,TRANSMUTATION_TABLE,4,TRUE))),"",IF($AF33="","",VLOOKUP(AI33,TRANSMUTATION_TABLE,4,TRUE)))
A34: 23 | B34: ='INPUT DATA'!B34 -> 0 | P34: =IF(COUNT($F34:$O34)=0,"",SUM($F34:$O34)) | Q34: =IF(ISERROR(IF($P34="","",ROUND(($P34/$P$10)*$Q$10,2))),"",IF($P34="","",ROUND(($P34/$P$10)*$Q$10,2))) | R34: =IF($Q34="","",ROUND($Q34*$R$10,2)) | AC34: =IF(COUNT($S34:$AB34)=0,"",SUM($S34:$AB34)) | AD34: =IF(ISERROR(IF($AC34="","",ROUND(($AC34/$AC$10)*$AD$10,2))),"",IF($AC34="","",ROUND(($AC34/$AC$10)*$AD$10,2))) | AE34: =IF($AD34="","",ROUND($AD34*$AE$10,2)) | AG34: =IF(ISERROR(IF($AF34="","",ROUND(($AF34/$AF$10)*$AG$10,2))),"",IF($AF34="","",ROUND(($AF34/$AF$10)*$AG$10,2))) | AH34: =IF($AG34="","",ROUND($AG34*$AH$10,2)) | AI34: =IF(ISERROR(IF($AF34="","",ROUND(SUM($R34,$AE34,$AH34),2))),"",IF($AF34="","",ROUND(SUM($R34,$AE34,$AH34),2))) | AJ34: =IF(ISERROR(IF($AF34="","",VLOOKUP(AI34,TRANSMUTATION_TABLE,4,TRUE))),"",IF($AF34="","",VLOOKUP(AI34,TRANSMUTATION_TABLE,4,TRUE)))
A35: 24 | B35: ='INPUT DATA'!B35 -> 0 | P35: =IF(COUNT($F35:$O35)=0,"",SUM($F35:$O35)) | Q35: =IF(ISERROR(IF($P35="","",ROUND(($P35/$P$10)*$Q$10,2))),"",IF($P35="","",ROUND(($P35/$P$10)*$Q$10,2))) | R35: =IF($Q35="","",ROUND($Q35*$R$10,2)) | AC35: =IF(COUNT($S35:$AB35)=0,"",SUM($S35:$AB35)) | AD35: =IF(ISERROR(IF($AC35="","",ROUND(($AC35/$AC$10)*$AD$10,2))),"",IF($AC35="","",ROUND(($AC35/$AC$10)*$AD$10,2))) | AE35: =IF($AD35="","",ROUND($AD35*$AE$10,2)) | AG35: =IF(ISERROR(IF($AF35="","",ROUND(($AF35/$AF$10)*$AG$10,2))),"",IF($AF35="","",ROUND(($AF35/$AF$10)*$AG$10,2))) | AH35: =IF($AG35="","",ROUND($AG35*$AH$10,2)) | AI35: =IF(ISERROR(IF($AF35="","",ROUND(SUM($R35,$AE35,$AH35),2))),"",IF($AF35="","",ROUND(SUM($R35,$AE35,$AH35),2))) | AJ35: =IF(ISERROR(IF($AF35="","",VLOOKUP(AI35,TRANSMUTATION_TABLE,4,TRUE))),"",IF($AF35="","",VLOOKUP(AI35,TRANSMUTATION_TABLE,4,TRUE)))
A36: 25 | B36: ='INPUT DATA'!B36 -> 0 | P36: =IF(COUNT($F36:$O36)=0,"",SUM($F36:$O36)) | Q36: =IF(ISERROR(IF($P36="","",ROUND(($P36/$P$10)*$Q$10,2))),"",IF($P36="","",ROUND(($P36/$P$10)*$Q$10,2))) | R36: =IF($Q36="","",ROUND($Q36*$R$10,2)) | AC36: =IF(COUNT($S36:$AB36)=0,"",SUM($S36:$AB36)) | AD36: =IF(ISERROR(IF($AC36="","",ROUND(($AC36/$AC$10)*$AD$10,2))),"",IF($AC36="","",ROUND(($AC36/$AC$10)*$AD$10,2))) | AE36: =IF($AD36="","",ROUND($AD36*$AE$10,2)) | AG36: =IF(ISERROR(IF($AF36="","",ROUND(($AF36/$AF$10)*$AG$10,2))),"",IF($AF36="","",ROUND(($AF36/$AF$10)*$AG$10,2))) | AH36: =IF($AG36="","",ROUND($AG36*$AH$10,2)) | AI36: =IF(ISERROR(IF($AF36="","",ROUND(SUM($R36,$AE36,$AH36),2))),"",IF($AF36="","",ROUND(SUM($R36,$AE36,$AH36),2))) | AJ36: =IF(ISERROR(IF($AF36="","",VLOOKUP(AI36,TRANSMUTATION_TABLE,4,TRUE))),"",IF($AF36="","",VLOOKUP(AI36,TRANSMUTATION_TABLE,4,TRUE)))
A37: 26 | B37: ='INPUT DATA'!B37 -> 0 | P37: =IF(COUNT($F37:$O37)=0,"",SUM($F37:$O37)) | Q37: =IF(ISERROR(IF($P37="","",ROUND(($P37/$P$10)*$Q$10,2))),"",IF($P37="","",ROUND(($P37/$P$10)*$Q$10,2))) | R37: =IF($Q37="","",ROUND($Q37*$R$10,2)) | AC37: =IF(COUNT($S37:$AB37)=0,"",SUM($S37:$AB37)) | AD37: =IF(ISERROR(IF($AC37="","",ROUND(($AC37/$AC$10)*$AD$10,2))),"",IF($AC37="","",ROUND(($AC37/$AC$10)*$AD$10,2))) | AE37: =IF($AD37="","",ROUND($AD37*$AE$10,2)) | AG37: =IF(ISERROR(IF($AF37="","",ROUND(($AF37/$AF$10)*$AG$10,2))),"",IF($AF37="","",ROUND(($AF37/$AF$10)*$AG$10,2))) | AH37: =IF($AG37="","",ROUND($AG37*$AH$10,2)) | AI37: =IF(ISERROR(IF($AF37="","",ROUND(SUM($R37,$AE37,$AH37),2))),"",IF($AF37="","",ROUND(SUM($R37,$AE37,$AH37),2))) | AJ37: =IF(ISERROR(IF($AF37="","",VLOOKUP(AI37,TRANSMUTATION_TABLE,4,TRUE))),"",IF($AF37="","",VLOOKUP(AI37,TRANSMUTATION_TABLE,4,TRUE)))
A38: 27 | B38: ='INPUT DATA'!B38 -> 0 | P38: =IF(COUNT($F38:$O38)=0,"",SUM($F38:$O38)) | Q38: =IF(ISERROR(IF($P38="","",ROUND(($P38/$P$10)*$Q$10,2))),"",IF($P38="","",ROUND(($P38/$P$10)*$Q$10,2))) | R38: =IF($Q38="","",ROUND($Q38*$R$10,2)) | AC38: =IF(COUNT($S38:$AB38)=0,"",SUM($S38:$AB38)) | AD38: =IF(ISERROR(IF($AC38="","",ROUND(($AC38/$AC$10)*$AD$10,2))),"",IF($AC38="","",ROUND(($AC38/$AC$10)*$AD$10,2))) | AE38: =IF($AD38="","",ROUND($AD38*$AE$10,2)) | AG38: =IF(ISERROR(IF($AF38="","",ROUND(($AF38/$AF$10)*$AG$10,2))),"",IF($AF38="","",ROUND(($AF38/$AF$10)*$AG$10,2))) | AH38: =IF($AG38="","",ROUND($AG38*$AH$10,2)) | AI38: =IF(ISERROR(IF($AF38="","",ROUND(SUM($R38,$AE38,$AH38),2))),"",IF($AF38="","",ROUND(SUM($R38,$AE38,$AH38),2))) | AJ38: =IF(ISERROR(IF($AF38="","",VLOOKUP(AI38,TRANSMUTATION_TABLE,4,TRUE))),"",IF($AF38="","",VLOOKUP(AI38,TRANSMUTATION_TABLE,4,TRUE)))
A39: 28 | B39: ='INPUT DATA'!B39 -> 0 | P39: =IF(COUNT($F39:$O39)=0,"",SUM($F39:$O39)) | Q39: =IF(ISERROR(IF($P39="","",ROUND(($P39/$P$10)*$Q$10,2))),"",IF($P39="","",ROUND(($P39/$P$10)*$Q$10,2))) | R39: =IF($Q39="","",ROUND($Q39*$R$10,2)) | AC39: =IF(COUNT($S39:$AB39)=0,"",SUM($S39:$AB39)) | AD39: =IF(ISERROR(IF($AC39="","",ROUND(($AC39/$AC$10)*$AD$10,2))),"",IF($AC39="","",ROUND(($AC39/$AC$10)*$AD$10,2))) | AE39: =IF($AD39="","",ROUND($AD39*$AE$10,2)) | AG39: =IF(ISERROR(IF($AF39="","",ROUND(($AF39/$AF$10)*$AG$10,2))),"",IF($AF39="","",ROUND(($AF39/$AF$10)*$AG$10,2))) | AH39: =IF($AG39="","",ROUND($AG39*$AH$10,2)) | AI39: =IF(ISERROR(IF($AF39="","",ROUND(SUM($R39,$AE39,$AH39),2))),"",IF($AF39="","",ROUND(SUM($R39,$AE39,$AH39),2))) | AJ39: =IF(ISERROR(IF($AF39="","",VLOOKUP(AI39,TRANSMUTATION_TABLE,4,TRUE))),"",IF($AF39="","",VLOOKUP(AI39,TRANSMUTATION_TABLE,4,TRUE)))
A40: 29 | B40: ='INPUT DATA'!B40 -> 0 | P40: =IF(COUNT($F40:$O40)=0,"",SUM($F40:$O40)) | Q40: =IF(ISERROR(IF($P40="","",ROUND(($P40/$P$10)*$Q$10,2))),"",IF($P40="","",ROUND(($P40/$P$10)*$Q$10,2))) | R40: =IF($Q40="","",ROUND($Q40*$R$10,2)) | AC40: =IF(COUNT($S40:$AB40)=0,"",SUM($S40:$AB40)) | AD40: =IF(ISERROR(IF($AC40="","",ROUND(($AC40/$AC$10)*$AD$10,2))),"",IF($AC40="","",ROUND(($AC40/$AC$10)*$AD$10,2))) | AE40: =IF($AD40="","",ROUND($AD40*$AE$10,2)) | AG40: =IF(ISERROR(IF($AF40="","",ROUND(($AF40/$AF$10)*$AG$10,2))),"",IF($AF40="","",ROUND(($AF40/$AF$10)*$AG$10,2))) | AH40: =IF($AG40="","",ROUND($AG40*$AH$10,2)) | AI40: =IF(ISERROR(IF($AF40="","",ROUND(SUM($R40,$AE40,$AH40),2))),"",IF($AF40="","",ROUND(SUM($R40,$AE40,$AH40),2))) | AJ40: =IF(ISERROR(IF($AF40="","",VLOOKUP(AI40,TRANSMUTATION_TABLE,4,TRUE))),"",IF($AF40="","",VLOOKUP(AI40,TRANSMUTATION_TABLE,4,TRUE)))
A41: 30 | B41: ='INPUT DATA'!B41 -> 0 | P41: =IF(COUNT($F41:$O41)=0,"",SUM($F41:$O41)) | Q41: =IF(ISERROR(IF($P41="","",ROUND(($P41/$P$10)*$Q$10,2))),"",IF($P41="","",ROUND(($P41/$P$10)*$Q$10,2))) | R41: =IF($Q41="","",ROUND($Q41*$R$10,2)) | AC41: =IF(COUNT($S41:$AB41)=0,"",SUM($S41:$AB41)) | AD41: =IF(ISERROR(IF($AC41="","",ROUND(($AC41/$AC$10)*$AD$10,2))),"",IF($AC41="","",ROUND(($AC41/$AC$10)*$AD$10,2))) | AE41: =IF($AD41="","",ROUND($AD41*$AE$10,2)) | AG41: =IF(ISERROR(IF($AF41="","",ROUND(($AF41/$AF$10)*$AG$10,2))),"",IF($AF41="","",ROUND(($AF41/$AF$10)*$AG$10,2))) | AH41: =IF($AG41="","",ROUND($AG41*$AH$10,2)) | AI41: =IF(ISERROR(IF($AF41="","",ROUND(SUM($R41,$AE41,$AH41),2))),"",IF($AF41="","",ROUND(SUM($R41,$AE41,$AH41),2))) | AJ41: =IF(ISERROR(IF($AF41="","",VLOOKUP(AI41,TRANSMUTATION_TABLE,4,TRUE))),"",IF($AF41="","",VLOOKUP(AI41,TRANSMUTATION_TABLE,4,TRUE)))
... A61: 50 | B61: ='INPUT DATA'!B61 -> 0 | P61: =IF(COUNT($F61:$O61)=0,"",SUM($F61:$O61)) | Q61: =IF(ISERROR(IF($P61="","",ROUND(($P61/$P$10)*$Q$10,2))),"",IF($P61="","",ROUND(($P61/$P$10)*$Q$10,2))) | R61: =IF($Q61="","",ROUND($Q61*$R$10,2)) | AC61: =IF(COUNT($S61:$AB61)=0,"",SUM($S61:$AB61)) | AD61: =IF(ISERROR(IF($AC61="","",ROUND(($AC61/$AC$10)*$AD$10,2))),"",IF($AC61="","",ROUND(($AC61/$AC$10)*$AD$10,2))) | AE61: =IF($AD61="","",ROUND($AD61*$AE$10,2)) | AG61: =IF(ISERROR(IF($AF61="","",ROUND(($AF61/$AF$10)*$AG$10,2))),"",IF($AF61="","",ROUND(($AF61/$AF$10)*$AG$10,2))) | AH61: =IF($AG61="","",ROUND($AG61*$AH$10,2)) | AI61: =IF(ISERROR(IF($AF61="","",ROUND(SUM($R61,$AE61,$AH61),2))),"",IF($AF61="","",ROUND(SUM($R61,$AE61,$AH61),2))) | AJ61: =IF(ISERROR(IF($AF61="","",VLOOKUP(AI61,TRANSMUTATION_TABLE,4,TRUE))),"",IF($AF61="","",VLOOKUP(AI61,TRANSMUTATION_TABLE,4,TRUE)))
B62: FEMALE
...

Sheet GMRC Q2
A1: Official E-Class Record in K to 12 Curriculum
C4: REGION | G4: ='INPUT DATA'!G4 -> III | L4: 4 | O4: ='INPUT DATA'!O4 -> CITY OF SAN FDO. | T4: DISTRICT | X4: ='INPUT DATA'!X4 -> NORTH
B5: SCHOOL NAME | G5: ='INPUT DATA'!G5 -> TELABASTAGAN INTEGRATED SCHOOL | T5: SCHOOL ID | X5: ='INPUT DATA'!X5 -> 500144 | AD5: SCHOOL YEAR | AG5: ='INPUT DATA'!AG5 -> 2025-2026
A7: SECOND QUARTER | F7: GRADE & SECTION: | K7: ='INPUT DATA'!K7 -> IV-RIZAL | Q7: TEACHER: | S7: ='INPUT DATA'!S7 -> ADELIA M. MANARANG | AC7: SUBJECT: | AG7: ='INPUT DATA'!AG7 -> GMRC
B8: LEARNERS' NAMES | F8: WRITTEN WORKS (20%) | S8: PERFORMANCE TASKS (60%) | AF8: QUARTERLY ASSESSMENT (20%) | AI8: Initial | AJ8: Quarterly
F9: 1 | G9: 2 | H9: 3 | I9: 4 | J9: 5 | K9: 6 | L9: 7 | M9: 8 | N9: 9 | O9: 10 | P9: Total | Q9: PS | R9: WS | S9: 1 | T9: 2 | U9: 3 | V9: 4 | W9: 5 | X9: 6 | Y9: 7 | Z9: 8 | AA9: 9 | AB9: 10 | AC9: Total | AD9: PS | AE9: WS | AF9: 1 | AG9: PS | AH9: WS | AI9: Grade | AJ9: Grade
B10: HIGHEST POSSIBLE SCORE | F10: 10 | G10: 10 | H10: 15 | I10: 10 | J10: 10 | K10: 15 | P10: =IF(COUNT($F10:$O10)=0,"",SUM($F10:$O10)) -> 70 | Q10: 100 | R10: 0.2 | S10: 10 | T10: 20 | U10: 15 | V10: 10 | W10: 10 | AC10: =IF(COUNT($S10:$AB10)=0,"",SUM($S10:$AB10)) -> 65 | AD10: 100 | AE10: 0.6 | AF10: 40 | AG10: 100 | AH10: 0.2
B11: MALE
A12: 1 | B12: ='INPUT DATA'!B12 -> Aranquez, Elemerson Jacob Quito | F12: 7 | G12: 8 | H12: 15 | I12: 1 | J12: 9 | K12: 6 | P12: =IF(COUNT($F12:$O12)=0,"",SUM($F12:$O12)) -> 46 | Q12: =IF(ISERROR(IF($P12="","",ROUND(($P12/$P$10)*$Q$10,2))),"",IF($P12="","",ROUND(($P12/$P$10)*$Q$10,2))) -> 65.71 | R12: =IF($Q12="","",ROUND($Q12*$R$10,2)) -> 13.14 | S12: 7 | T12: 16 | U12: 13 | V12: 8 | W12: 8 | AC12: =IF(COUNT($S12:$AB12)=0,"",SUM($S12:$AB12)) -> 52 | AD12: =IF(ISERROR(IF($AC12="","",ROUND(($AC12/$AC$10)*$AD$10,2))),"",IF($AC12="","",ROUND(($AC12/$AC$10)*$AD$10,2))) -> 80 | AE12: =IF($AD12="","",ROUND($AD12*$AE$10,2)) -> 48 | AF12: 36 | AG12: =IF(ISERROR(IF($AF12="","",ROUND(($AF12/$AF$10)*$AG$10,2))),"",IF($AF12="","",ROUND(($AF12/$AF$10)*$AG$10,2))) -> 90 | AH12: =IF($AG12="","",ROUND($AG12*$AH$10,2)) -> 18 | AI12: =IF(ISERROR(IF($AF12="","",ROUND(SUM($R12,$AE12,$AH12),2))),"",IF($AF12="","",ROUND(SUM($R12,$AE12,$AH12),2))) -> 79.14 | AJ12: =IF(ISERROR(IF($AF12="","",VLOOKUP(AI12,TRANSMUTATION_TABLE,4,TRUE))),"",IF($AF12="","",VLOOKUP(AI12,TRANSMUTATION_TABLE,4,TRUE))) -> 86
A13: 2 | B13: ='INPUT DATA'!B13 -> Bautisa, France Kiel Lacon | F13: 6 | G13: 7 | H13: 5 | I13: 8 | J13: 9 | K13: 5 | P13: =IF(COUNT($F13:$O13)=0,"",SUM($F13:$O13)) -> 40 | Q13: =IF(ISERROR(IF($P13="","",ROUND(($P13/$P$10)*$Q$10,2))),"",IF($P13="","",ROUND(($P13/$P$10)*$Q$10,2))) -> 57.14 | R13: =IF($Q13="","",ROUND($Q13*$R$10,2)) -> 11.43 | S13: 7 | T13: 17 | U13: 9 | V13: 10 | W13: 8 | AC13: =IF(COUNT($S13:$AB13)=0,"",SUM($S13:$AB13)) -> 51 | AD13: =IF(ISERROR(IF($AC13="","",ROUND(($AC13/$AC$10)*$AD$10,2))),"",IF($AC13="","",ROUND(($AC13/$AC$10)*$AD$10,2))) -> 78.46 | AE13: =IF($AD13="","",ROUND($AD13*$AE$10,2)) -> 47.08 | AF13: 29 | AG13: =IF(ISERROR(IF($AF13="","",ROUND(($AF13/$AF$10)*$AG$10,2))),"",IF($AF13="","",ROUND(($AF13/$AF$10)*$AG$10,2))) -> 72.5 | AH13: =IF($AG13="","",ROUND($AG13*$AH$10,2)) -> 14.5 | AI13: =IF(ISERROR(IF($AF13="","",ROUND(SUM($R13,$AE13,$AH13),2))),"",IF($AF13="","",ROUND(SUM($R13,$AE13,$AH13),2))) -> 73.01 | AJ13: =IF(ISERROR(IF($AF13="","",VLOOKUP(AI13,TRANSMUTATION_TABLE,4,TRUE))),"",IF($AF13="","",VLOOKUP(AI13,TRANSMUTATION_TABLE,4,TRUE))) -> 83
A14: 3 | B14: ='INPUT DATA'!B14 -> Candelario, Nylan Esto | F14: 7 | G14: 8 | H14: 10 | I14: 10 | J14: 10 | K14: 8 | P14: =IF(COUNT($F14:$O14)=0,"",SUM($F14:$O14)) -> 53 | Q14: =IF(ISERROR(IF($P14="","",ROUND(($P14/$P$10)*$Q$10,2))),"",IF($P14="","",ROUND(($P14/$P$10)*$Q$10,2))) -> 75.71 | R14: =IF($Q14="","",ROUND($Q14*$R$10,2)) -> 15.14 | S14: 8 | T14: 17 | U14: 14 | V14: 10 | W14: 10 | AC14: =IF(COUNT($S14:$AB14)=0,"",SUM($S14:$AB14)) -> 59 | AD14: =IF(ISERROR(IF($AC14="","",ROUND(($AC14/$AC$10)*$AD$10,2))),"",IF($AC14="","",ROUND(($AC14/$AC$10)*$AD$10,2))) -> 90.77 | AE14: =IF($AD14="","",ROUND($AD14*$AE$10,2)) -> 54.46 | AF14: 31 | AG14: =IF(ISERROR(IF($AF14="","",ROUND(($AF14/$AF$10)*$AG$10,2))),"",IF($AF14="","",ROUND(($AF14/$AF$10)*$AG$10,2))) -> 77.5 | AH14: =IF($AG14="","",ROUND($AG14*$AH$10,2)) -> 15.5 | AI14: =IF(ISERROR(IF($AF14="","",ROUND(SUM($R14,$AE14,$AH14),2))),"",IF($AF14="","",ROUND(SUM($R14,$AE14,$AH14),2))) -> 85.1 | AJ14: =IF(ISERROR(IF($AF14="","",VLOOKUP(AI14,TRANSMUTATION_TABLE,4,TRUE))),"",IF($AF14="","",VLOOKUP(AI14,TRANSMUTATION_TABLE,4,TRUE))) -> 90
A15: 4 | B15: ='INPUT DATA'!B15 -> Dalangin, Lorenz Salvador | F15: 8 | G15: 7 | H15: 15 | I15: 10 | J15: 10 | K15: 14 | P15: =IF(COUNT($F15:$O15)=0,"",SUM($F15:$O15)) -> 64 | Q15: =IF(ISERROR(IF($P15="","",ROUND(($P15/$P$10)*$Q$10,2))),"",IF($P15="","",ROUND(($P15/$P$10)*$Q$10,2))) -> 91.43 | R15: =IF($Q15="","",ROUND($Q15*$R$10,2)) -> 18.29 | S15: 8 | T15: 16 | U15: 15 | V15: 10 | W15: 10 | AC15: =IF(COUNT($S15:$AB15)=0,"",SUM($S15:$AB15)) -> 59 | AD15: =IF(ISERROR(IF($AC15="","",ROUND(($AC15/$AC$10)*$AD$10,2))),"",IF($AC15="","",ROUND(($AC15/$AC$10)*$AD$10,2))) -> 90.77 | AE15: =IF($AD15="","",ROUND($AD15*$AE$10,2)) -> 54.46 | AF15: 20 | AG15: =IF(ISERROR(IF($AF15="","",ROUND(($AF15/$AF$10)*$AG$10,2))),"",IF($AF15="","",ROUND(($AF15/$AF$10)*$AG$10,2))) -> 50 | AH15: =IF($AG15="","",ROUND($AG15*$AH$10,2)) -> 10 | AI15: =IF(ISERROR(IF($AF15="","",ROUND(SUM($R15,$AE15,$AH15),2))),"",IF($AF15="","",ROUND(SUM($R15,$AE15,$AH15),2))) -> 82.75 | AJ15: =IF(ISERROR(IF($AF15="","",VLOOKUP(AI15,TRANSMUTATION_TABLE,4,TRUE))),"",IF($AF15="","",VLOOKUP(AI15,TRANSMUTATION_TABLE,4,TRUE))) -> 89
A16: 5 | B16: ='INPUT DATA'!B16 -> De Jesus, Benjamin Tyga Liscano | F16: 6 | G16: 6 | H16: 5 | I16: 7 | J16: 7 | K16: 15 | P16: =IF(COUNT($F16:$O16)=0,"",SUM($F16:$O16)) -> 46 | Q16: =IF(ISERROR(IF($P16="","",ROUND(($P16/$P$10)*$Q$10,2))),"",IF($P16="","",ROUND(($P16/$P$10)*$Q$10,2))) -> 65.71 | R16: =IF($Q16="","",ROUND($Q16*$R$10,2)) -> 13.14 | S16: 8 | T16: 18 | U16: 5 | V16: 5 | W16: 10 | AC16: =IF(COUNT($S16:$AB16)=0,"",SUM($S16:$AB16)) -> 46 | AD16: =IF(ISERROR(IF($AC16="","",ROUND(($AC16/$AC$10)*$AD$10,2))),"",IF($AC16="","",ROUND(($AC16/$AC$10)*$AD$10,2))) -> 70.77 | AE16: =IF($AD16="","",ROUND($AD16*$AE$10,2)) -> 42.46 | AF16: 37 | AG16: =IF(ISERROR(IF($AF16="","",ROUND(($AF16/$AF$10)*$AG$10,2))),"",IF($AF16="","",ROUND(($AF16/$AF$10)*$AG$10,2))) -> 92.5 | AH16: =IF($AG16="","",ROUND($AG16*$AH$10,2)) -> 18.5 | AI16: =IF(ISERROR(IF($AF16="","",ROUND(SUM($R16,$AE16,$AH16),2))),"",IF($AF16="","",ROUND(SUM($R16,$AE16,$AH16),2))) -> 74.1 | AJ16: =IF(ISERROR(IF($AF16="","",VLOOKUP(AI16,TRANSMUTATION_TABLE,4,TRUE))),"",IF($AF16="","",VLOOKUP(AI16,TRANSMUTATION_TABLE,4,TRUE))) -> 83
A17: 6 | B17: ='INPUT DATA'!B17 -> Cortez, Xyron Credo | F17: 8 | G17: 10 | H17: 10 | I17: 10 | J17: 10 | K17: 15 | P17: =IF(COUNT($F17:$O17)=0,"",SUM($F17:$O17)) -> 63 | Q17: =IF(ISERROR(IF($P17="","",ROUND(($P17/$P$10)*$Q$10,2))),"",IF($P17="","",ROUND(($P17/$P$10)*$Q$10,2))) -> 90 | R17: =IF($Q17="","",ROUND($Q17*$R$10,2)) -> 18 | S17: 9 | T17: 19 | U17: 12 | V17: 6 | W17: 6 | AC17: =IF(COUNT($S17:$AB17)=0,"",SUM($S17:$AB17)) -> 52 | AD17: =IF(ISERROR(IF($AC17="","",ROUND(($AC17/$AC$10)*$AD$10,2))),"",IF($AC17="","",ROUND(($AC17/$AC$10)*$AD$10,2))) -> 80 | AE17: =IF($AD17="","",ROUND($AD17*$AE$10,2)) -> 48 | AF17: 32 | AG17: =IF(ISERROR(IF($AF17="","",ROUND(($AF17/$AF$10)*$AG$10,2))),"",IF($AF17="","",ROUND(($AF17/$AF$10)*$AG$10,2))) -> 80 | AH17: =IF($AG17="","",ROUND($AG17*$AH$10,2)) -> 16 | AI17: =IF(ISERROR(IF($AF17="","",ROUND(SUM($R17,$AE17,$AH17),2))),"",IF($AF17="","",ROUND(SUM($R17,$AE17,$AH17),2))) -> 82 | AJ17: =IF(ISERROR(IF($AF17="","",VLOOKUP(AI17,TRANSMUTATION_TABLE,4,TRUE))),"",IF($AF17="","",VLOOKUP(AI17,TRANSMUTATION_TABLE,4,TRUE))) -> 88
A18: 7 | B18: ='INPUT DATA'!B18 -> Garong Shemuelle Jones L. | F18: 8 | G18: 9 | H18: 5 | I18: 8 | J18: 10 | K18: 8 | P18: =IF(COUNT($F18:$O18)=0,"",SUM($F18:$O18)) -> 48 | Q18: =IF(ISERROR(IF($P18="","",ROUND(($P18/$P$10)*$Q$10,2))),"",IF($P18="","",ROUND(($P18/$P$10)*$Q$10,2))) -> 68.57 | R18: =IF($Q18="","",ROUND($Q18*$R$10,2)) -> 13.71 | S18: 8 | T18: 17 | U18: 14 | V18: 9 | W18: 7 | AC18: =IF(COUNT($S18:$AB18)=0,"",SUM($S18:$AB18)) -> 55 | AD18: =IF(ISERROR(IF($AC18="","",ROUND(($AC18/$AC$10)*$AD$10,2))),"",IF($AC18="","",ROUND(($AC18/$AC$10)*$AD$10,2))) -> 84.62 | AE18: =IF($AD18="","",ROUND($AD18*$AE$10,2)) -> 50.77 | AF18: 30 | AG18: =IF(ISERROR(IF($AF18="","",ROUND(($AF18/$AF$10)*$AG$10,2))),"",IF($AF18="","",ROUND(($AF18/$AF$10)*$AG$10,2))) -> 75 | AH18: =IF($AG18="","",ROUND($AG18*$AH$10,2)) -> 15 | AI18: =IF(ISERROR(IF($AF18="","",ROUND(SUM($R18,$AE18,$AH18),2))),"",IF($AF18="","",ROUND(SUM($R18,$AE18,$AH18),2))) -> 79.48 | AJ18: =IF(ISERROR(IF($AF18="","",VLOOKUP(AI18,TRANSMUTATION_TABLE,4,TRUE))),"",IF($AF18="","",VLOOKUP(AI18,TRANSMUTATION_TABLE,4,TRUE))) -> 87
A19: 8 | B19: ='INPUT DATA'!B19 -> Gonzales, Hadrian Consulta | D19: 0 | F19: 7 | G19: 8 | H19: 15 | I19: 10 | J19: 10 | K19: 15 | P19: =IF(COUNT($F19:$O19)=0,"",SUM($F19:$O19)) -> 65 | Q19: =IF(ISERROR(IF($P19="","",ROUND(($P19/$P$10)*$Q$10,2))),"",IF($P19="","",ROUND(($P19/$P$10)*$Q$10,2))) -> 92.86 | R19: =IF($Q19="","",ROUND($Q19*$R$10,2)) -> 18.57 | S19: 9 | T19: 18 | U19: 14 | V19: 10 | W19: 5 | AC19: =IF(COUNT($S19:$AB19)=0,"",SUM($S19:$AB19)) -> 56 | AD19: =IF(ISERROR(IF($AC19="","",ROUND(($AC19/$AC$10)*$AD$10,2))),"",IF($AC19="","",ROUND(($AC19/$AC$10)*$AD$10,2))) -> 86.15 | AE19: =IF($AD19="","",ROUND($AD19*$AE$10,2)) -> 51.69 | AF19: 30 | AG19: =IF(ISERROR(IF($AF19="","",ROUND(($AF19/$AF$10)*$AG$10,2))),"",IF($AF19="","",ROUND(($AF19/$AF$10)*$AG$10,2))) -> 75 | AH19: =IF($AG19="","",ROUND($AG19*$AH$10,2)) -> 15 | AI19: =IF(ISERROR(IF($AF19="","",ROUND(SUM($R19,$AE19,$AH19),2))),"",IF($AF19="","",ROUND(SUM($R19,$AE19,$AH19),2))) -> 85.26 | AJ19: =IF(ISERROR(IF($AF19="","",VLOOKUP(AI19,TRANSMUTATION_TABLE,4,TRUE))),"",IF($AF19="","",VLOOKUP(AI19,TRANSMUTATION_TABLE,4,TRUE))) -> 90
A20: 9 | B20: ='INPUT DATA'!B20 -> Mabana, Terrence Navarro | F20: 8 | G20: 7 | H20: 13 | I20: 10 | J20: 5 | K20: 15 | P20: =IF(COUNT($F20:$O20)=0,"",SUM($F20:$O20)) -> 58 | Q20: =IF(ISERROR(IF($P20="","",ROUND(($P20/$P$10)*$Q$10,2))),"",IF($P20="","",ROUND(($P20/$P$10)*$Q$10,2))) -> 82.86 | R20: =IF($Q20="","",ROUND($Q20*$R$10,2)) -> 16.57 | S20: 5 | T20: 17 | U20: 14 | V20: 6 | W20: 5 | AC20: =IF(COUNT($S20:$AB20)=0,"",SUM($S20:$AB20)) -> 47 | AD20: =IF(ISERROR(IF($AC20="","",ROUND(($AC20/$AC$10)*$AD$10,2))),"",IF($AC20="","",ROUND(($AC20/$AC$10)*$AD$10,2))) -> 72.31 | AE20: =IF($AD20="","",ROUND($AD20*$AE$10,2)) -> 43.39 | AF20: 37 | AG20: =IF(ISERROR(IF($AF20="","",ROUND(($AF20/$AF$10)*$AG$10,2))),"",IF($AF20="","",ROUND(($AF20/$AF$10)*$AG$10,2))) -> 92.5 | AH20: =IF($AG20="","",ROUND($AG20*$AH$10,2)) -> 18.5 | AI20: =IF(ISERROR(IF($AF20="","",ROUND(SUM($R20,$AE20,$AH20),2))),"",IF($AF20="","",ROUND(SUM($R20,$AE20,$AH20),2))) -> 78.46 | AJ20: =IF(ISERROR(IF($AF20="","",VLOOKUP(AI20,TRANSMUTATION_TABLE,4,TRUE))),"",IF($AF20="","",VLOOKUP(AI20,TRANSMUTATION_TABLE,4,TRUE))) -> 86
A21: 10 | B21: ='INPUT DATA'!B21 -> Mangao, John Carlo Tarroza | F21: 7 | G21: 8 | H21: 10 | I21: 8 | J21: 5 | K21: 14 | P21: =IF(COUNT($F21:$O21)=0,"",SUM($F21:$O21)) -> 52 | Q21: =IF(ISERROR(IF($P21="","",ROUND(($P21/$P$10)*$Q$10,2))),"",IF($P21="","",ROUND(($P21/$P$10)*$Q$10,2))) -> 74.29 | R21: =IF($Q21="","",ROUND($Q21*$R$10,2)) -> 14.86 | S21: 7 | T21: 16 | U21: 7 | V21: 10 | W21: 5 | AC21: =IF(COUNT($S21:$AB21)=0,"",SUM($S21:$AB21)) -> 45 | AD21: =IF(ISERROR(IF($AC21="","",ROUND(($AC21/$AC$10)*$AD$10,2))),"",IF($AC21="","",ROUND(($AC21/$AC$10)*$AD$10,2))) -> 69.23 | AE21: =IF($AD21="","",ROUND($AD21*$AE$10,2)) -> 41.54 | AF21: 37 | AG21: =IF(ISERROR(IF($AF21="","",ROUND(($AF21/$AF$10)*$AG$10,2))),"",IF($AF21="","",ROUND(($AF21/$AF$10)*$AG$10,2))) -> 92.5 | AH21: =IF($AG21="","",ROUND($AG21*$AH$10,2)) -> 18.5 | AI21: =IF(ISERROR(IF($AF21="","",ROUND(SUM($R21,$AE21,$AH21),2))),"",IF($AF21="","",ROUND(SUM($R21,$AE21,$AH21),2))) -> 74.9 | AJ21: =IF(ISERROR(IF($AF21="","",VLOOKUP(AI21,TRANSMUTATION_TABLE,4,TRUE))),"",IF($AF21="","",VLOOKUP(AI21,TRANSMUTATION_TABLE,4,TRUE))) -> 84
A22: 11 | B22: ='INPUT DATA'!B22 -> Manuel, Mathias Manzanes | D22: 0 | F22: 5 | G22: 6 | H22: 10 | P22: =IF(COUNT($F22:$O22)=0,"",SUM($F22:$O22)) -> 21 | Q22: =IF(ISERROR(IF($P22="","",ROUND(($P22/$P$10)*$Q$10,2))),"",IF($P22="","",ROUND(($P22/$P$10)*$Q$10,2))) -> 30 | R22: =IF($Q22="","",ROUND($Q22*$R$10,2)) -> 6 | S22: 5 | T22: 15 | AC22: =IF(COUNT($S22:$AB22)=0,"",SUM($S22:$AB22)) -> 20 | AD22: =IF(ISERROR(IF($AC22="","",ROUND(($AC22/$AC$10)*$AD$10,2))),"",IF($AC22="","",ROUND(($AC22/$AC$10)*$AD$10,2))) -> 30.77 | AE22: =IF($AD22="","",ROUND($AD22*$AE$10,2)) -> 18.46 | AG22: =IF(ISERROR(IF($AF22="","",ROUND(($AF22/$AF$10)*$AG$10,2))),"",IF($AF22="","",ROUND(($AF22/$AF$10)*$AG$10,2))) | AH22: =IF($AG22="","",ROUND($AG22*$AH$10,2)) | AI22: =IF(ISERROR(IF($AF22="","",ROUND(SUM($R22,$AE22,$AH22),2))),"",IF($AF22="","",ROUND(SUM($R22,$AE22,$AH22),2))) | AJ22: =IF(ISERROR(IF($AF22="","",VLOOKUP(AI22,TRANSMUTATION_TABLE,4,TRUE))),"",IF($AF22="","",VLOOKUP(AI22,TRANSMUTATION_TABLE,4,TRUE)))
A23: 12 | B23: ='INPUT DATA'!B23 -> Pleno, James Andrei Dizon | F23: 9 | G23: 8 | H23: 15 | I23: 10 | J23: 10 | K23: 15 | P23: =IF(COUNT($F23:$O23)=0,"",SUM($F23:$O23)) -> 67 | Q23: =IF(ISERROR(IF($P23="","",ROUND(($P23/$P$10)*$Q$10,2))),"",IF($P23="","",ROUND(($P23/$P$10)*$Q$10,2))) -> 95.71 | R23: =IF($Q23="","",ROUND($Q23*$R$10,2)) -> 19.14 | S23: 9 | T23: 18 | U23: 5 | V23: 5 | W23: 6 | AC23: =IF(COUNT($S23:$AB23)=0,"",SUM($S23:$AB23)) -> 43 | AD23: =IF(ISERROR(IF($AC23="","",ROUND(($AC23/$AC$10)*$AD$10,2))),"",IF($AC23="","",ROUND(($AC23/$AC$10)*$AD$10,2))) -> 66.15 | AE23: =IF($AD23="","",ROUND($AD23*$AE$10,2)) -> 39.69 | AF23: 39 | AG23: =IF(ISERROR(IF($AF23="","",ROUND(($AF23/$AF$10)*$AG$10,2))),"",IF($AF23="","",ROUND(($AF23/$AF$10)*$AG$10,2))) -> 97.5 | AH23: =IF($AG23="","",ROUND($AG23*$AH$10,2)) -> 19.5 | AI23: =IF(ISERROR(IF($AF23="","",ROUND(SUM($R23,$AE23,$AH23),2))),"",IF($AF23="","",ROUND(SUM($R23,$AE23,$AH23),2))) -> 78.33 | AJ23: =IF(ISERROR(IF($AF23="","",VLOOKUP(AI23,TRANSMUTATION_TABLE,4,TRUE))),"",IF($AF23="","",VLOOKUP(AI23,TRANSMUTATION_TABLE,4,TRUE))) -> 86
A24: 13 | B24: ='INPUT DATA'!B24 -> Reyes, Brionne Ysmael | F24: 8 | G24: 9 | H24: 5 | I24: 10 | J24: 5 | K24: 15 | P24: =IF(COUNT($F24:$O24)=0,"",SUM($F24:$O24)) -> 52 | Q24: =IF(ISERROR(IF($P24="","",ROUND(($P24/$P$10)*$Q$10,2))),"",IF($P24="","",ROUND(($P24/$P$10)*$Q$10,2))) -> 74.29 | R24: =IF($Q24="","",ROUND($Q24*$R$10,2)) -> 14.86 | S24: 8 | T24: 18 | U24: 5 | V24: 10 | W24: 9 | AC24: =IF(COUNT($S24:$AB24)=0,"",SUM($S24:$AB24)) -> 50 | AD24: =IF(ISERROR(IF($AC24="","",ROUND(($AC24/$AC$10)*$AD$10,2))),"",IF($AC24="","",ROUND(($AC24/$AC$10)*$AD$10,2))) -> 76.92 | AE24: =IF($AD24="","",ROUND($AD24*$AE$10,2)) -> 46.15 | AF24: 36 | AG24: =IF(ISERROR(IF($AF24="","",ROUND(($AF24/$AF$10)*$AG$10,2))),"",IF($AF24="","",ROUND(($AF24/$AF$10)*$AG$10,2))) -> 90 | AH24: =IF($AG24="","",ROUND($AG24*$AH$10,2)) -> 18 | AI24: =IF(ISERROR(IF($AF24="","",ROUND(SUM($R24,$AE24,$AH24),2))),"",IF($AF24="","",ROUND(SUM($R24,$AE24,$AH24),2))) -> 79.01 | AJ24: =IF(ISERROR(IF($AF24="","",VLOOKUP(AI24,TRANSMUTATION_TABLE,4,TRUE))),"",IF($AF24="","",VLOOKUP(AI24,TRANSMUTATION_TABLE,4,TRUE))) -> 86
A25: 14 | B25: ='INPUT DATA'!B25 -> Rosales, John Mc Brandon Patubo | F25: 9 | G25: 8 | H25: 10 | I25: 10 | J25: 10 | K25: 15 | P25: =IF(COUNT($F25:$O25)=0,"",SUM($F25:$O25)) -> 62 | Q25: =IF(ISERROR(IF($P25="","",ROUND(($P25/$P$10)*$Q$10,2))),"",IF($P25="","",ROUND(($P25/$P$10)*$Q$10,2))) -> 88.57 | R25: =IF($Q25="","",ROUND($Q25*$R$10,2)) -> 17.71 | S25: 9 | T25: 17 | U25: 10 | V25: 6 | W25: 6 | AC25: =IF(COUNT($S25:$AB25)=0,"",SUM($S25:$AB25)) -> 48 | AD25: =IF(ISERROR(IF($AC25="","",ROUND(($AC25/$AC$10)*$AD$10,2))),"",IF($AC25="","",ROUND(($AC25/$AC$10)*$AD$10,2))) -> 73.85 | AE25: =IF($AD25="","",ROUND($AD25*$AE$10,2)) -> 44.31 | AF25: 39 | AG25: =IF(ISERROR(IF($AF25="","",ROUND(($AF25/$AF$10)*$AG$10,2))),"",IF($AF25="","",ROUND(($AF25/$AF$10)*$AG$10,2))) -> 97.5 | AH25: =IF($AG25="","",ROUND($AG25*$AH$10,2)) -> 19.5 | AI25: =IF(ISERROR(IF($AF25="","",ROUND(SUM($R25,$AE25,$AH25),2))),"",IF($AF25="","",ROUND(SUM($R25,$AE25,$AH25),2))) -> 81.52 | AJ25: =IF(ISERROR(IF($AF25="","",VLOOKUP(AI25,TRANSMUTATION_TABLE,4,TRUE))),"",IF($AF25="","",VLOOKUP(AI25,TRANSMUTATION_TABLE,4,TRUE))) -> 88
A26: 15 | B26: ='INPUT DATA'!B26 -> Rosales, Jhon Vinvie Felicidad | F26: 8 | G26: 9 | H26: 11 | I26: 8 | J26: 10 | K26: 15 | P26: =IF(COUNT($F26:$O26)=0,"",SUM($F26:$O26)) -> 61 | Q26: =IF(ISERROR(IF($P26="","",ROUND(($P26/$P$10)*$Q$10,2))),"",IF($P26="","",ROUND(($P26/$P$10)*$Q$10,2))) -> 87.14 | R26: =IF($Q26="","",ROUND($Q26*$R$10,2)) -> 17.43 | S26: 8 | T26: 17 | U26: 15 | V26: 9 | W26: 10 | AC26: =IF(COUNT($S26:$AB26)=0,"",SUM($S26:$AB26)) -> 59 | AD26: =IF(ISERROR(IF($AC26="","",ROUND(($AC26/$AC$10)*$AD$10,2))),"",IF($AC26="","",ROUND(($AC26/$AC$10)*$AD$10,2))) -> 90.77 | AE26: =IF($AD26="","",ROUND($AD26*$AE$10,2)) -> 54.46 | AF26: 30 | AG26: =IF(ISERROR(IF($AF26="","",ROUND(($AF26/$AF$10)*$AG$10,2))),"",IF($AF26="","",ROUND(($AF26/$AF$10)*$AG$10,2))) -> 75 | AH26: =IF($AG26="","",ROUND($AG26*$AH$10,2)) -> 15 | AI26: =IF(ISERROR(IF($AF26="","",ROUND(SUM($R26,$AE26,$AH26),2))),"",IF($AF26="","",ROUND(SUM($R26,$AE26,$AH26),2))) -> 86.89 | AJ26: =IF(ISERROR(IF($AF26="","",VLOOKUP(AI26,TRANSMUTATION_TABLE,4,TRUE))),"",IF($AF26="","",VLOOKUP(AI26,TRANSMUTATION_TABLE,4,TRUE))) -> 91
A27: 16 | B27: ='INPUT DATA'!B27 -> Tolentino, John Noel Cabrera | F27: 7 | G27: 8 | H27: 12 | I27: 10 | J27: 9 | K27: 15 | P27: =IF(COUNT($F27:$O27)=0,"",SUM($F27:$O27)) -> 61 | Q27: =IF(ISERROR(IF($P27="","",ROUND(($P27/$P$10)*$Q$10,2))),"",IF($P27="","",ROUND(($P27/$P$10)*$Q$10,2))) -> 87.14 | R27: =IF($Q27="","",ROUND($Q27*$R$10,2)) -> 17.43 | S27: 8 | T27: 18 | U27: 13 | V27: 9 | W27: 8 | AC27: =IF(COUNT($S27:$AB27)=0,"",SUM($S27:$AB27)) -> 56 | AD27: =IF(ISERROR(IF($AC27="","",ROUND(($AC27/$AC$10)*$AD$10,2))),"",IF($AC27="","",ROUND(($AC27/$AC$10)*$AD$10,2))) -> 86.15 | AE27: =IF($AD27="","",ROUND($AD27*$AE$10,2)) -> 51.69 | AF27: 37 | AG27: =IF(ISERROR(IF($AF27="","",ROUND(($AF27/$AF$10)*$AG$10,2))),"",IF($AF27="","",ROUND(($AF27/$AF$10)*$AG$10,2))) -> 92.5 | AH27: =IF($AG27="","",ROUND($AG27*$AH$10,2)) -> 18.5 | AI27: =IF(ISERROR(IF($AF27="","",ROUND(SUM($R27,$AE27,$AH27),2))),"",IF($AF27="","",ROUND(SUM($R27,$AE27,$AH27),2))) -> 87.62 | AJ27: =IF(ISERROR(IF($AF27="","",VLOOKUP(AI27,TRANSMUTATION_TABLE,4,TRUE))),"",IF($AF27="","",VLOOKUP(AI27,TRANSMUTATION_TABLE,4,TRUE))) -> 92
A28: 17 | B28: ='INPUT DATA'!B28 -> Traya, John Romeo Villanueva | F28: 8 | G28: 8 | H28: 10 | I28: 10 | J28: 10 | K28: 15 | P28: =IF(COUNT($F28:$O28)=0,"",SUM($F28:$O28)) -> 61 | Q28: =IF(ISERROR(IF($P28="","",ROUND(($P28/$P$10)*$Q$10,2))),"",IF($P28="","",ROUND(($P28/$P$10)*$Q$10,2))) -> 87.14 | R28: =IF($Q28="","",ROUND($Q28*$R$10,2)) -> 17.43 | S28: 6 | T28: 18 | U28: 14 | V28: 6 | W28: 7 | AC28: =IF(COUNT($S28:$AB28)=0,"",SUM($S28:$AB28)) -> 51 | AD28: =IF(ISERROR(IF($AC28="","",ROUND(($AC28/$AC$10)*$AD$10,2))),"",IF($AC28="","",ROUND(($AC28/$AC$10)*$AD$10,2))) -> 78.46 | AE28: =IF($AD28="","",ROUND($AD28*$AE$10,2)) -> 47.08 | AF28: 29 | AG28: =IF(ISERROR(IF($AF28="","",ROUND(($AF28/$AF$10)*$AG$10,2))),"",IF($AF28="","",ROUND(($AF28/$AF$10)*$AG$10,2))) -> 72.5 | AH28: =IF($AG28="","",ROUND($AG28*$AH$10,2)) -> 14.5 | AI28: =IF(ISERROR(IF($AF28="","",ROUND(SUM($R28,$AE28,$AH28),2))),"",IF($AF28="","",ROUND(SUM($R28,$AE28,$AH28),2))) -> 79.01 | AJ28: =IF(ISERROR(IF($AF28="","",VLOOKUP(AI28,TRANSMUTATION_TABLE,4,TRUE))),"",IF($AF28="","",VLOOKUP(AI28,TRANSMUTATION_TABLE,4,TRUE))) -> 86
A29: 18 | B29: ='INPUT DATA'!B29 -> Villafuerte, Ken Buan | F29: 9 | G29: 9 | H29: 15 | I29: 10 | J29: 10 | K29: 15 | P29: =IF(COUNT($F29:$O29)=0,"",SUM($F29:$O29)) -> 68 | Q29: =IF(ISERROR(IF($P29="","",ROUND(($P29/$P$10)*$Q$10,2))),"",IF($P29="","",ROUND(($P29/$P$10)*$Q$10,2))) -> 97.14 | R29: =IF($Q29="","",ROUND($Q29*$R$10,2)) -> 19.43 | S29: 8 | T29: 18 | U29: 15 | V29: 7 | W29: 10 | AC29: =IF(COUNT($S29:$AB29)=0,"",SUM($S29:$AB29)) -> 58 | AD29: =IF(ISERROR(IF($AC29="","",ROUND(($AC29/$AC$10)*$AD$10,2))),"",IF($AC29="","",ROUND(($AC29/$AC$10)*$AD$10,2))) -> 89.23 | AE29: =IF($AD29="","",ROUND($AD29*$AE$10,2)) -> 53.54 | AF29: 36 | AG29: =IF(ISERROR(IF($AF29="","",ROUND(($AF29/$AF$10)*$AG$10,2))),"",IF($AF29="","",ROUND(($AF29/$AF$10)*$AG$10,2))) -> 90 | AH29: =IF($AG29="","",ROUND($AG29*$AH$10,2)) -> 18 | AI29: =IF(ISERROR(IF($AF29="","",ROUND(SUM($R29,$AE29,$AH29),2))),"",IF($AF29="","",ROUND(SUM($R29,$AE29,$AH29),2))) -> 90.97 | AJ29: =IF(ISERROR(IF($AF29="","",VLOOKUP(AI29,TRANSMUTATION_TABLE,4,TRUE))),"",IF($AF29="","",VLOOKUP(AI29,TRANSMUTATION_TABLE,4,TRUE))) -> 94
A30: 19 | B30: ='INPUT DATA'!B30 -> Pangilinan, David Dweyn | F30: 8 | G30: 7 | H30: 5 | I30: 9 | J30: 5 | K30: 5 | P30: =IF(COUNT($F30:$O30)=0,"",SUM($F30:$O30)) -> 39 | Q30: =IF(ISERROR(IF($P30="","",ROUND(($P30/$P$10)*$Q$10,2))),"",IF($P30="","",ROUND(($P30/$P$10)*$Q$10,2))) -> 55.71 | R30: =IF($Q30="","",ROUND($Q30*$R$10,2)) -> 11.14 | S30: 9 | T30: 17 | U30: 5 | V30: 6 | W30: 5 | AC30: =IF(COUNT($S30:$AB30)=0,"",SUM($S30:$AB30)) -> 42 | AD30: =IF(ISERROR(IF($AC30="","",ROUND(($AC30/$AC$10)*$AD$10,2))),"",IF($AC30="","",ROUND(($AC30/$AC$10)*$AD$10,2))) -> 64.62 | AE30: =IF($AD30="","",ROUND($AD30*$AE$10,2)) -> 38.77 | AF30: 33 | AG30: =IF(ISERROR(IF($AF30="","",ROUND(($AF30/$AF$10)*$AG$10,2))),"",IF($AF30="","",ROUND(($AF30/$AF$10)*$AG$10,2))) -> 82.5 | AH30: =IF($AG30="","",ROUND($AG30*$AH$10,2)) -> 16.5 | AI30: =IF(ISERROR(IF($AF30="","",ROUND(SUM($R30,$AE30,$AH30),2))),"",IF($AF30="","",ROUND(SUM($R30,$AE30,$AH30),2))) -> 66.41 | AJ30: =IF(ISERROR(IF($AF30="","",VLOOKUP(AI30,TRANSMUTATION_TABLE,4,TRUE))),"",IF($AF30="","",VLOOKUP(AI30,TRANSMUTATION_TABLE,4,TRUE))) -> 79
A31: 20 | B31: ='INPUT DATA'!B31 -> 0 | P31: =IF(COUNT($F31:$O31)=0,"",SUM($F31:$O31)) | Q31: =IF(ISERROR(IF($P31="","",ROUND(($P31/$P$10)*$Q$10,2))),"",IF($P31="","",ROUND(($P31/$P$10)*$Q$10,2))) | R31: =IF($Q31="","",ROUND($Q31*$R$10,2)) | AC31: =IF(COUNT($S31:$AB31)=0,"",SUM($S31:$AB31)) | AD31: =IF(ISERROR(IF($AC31="","",ROUND(($AC31/$AC$10)*$AD$10,2))),"",IF($AC31="","",ROUND(($AC31/$AC$10)*$AD$10,2))) | AE31: =IF($AD31="","",ROUND($AD31*$AE$10,2)) | AG31: =IF(ISERROR(IF($AF31="","",ROUND(($AF31/$AF$10)*$AG$10,2))),"",IF($AF31="","",ROUND(($AF31/$AF$10)*$AG$10,2))) | AH31: =IF($AG31="","",ROUND($AG31*$AH$10,2)) | AI31: =IF(ISERROR(IF($AF31="","",ROUND(SUM($R31,$AE31,$AH31),2))),"",IF($AF31="","",ROUND(SUM($R31,$AE31,$AH31),2))) | AJ31: =IF(ISERROR(IF($AF31="","",VLOOKUP(AI31,TRANSMUTATION_TABLE,4,TRUE))),"",IF($AF31="","",VLOOKUP(AI31,TRANSMUTATION_TABLE,4,TRUE)))
A32: 21 | B32: ='INPUT DATA'!B32 -> 0 | P32: =IF(COUNT($F32:$O32)=0,"",SUM($F32:$O32)) | Q32: =IF(ISERROR(IF($P32="","",ROUND(($P32/$P$10)*$Q$10,2))),"",IF($P32="","",ROUND(($P32/$P$10)*$Q$10,2))) | R32: =IF($Q32="","",ROUND($Q32*$R$10,2)) | AC32: =IF(COUNT($S32:$AB32)=0,"",SUM($S32:$AB32)) | AD32: =IF(ISERROR(IF($AC32="","",ROUND(($AC32/$AC$10)*$AD$10,2))),"",IF($AC32="","",ROUND(($AC32/$AC$10)*$AD$10,2))) | AE32: =IF($AD32="","",ROUND($AD32*$AE$10,2)) | AG32: =IF(ISERROR(IF($AF32="","",ROUND(($AF32/$AF$10)*$AG$10,2))),"",IF($AF32="","",ROUND(($AF32/$AF$10)*$AG$10,2))) | AH32: =IF($AG32="","",ROUND($AG32*$AH$10,2)) | AI32: =IF(ISERROR(IF($AF32="","",ROUND(SUM($R32,$AE32,$AH32),2))),"",IF($AF32="","",ROUND(SUM($R32,$AE32,$AH32),2))) | AJ32: =IF(ISERROR(IF($AF32="","",VLOOKUP(AI32,TRANSMUTATION_TABLE,4,TRUE))),"",IF($AF32="","",VLOOKUP(AI32,TRANSMUTATION_TABLE,4,TRUE)))
A33: 22 | B33: ='INPUT DATA'!B33 -> 0 | P33: =IF(COUNT($F33:$O33)=0,"",SUM($F33:$O33)) | Q33: =IF(ISERROR(IF($P33="","",ROUND(($P33/$P$10)*$Q$10,2))),"",IF($P33="","",ROUND(($P33/$P$10)*$Q$10,2))) | R33: =IF($Q33="","",ROUND($Q33*$R$10,2)) | AC33: =IF(COUNT($S33:$AB33)=0,"",SUM($S33:$AB33)) | AD33: =IF(ISERROR(IF($AC33="","",ROUND(($AC33/$AC$10)*$AD$10,2))),"",IF($AC33="","",ROUND(($AC33/$AC$10)*$AD$10,2))) | AE33: =IF($AD33="","",ROUND($AD33*$AE$10,2)) | AG33: =IF(ISERROR(IF($AF33="","",ROUND(($AF33/$AF$10)*$AG$10,2))),"",IF($AF33="","",ROUND(($AF33/$AF$10)*$AG$10,2))) | AH33: =IF($AG33="","",ROUND($AG33*$AH$10,2)) | AI33: =IF(ISERROR(IF($AF33="","",ROUND(SUM($R33,$AE33,$AH33),2))),"",IF($AF33="","",ROUND(SUM($R33,$AE33,$AH33),2))) | AJ33: =IF(ISERROR(IF($AF33="","",VLOOKUP(AI33,TRANSMUTATION_TABLE,4,TRUE))),"",IF($AF33="","",VLOOKUP(AI33,TRANSMUTATION_TABLE,4,TRUE)))
A34: 23 | B34: ='INPUT DATA'!B34 -> 0 | P34: =IF(COUNT($F34:$O34)=0,"",SUM($F34:$O34)) | Q34: =IF(ISERROR(IF($P34="","",ROUND(($P34/$P$10)*$Q$10,2))),"",IF($P34="","",ROUND(($P34/$P$10)*$Q$10,2))) | R34: =IF($Q34="","",ROUND($Q34*$R$10,2)) | AC34: =IF(COUNT($S34:$AB34)=0,"",SUM($S34:$AB34)) | AD34: =IF(ISERROR(IF($AC34="","",ROUND(($AC34/$AC$10)*$AD$10,2))),"",IF($AC34="","",ROUND(($AC34/$AC$10)*$AD$10,2))) | AE34: =IF($AD34="","",ROUND($AD34*$AE$10,2)) | AG34: =IF(ISERROR(IF($AF34="","",ROUND(($AF34/$AF$10)*$AG$10,2))),"",IF($AF34="","",ROUND(($AF34/$AF$10)*$AG$10,2))) | AH34: =IF($AG34="","",ROUND($AG34*$AH$10,2)) | AI34: =IF(ISERROR(IF($AF34="","",ROUND(SUM($R34,$AE34,$AH34),2))),"",IF($AF34="","",ROUND(SUM($R34,$AE34,$AH34),2))) | AJ34: =IF(ISERROR(IF($AF34="","",VLOOKUP(AI34,TRANSMUTATION_TABLE,4,TRUE))),"",IF($AF34="","",VLOOKUP(AI34,TRANSMUTATION_TABLE,4,TRUE)))
