Workbook
Name TRANSMUTATION_TABLE: 'DO NOT DELETE'!$G$2:$J$42

Sheet INPUT DATA
A1: Input Data Sheet for E-Class Record
C4: REGION | G4: III | L4: DIVISION | O4: CITY OF SAN FDO. | T4: DISTRICT | X4: NORTH
B5: SCHOOL NAME | G5: TELABASTAGAN INTEGRATED SCHOOL | T5: SCHOOL ID | X5: 500144 | AD5: SCHOOL YEAR | AG5: 2025-2026
F7: GRADE & SECTION: | K7: V-MAGSAYSAY | Q7: TEACHER: | S7: ADELIA M. MANARANG | AC7: SUBJECT: | AG7: EDUKASYON SA PAGPAPAKATAO
B8: LEARNERS' NAMES
B11: MALE
A12: 1 | B12: Abawag, Jasmin | C12: Abawag, Jasmin | D12: 0 | E12: 0
A13: 2 | B13: Baluyot Frias Jan Xevier | C13: Baluyot Frias Jan Xevier | D13: 0 | E13: 0
A14: 3 | B14: Batislaon,Aeron Carreon | C14: Batislaon,Aeron Carreon | D14: 0 | E14: 0
A15: 4 | B15: Bernardo Kurt Michael Riosa | C15: Bernardo Kurt Michael Riosa | D15: 0 | E15: 0
A16: 5 | B16: Buan, Cyrus Arvee Giongco | C16: Buan, Cyrus Arvee Giongco | D16: 0 | E16: 0
A17: 6 | B17: Cunanan, Prince Carl | C17: Cunanan, Prince Carl | D17: 0 | E17: 0
A18: 7 | B18: Goingco, Drake Calvin Bautista | C18: Goingco, Drake Calvin Bautista | D18: 0 | E18: 0
A19: 8 | B19: Infante, James Mendez | C19: Infante, James Mendez | D19: 0 | E19: 0
A20: 9 | B20: Lacson John Red Hernandez | C20: Lacson John Red Hernandez | D20: 0 | E20: 0
A21: 10 | B21: Limin,Jaslan Mangalindan | C21: Limin,Jaslan Mangalindan | D21: 0 | E21: 0
A22: 11 | B22: Lusung, Yuan Lein Rodriguez | C22: Lusung, Yuan Lein Rodriguez | D22: 0 | E22: D.
A23: 12 | B23: Macaspac, Matteo Dho Arcilla | C23: Macaspac, Matteo Dho Arcilla | D23: 0 | E23: 0
A24: 13 | B24: Miranda, Franz | C24: Miranda, Franz | D24: 0 | E24: 0
A25: 14 | B25: Nayanggazohann,Cedy | C25: Nayanggazohann,Cedy | D25: 0 | E25: 0
A26: 15 | B26: Quiambao, Harvin Miranda | C26: Quiambao, Harvin Miranda | D26: 0 | E26: 0
A27: 16 | B27: Reyes Mhon Vincent Corpuz | C27: Reyes Mhon Vincent Corpuz | D27: 0 | E27: 0
A28: 17 | B28: Meneje, Gelo S. | C28: Salunga Gelo M. | D28: 0 | E28: 0
A29: 18 | B29: Serrano, Aaron Kiel Dabu | C29: Serrano, Aaron Kiel Dabu | D29: 0 | E29: 0
A30: 19 | B30: Villamayon, Jasper Supang | C30: Villamayon, Jasper Supang | D30: 0 | E30: 0
A31: 20 | B31: Vistar, C-Jay Gomaga | C31: Vistar, C-Jay Gomaga | D31: 0 | E31: 0
A32: 21 | B32: Zapata, Xed Yuan Arcilla | C32: Zapata, Xed Yuan Arcilla | D32: 0 | E32: 0
A33: 22 | B33: Cardenio, John Henry | D33: 0 | E33: 0
A34: 23 | D34: 0 | E34: 0
A35: 24 | D35: 0 | E35: 0
A36: 25 | D36: 0 | E36: 0
A37: 26 | D37: 0 | E37: 0
A38: 27 | D38: 0 | E38: 0
D39: 0 | E39: 0
A40: 29 | C40: 0 | D40: 0 | E40: 0
A41: 30 | C41: 0 | D41: 0 | E41: 0
A42: 31 | C42: 0 | D42: 0 | E42: 0
A43: 32 | C43: 0 | D43: 0 | E43: 0
A44: 33 | C44: 0 | D44: 0 | E44: 0
A45: 34 | C45: 0 | D45: 0 | E45: 0
...

Sheet EsP_Q1
A1: Official E-Class Record in K to 12 Curriculum
C4: REGION | G4: ='INPUT DATA'!G4 -> III | L4: DIVISION | O4: ='INPUT DATA'!O4 -> CITY OF SAN FDO. | T4: DISTRICT | X4: ='INPUT DATA'!X4 -> NORTH
B5: SCHOOL NAME | G5: ='INPUT DATA'!G5 -> TELABASTAGAN INTEGRATED SCHOOL | T5: SCHOOL ID | X5: ='INPUT DATA'!X5 -> 500144 | AD5: SCHOOL YEAR | AG5: ='INPUT DATA'!AG5 -> 2025-2026
A7: FIRST QUARTER | F7: GRADE & SECTION: | K7: ='INPUT DATA'!K7 -> V-MAGSAYSAY | Q7: TEACHER: | S7: ='INPUT DATA'!S7 -> ADELIA M. MANARANG | AC7: SUBJECT: | AG7: ='INPUT DATA'!AG7 -> EDUKASYON SA PAGPAPAKATAO
B8: LEARNERS' NAMES | F8: WRITTEN WORKS (30%) | S8: PERFORMANCE TASKS (50%) | AF8: QUARTERLY ASSESSMENT (20%) | AI8: Initial | AJ8: Quarterly
F9: 1 | G9: 2 | H9: 3 | I9: 4 | J9: 5 | K9: 6 | L9: 7 | M9: 8 | N9: 9 | O9: 10 | P9: Total | Q9: PS | R9: WS | S9: 1 | T9: 2 | U9: 3 | V9: 4 | W9: 5 | X9: 6 | Y9: 7 | Z9: 8 | AA9: 9 | AB9: 10 | AC9: Total | AD9: PS | AE9: WS | AF9: 1 | AG9: PS | AH9: WS | AI9: 5 | AJ9: Grade
B10: HIGHEST POSSIBLE SCORE | F10: 10 | G10: 15 | H10: 10 | I10: 10 | J10: 10 | K10: 10 | L10: 10 | P10: =IF(COUNT($F10:$O10)=0,"",SUM($F10:$O10)) -> 75 | Q10: 100 | R10: 0.3 | S10: 10 | T10: 10 | U10: 10 | V10: 15 | W10: 10 | X10: 10 | AC10: =IF(COUNT($S10:$AB10)=0,"",SUM($S10:$AB10)) -> 65 | AD10: 100 | AE10: 0.5 | AF10: 50 | AG10: 100 | AH10: 0.2
B11: MALE
A12: 1 | B12: ='INPUT DATA'!B12 -> Abawag, Jasmin | F12: 9 | G12: 11 | H12: 7 | I12: 10 | J12: 9 | K12: 10 | L12: 8 | P12: =IF(COUNT($F12:$O12)=0,"",SUM($F12:$O12)) -> 64 | Q12: =IF(ISERROR(IF($P12="","",ROUND(($P12/$P$10)*$Q$10,2))),"",IF($P12="","",ROUND(($P12/$P$10)*$Q$10,2))) -> 85.33 | R12: =IF($Q12="","",ROUND($Q12*$R$10,2)) -> 25.6 | S12: 8 | T12: 10 | U12: 9 | V12: 14 | W12: 9 | X12: 9 | AC12: =IF(COUNT($S12:$AB12)=0,"",SUM($S12:$AB12)) -> 59 | AD12: =IF(ISERROR(IF($AC12="","",ROUND(($AC12/$AC$10)*$AD$10,2))),"",IF($AC12="","",ROUND(($AC12/$AC$10)*$AD$10,2))) -> 90.77 | AE12: =IF($AD12="","",ROUND($AD12*$AE$10,2)) -> 45.39 | AF12: 35 | AG12: =IF(ISERROR(IF($AF12="","",ROUND(($AF12/$AF$10)*$AG$10,2))),"",IF($AF12="","",ROUND(($AF12/$AF$10)*$AG$10,2))) -> 70 | AH12: =IF($AG12="","",ROUND($AG12*$AH$10,2)) -> 14 | AI12: =IF(ISERROR(IF($AF12="","",ROUND(SUM($R12,$AE12,$AH12),2))),"",IF($AF12="","",ROUND(SUM($R12,$AE12,$AH12),2))) -> 84.99 | AJ12: =IF(ISERROR(IF($AF12="","",VLOOKUP(AI12,TRANSMUTATION_TABLE,4,TRUE))),"",IF($AF12="","",VLOOKUP(AI12,TRANSMUTATION_TABLE,4,TRUE))) -> 90
A13: 2 | B13: ='INPUT DATA'!B13 -> Baluyot Frias Jan Xevier | F13: 7 | G13: 11 | H13: 2 | I13: 10 | J13: 2 | K13: 10 | L13: 2 | P13: =IF(COUNT($F13:$O13)=0,"",SUM($F13:$O13)) -> 44 | Q13: =IF(ISERROR(IF($P13="","",ROUND(($P13/$P$10)*$Q$10,2))),"",IF($P13="","",ROUND(($P13/$P$10)*$Q$10,2))) -> 58.67 | R13: =IF($Q13="","",ROUND($Q13*$R$10,2)) -> 17.6 | S13: 9 | T13: 2 | U13: 5 | V13: 12 | W13: 9 | X13: 9 | AC13: =IF(COUNT($S13:$AB13)=0,"",SUM($S13:$AB13)) -> 46 | AD13: =IF(ISERROR(IF($AC13="","",ROUND(($AC13/$AC$10)*$AD$10,2))),"",IF($AC13="","",ROUND(($AC13/$AC$10)*$AD$10,2))) -> 70.77 | AE13: =IF($AD13="","",ROUND($AD13*$AE$10,2)) -> 35.39 | AF13: 31 | AG13: =IF(ISERROR(IF($AF13="","",ROUND(($AF13/$AF$10)*$AG$10,2))),"",IF($AF13="","",ROUND(($AF13/$AF$10)*$AG$10,2))) -> 62 | AH13: =IF($AG13="","",ROUND($AG13*$AH$10,2)) -> 12.4 | AI13: =IF(ISERROR(IF($AF13="","",ROUND(SUM($R13,$AE13,$AH13),2))),"",IF($AF13="","",ROUND(SUM($R13,$AE13,$AH13),2))) -> 65.39 | AJ13: =IF(ISERROR(IF($AF13="","",VLOOKUP(AI13,TRANSMUTATION_TABLE,4,TRUE))),"",IF($AF13="","",VLOOKUP(AI13,TRANSMUTATION_TABLE,4,TRUE))) -> 78
A14: 3 | B14: ='INPUT DATA'!B14 -> Batislaon,Aeron Carreon | F14: 8 | G14: 11 | H14: 8 | I14: 6 | J14: 10 | K14: 9 | L14: 10 | P14: =IF(COUNT($F14:$O14)=0,"",SUM($F14:$O14)) -> 62 | Q14: =IF(ISERROR(IF($P14="","",ROUND(($P14/$P$10)*$Q$10,2))),"",IF($P14="","",ROUND(($P14/$P$10)*$Q$10,2))) -> 82.67 | R14: =IF($Q14="","",ROUND($Q14*$R$10,2)) -> 24.8 | S14: 8 | T14: 8 | U14: 5 | V14: 14 | W14: 10 | X14: 10 | AC14: =IF(COUNT($S14:$AB14)=0,"",SUM($S14:$AB14)) -> 55 | AD14: =IF(ISERROR(IF($AC14="","",ROUND(($AC14/$AC$10)*$AD$10,2))),"",IF($AC14="","",ROUND(($AC14/$AC$10)*$AD$10,2))) -> 84.62 | AE14: =IF($AD14="","",ROUND($AD14*$AE$10,2)) -> 42.31 | AF14: 46 | AG14: =IF(ISERROR(IF($AF14="","",ROUND(($AF14/$AF$10)*$AG$10,2))),"",IF($AF14="","",ROUND(($AF14/$AF$10)*$AG$10,2))) -> 92 | AH14: =IF($AG14="","",ROUND($AG14*$AH$10,2)) -> 18.4 | AI14: =IF(ISERROR(IF($AF14="","",ROUND(SUM($R14,$AE14,$AH14),2))),"",IF($AF14="","",ROUND(SUM($R14,$AE14,$AH14),2))) -> 85.51 | AJ14: =IF(ISERROR(IF($AF14="","",VLOOKUP(AI14,TRANSMUTATION_TABLE,4,TRUE))),"",IF($AF14="","",VLOOKUP(AI14,TRANSMUTATION_TABLE,4,TRUE))) -> 90
A15: 4 | B15: ='INPUT DATA'!B15 -> Bernardo Kurt Michael Riosa | F15: 8 | G15: 9 | H15: 2 | I15: 9 | J15: 7 | K15: 8 | L15: 4 | P15: =IF(COUNT($F15:$O15)=0,"",SUM($F15:$O15)) -> 47 | Q15: =IF(ISERROR(IF($P15="","",ROUND(($P15/$P$10)*$Q$10,2))),"",IF($P15="","",ROUND(($P15/$P$10)*$Q$10,2))) -> 62.67 | R15: =IF($Q15="","",ROUND($Q15*$R$10,2)) -> 18.8 | S15: 9 | T15: 9 | U15: 8 | V15: 12 | W15: 6 | X15: 9 | AC15: =IF(COUNT($S15:$AB15)=0,"",SUM($S15:$AB15)) -> 53 | AD15: =IF(ISERROR(IF($AC15="","",ROUND(($AC15/$AC$10)*$AD$10,2))),"",IF($AC15="","",ROUND(($AC15/$AC$10)*$AD$10,2))) -> 81.54 | AE15: =IF($AD15="","",ROUND($AD15*$AE$10,2)) -> 40.77 | AF15: 39 | AG15: =IF(ISERROR(IF($AF15="","",ROUND(($AF15/$AF$10)*$AG$10,2))),"",IF($AF15="","",ROUND(($AF15/$AF$10)*$AG$10,2))) -> 78 | AH15: =IF($AG15="","",ROUND($AG15*$AH$10,2)) -> 15.6 | AI15: =IF(ISERROR(IF($AF15="","",ROUND(SUM($R15,$AE15,$AH15),2))),"",IF($AF15="","",ROUND(SUM($R15,$AE15,$AH15),2))) -> 75.17 | AJ15: =IF(ISERROR(IF($AF15="","",VLOOKUP(AI15,TRANSMUTATION_TABLE,4,TRUE))),"",IF($AF15="","",VLOOKUP(AI15,TRANSMUTATION_TABLE,4,TRUE))) -> 84
A16: 5 | B16: ='INPUT DATA'!B16 -> Buan, Cyrus Arvee Giongco | F16: 8 | G16: 12 | H16: 10 | I16: 6 | J16: 2 | K16: 2 | L16: 10 | P16: =IF(COUNT($F16:$O16)=0,"",SUM($F16:$O16)) -> 50 | Q16: =IF(ISERROR(IF($P16="","",ROUND(($P16/$P$10)*$Q$10,2))),"",IF($P16="","",ROUND(($P16/$P$10)*$Q$10,2))) -> 66.67 | R16: =IF($Q16="","",ROUND($Q16*$R$10,2)) -> 20 | S16: 8 | T16: 2 | U16: 10 | V16: 12 | W16: 9 | X16: 9 | AC16: =IF(COUNT($S16:$AB16)=0,"",SUM($S16:$AB16)) -> 50 | AD16: =IF(ISERROR(IF($AC16="","",ROUND(($AC16/$AC$10)*$AD$10,2))),"",IF($AC16="","",ROUND(($AC16/$AC$10)*$AD$10,2))) -> 76.92 | AE16: =IF($AD16="","",ROUND($AD16*$AE$10,2)) -> 38.46 | AF16: 36 | AG16: =IF(ISERROR(IF($AF16="","",ROUND(($AF16/$AF$10)*$AG$10,2))),"",IF($AF16="","",ROUND(($AF16/$AF$10)*$AG$10,2))) -> 72 | AH16: =IF($AG16="","",ROUND($AG16*$AH$10,2)) -> 14.4 | AI16: =IF(ISERROR(IF($AF16="","",ROUND(SUM($R16,$AE16,$AH16),2))),"",IF($AF16="","",ROUND(SUM($R16,$AE16,$AH16),2))) -> 72.86 | AJ16: =IF(ISERROR(IF($AF16="","",VLOOKUP(AI16,TRANSMUTATION_TABLE,4,TRUE))),"",IF($AF16="","",VLOOKUP(AI16,TRANSMUTATION_TABLE,4,TRUE))) -> 83
A17: 6 | B17: ='INPUT DATA'!B17 -> Cunanan, Prince Carl | F17: 8 | G17: 6 | H17: 10 | I17: 7 | J17: 10 | K17: 9 | L17: 9 | P17: =IF(COUNT($F17:$O17)=0,"",SUM($F17:$O17)) -> 59 | Q17: =IF(ISERROR(IF($P17="","",ROUND(($P17/$P$10)*$Q$10,2))),"",IF($P17="","",ROUND(($P17/$P$10)*$Q$10,2))) -> 78.67 | R17: =IF($Q17="","",ROUND($Q17*$R$10,2)) -> 23.6 | S17: 6 | T17: 7 | U17: 8 | V17: 13 | W17: 5 | X17: 6 | AC17: =IF(COUNT($S17:$AB17)=0,"",SUM($S17:$AB17)) -> 45 | AD17: =IF(ISERROR(IF($AC17="","",ROUND(($AC17/$AC$10)*$AD$10,2))),"",IF($AC17="","",ROUND(($AC17/$AC$10)*$AD$10,2))) -> 69.23 | AE17: =IF($AD17="","",ROUND($AD17*$AE$10,2)) -> 34.62 | AF17: 31 | AG17: =IF(ISERROR(IF($AF17="","",ROUND(($AF17/$AF$10)*$AG$10,2))),"",IF($AF17="","",ROUND(($AF17/$AF$10)*$AG$10,2))) -> 62 | AH17: =IF($AG17="","",ROUND($AG17*$AH$10,2)) -> 12.4 | AI17: =IF(ISERROR(IF($AF17="","",ROUND(SUM($R17,$AE17,$AH17),2))),"",IF($AF17="","",ROUND(SUM($R17,$AE17,$AH17),2))) -> 70.62 | AJ17: =IF(ISERROR(IF($AF17="","",VLOOKUP(AI17,TRANSMUTATION_TABLE,4,TRUE))),"",IF($AF17="","",VLOOKUP(AI17,TRANSMUTATION_TABLE,4,TRUE))) -> 81
A18: 7 | B18: ='INPUT DATA'!B18 -> Goingco, Drake Calvin Bautista | F18: 9 | G18: 10 | H18: 10 | I18: 10 | J18: 10 | K18: 2 | L18: 8 | P18: =IF(COUNT($F18:$O18)=0,"",SUM($F18:$O18)) -> 59 | Q18: =IF(ISERROR(IF($P18="","",ROUND(($P18/$P$10)*$Q$10,2))),"",IF($P18="","",ROUND(($P18/$P$10)*$Q$10,2))) -> 78.67 | R18: =IF($Q18="","",ROUND($Q18*$R$10,2)) -> 23.6 | S18: 10 | T18: 10 | U18: 10 | V18: 15 | W18: 10 | X18: 10 | AC18: =IF(COUNT($S18:$AB18)=0,"",SUM($S18:$AB18)) -> 65 | AD18: =IF(ISERROR(IF($AC18="","",ROUND(($AC18/$AC$10)*$AD$10,2))),"",IF($AC18="","",ROUND(($AC18/$AC$10)*$AD$10,2))) -> 100 | AE18: =IF($AD18="","",ROUND($AD18*$AE$10,2)) -> 50 | AF18: 36 | AG18: =IF(ISERROR(IF($AF18="","",ROUND(($AF18/$AF$10)*$AG$10,2))),"",IF($AF18="","",ROUND(($AF18/$AF$10)*$AG$10,2))) -> 72 | AH18: =IF($AG18="","",ROUND($AG18*$AH$10,2)) -> 14.4 | AI18: =IF(ISERROR(IF($AF18="","",ROUND(SUM($R18,$AE18,$AH18),2))),"",IF($AF18="","",ROUND(SUM($R18,$AE18,$AH18),2))) -> 88 | AJ18: =IF(ISERROR(IF($AF18="","",VLOOKUP(AI18,TRANSMUTATION_TABLE,4,TRUE))),"",IF($AF18="","",VLOOKUP(AI18,TRANSMUTATION_TABLE,4,TRUE))) -> 92
A19: 8 | B19: ='INPUT DATA'!B19 -> Infante, James Mendez | D19: 0 | F19: 8 | G19: 11 | H19: 8 | I19: 8 | J19: 9 | K19: 7 | L19: 5 | P19: =IF(COUNT($F19:$O19)=0,"",SUM($F19:$O19)) -> 56 | Q19: =IF(ISERROR(IF($P19="","",ROUND(($P19/$P$10)*$Q$10,2))),"",IF($P19="","",ROUND(($P19/$P$10)*$Q$10,2))) -> 74.67 | R19: =IF($Q19="","",ROUND($Q19*$R$10,2)) -> 22.4 | S19: 9 | T19: 8 | U19: 7 | V19: 12 | W19: 5 | X19: 5 | AC19: =IF(COUNT($S19:$AB19)=0,"",SUM($S19:$AB19)) -> 46 | AD19: =IF(ISERROR(IF($AC19="","",ROUND(($AC19/$AC$10)*$AD$10,2))),"",IF($AC19="","",ROUND(($AC19/$AC$10)*$AD$10,2))) -> 70.77 | AE19: =IF($AD19="","",ROUND($AD19*$AE$10,2)) -> 35.39 | AF19: 37 | AG19: =IF(ISERROR(IF($AF19="","",ROUND(($AF19/$AF$10)*$AG$10,2))),"",IF($AF19="","",ROUND(($AF19/$AF$10)*$AG$10,2))) -> 74 | AH19: =IF($AG19="","",ROUND($AG19*$AH$10,2)) -> 14.8 | AI19: =IF(ISERROR(IF($AF19="","",ROUND(SUM($R19,$AE19,$AH19),2))),"",IF($AF19="","",ROUND(SUM($R19,$AE19,$AH19),2))) -> 72.59 | AJ19: =IF(ISERROR(IF($AF19="","",VLOOKUP(AI19,TRANSMUTATION_TABLE,4,TRUE))),"",IF($AF19="","",VLOOKUP(AI19,TRANSMUTATION_TABLE,4,TRUE))) -> 82
A20: 9 | B20: ='INPUT DATA'!B20 -> Lacson John Red Hernandez | F20: 7 | G20: 11 | H20: 7 | I20: 6 | J20: 10 | K20: 8 | L20: 9 | P20: =IF(COUNT($F20:$O20)=0,"",SUM($F20:$O20)) -> 58 | Q20: =IF(ISERROR(IF($P20="","",ROUND(($P20/$P$10)*$Q$10,2))),"",IF($P20="","",ROUND(($P20/$P$10)*$Q$10,2))) -> 77.33 | R20: =IF($Q20="","",ROUND($Q20*$R$10,2)) -> 23.2 | S20: 6 | T20: 10 | U20: 5 | V20: 11 | W20: 8 | X20: 6 | AC20: =IF(COUNT($S20:$AB20)=0,"",SUM($S20:$AB20)) -> 46 | AD20: =IF(ISERROR(IF($AC20="","",ROUND(($AC20/$AC$10)*$AD$10,2))),"",IF($AC20="","",ROUND(($AC20/$AC$10)*$AD$10,2))) -> 70.77 | AE20: =IF($AD20="","",ROUND($AD20*$AE$10,2)) -> 35.39 | AF20: 21 | AG20: =IF(ISERROR(IF($AF20="","",ROUND(($AF20/$AF$10)*$AG$10,2))),"",IF($AF20="","",ROUND(($AF20/$AF$10)*$AG$10,2))) -> 42 | AH20: =IF($AG20="","",ROUND($AG20*$AH$10,2)) -> 8.4 | AI20: =IF(ISERROR(IF($AF20="","",ROUND(SUM($R20,$AE20,$AH20),2))),"",IF($AF20="","",ROUND(SUM($R20,$AE20,$AH20),2))) -> 66.99 | AJ20: =IF(ISERROR(IF($AF20="","",VLOOKUP(AI20,TRANSMUTATION_TABLE,4,TRUE))),"",IF($AF20="","",VLOOKUP(AI20,TRANSMUTATION_TABLE,4,TRUE))) -> 79
A21: 10 | B21: ='INPUT DATA'!B21 -> Limin,Jaslan Mangalindan | F21: 8 | G21: 11 | H21: 2 | I21: 10 | J21: 10 | K21: 2 | L21: 10 | P21: =IF(COUNT($F21:$O21)=0,"",SUM($F21:$O21)) -> 53 | Q21: =IF(ISERROR(IF($P21="","",ROUND(($P21/$P$10)*$Q$10,2))),"",IF($P21="","",ROUND(($P21/$P$10)*$Q$10,2))) -> 70.67 | R21: =IF($Q21="","",ROUND($Q21*$R$10,2)) -> 21.2 | S21: 7 | T21: 10 | U21: 10 | V21: 12 | W21: 10 | X21: 6 | AC21: =IF(COUNT($S21:$AB21)=0,"",SUM($S21:$AB21)) -> 55 | AD21: =IF(ISERROR(IF($AC21="","",ROUND(($AC21/$AC$10)*$AD$10,2))),"",IF($AC21="","",ROUND(($AC21/$AC$10)*$AD$10,2))) -> 84.62 | AE21: =IF($AD21="","",ROUND($AD21*$AE$10,2)) -> 42.31 | AF21: 38 | AG21: =IF(ISERROR(IF($AF21="","",ROUND(($AF21/$AF$10)*$AG$10,2))),"",IF($AF21="","",ROUND(($AF21/$AF$10)*$AG$10,2))) -> 76 | AH21: =IF($AG21="","",ROUND($AG21*$AH$10,2)) -> 15.2 | AI21: =IF(ISERROR(IF($AF21="","",ROUND(SUM($R21,$AE21,$AH21),2))),"",IF($AF21="","",ROUND(SUM($R21,$AE21,$AH21),2))) -> 78.71 | AJ21: =IF(ISERROR(IF($AF21="","",VLOOKUP(AI21,TRANSMUTATION_TABLE,4,TRUE))),"",IF($AF21="","",VLOOKUP(AI21,TRANSMUTATION_TABLE,4,TRUE))) -> 86
A22: 11 | B22: ='INPUT DATA'!B22 -> Lusung, Yuan Lein Rodriguez | D22: 0 | F22: 9 | G22: 9 | H22: 7 | I22: 10 | J22: 10 | K22: 9 | L22: 10 | P22: =IF(COUNT($F22:$O22)=0,"",SUM($F22:$O22)) -> 64 | Q22: =IF(ISERROR(IF($P22="","",ROUND(($P22/$P$10)*$Q$10,2))),"",IF($P22="","",ROUND(($P22/$P$10)*$Q$10,2))) -> 85.33 | R22: =IF($Q22="","",ROUND($Q22*$R$10,2)) -> 25.6 | S22: 9 | T22: 10 | U22: 10 | V22: 14 | W22: 9 | X22: 10 | AC22: =IF(COUNT($S22:$AB22)=0,"",SUM($S22:$AB22)) -> 62 | AD22: =IF(ISERROR(IF($AC22="","",ROUND(($AC22/$AC$10)*$AD$10,2))),"",IF($AC22="","",ROUND(($AC22/$AC$10)*$AD$10,2))) -> 95.38 | AE22: =IF($AD22="","",ROUND($AD22*$AE$10,2)) -> 47.69 | AF22: 42 | AG22: =IF(ISERROR(IF($AF22="","",ROUND(($AF22/$AF$10)*$AG$10,2))),"",IF($AF22="","",ROUND(($AF22/$AF$10)*$AG$10,2))) -> 84 | AH22: =IF($AG22="","",ROUND($AG22*$AH$10,2)) -> 16.8 | AI22: =IF(ISERROR(IF($AF22="","",ROUND(SUM($R22,$AE22,$AH22),2))),"",IF($AF22="","",ROUND(SUM($R22,$AE22,$AH22),2))) -> 90.09 | AJ22: =IF(ISERROR(IF($AF22="","",VLOOKUP(AI22,TRANSMUTATION_TABLE,4,TRUE))),"",IF($AF22="","",VLOOKUP(AI22,TRANSMUTATION_TABLE,4,TRUE))) -> 93
A23: 12 | B23: ='INPUT DATA'!B23 -> Macaspac, Matteo Dho Arcilla | F23: 8 | G23: 11 | H23: 7 | I23: 9 | J23: 10 | K23: 9 | L23: 6 | P23: =IF(COUNT($F23:$O23)=0,"",SUM($F23:$O23)) -> 60 | Q23: =IF(ISERROR(IF($P23="","",ROUND(($P23/$P$10)*$Q$10,2))),"",IF($P23="","",ROUND(($P23/$P$10)*$Q$10,2))) -> 80 | R23: =IF($Q23="","",ROUND($Q23*$R$10,2)) -> 24 | S23: 8 | T23: 10 | U23: 10 | V23: 14 | W23: 8 | X23: 10 | AC23: =IF(COUNT($S23:$AB23)=0,"",SUM($S23:$AB23)) -> 60 | AD23: =IF(ISERROR(IF($AC23="","",ROUND(($AC23/$AC$10)*$AD$10,2))),"",IF($AC23="","",ROUND(($AC23/$AC$10)*$AD$10,2))) -> 92.31 | AE23: =IF($AD23="","",ROUND($AD23*$AE$10,2)) -> 46.16 | AF23: 25 | AG23: =IF(ISERROR(IF($AF23="","",ROUND(($AF23/$AF$10)*$AG$10,2))),"",IF($AF23="","",ROUND(($AF23/$AF$10)*$AG$10,2))) -> 50 | AH23: =IF($AG23="","",ROUND($AG23*$AH$10,2)) -> 10 | AI23: =IF(ISERROR(IF($AF23="","",ROUND(SUM($R23,$AE23,$AH23),2))),"",IF($AF23="","",ROUND(SUM($R23,$AE23,$AH23),2))) -> 80.16 | AJ23: =IF(ISERROR(IF($AF23="","",VLOOKUP(AI23,TRANSMUTATION_TABLE,4,TRUE))),"",IF($AF23="","",VLOOKUP(AI23,TRANSMUTATION_TABLE,4,TRUE))) -> 87
A24: 13 | B24: ='INPUT DATA'!B24 -> Miranda, Franz | F24: 8 | G24: 12 | H24: 7 | I24: 9 | J24: 10 | K24: 10 | L24: 10 | P24: =IF(COUNT($F24:$O24)=0,"",SUM($F24:$O24)) -> 66 | Q24: =IF(ISERROR(IF($P24="","",ROUND(($P24/$P$10)*$Q$10,2))),"",IF($P24="","",ROUND(($P24/$P$10)*$Q$10,2))) -> 88 | R24: =IF($Q24="","",ROUND($Q24*$R$10,2)) -> 26.4 | S24: 8 | T24: 9 | U24: 9 | V24: 14 | W24: 9 | X24: 9 | AC24: =IF(COUNT($S24:$AB24)=0,"",SUM($S24:$AB24)) -> 58 | AD24: =IF(ISERROR(IF($AC24="","",ROUND(($AC24/$AC$10)*$AD$10,2))),"",IF($AC24="","",ROUND(($AC24/$AC$10)*$AD$10,2))) -> 89.23 | AE24: =IF($AD24="","",ROUND($AD24*$AE$10,2)) -> 44.62 | AF24: 22 | AG24: =IF(ISERROR(IF($AF24="","",ROUND(($AF24/$AF$10)*$AG$10,2))),"",IF($AF24="","",ROUND(($AF24/$AF$10)*$AG$10,2))) -> 44 | AH24: =IF($AG24="","",ROUND($AG24*$AH$10,2)) -> 8.8 | AI24: =IF(ISERROR(IF($AF24="","",ROUND(SUM($R24,$AE24,$AH24),2))),"",IF($AF24="","",ROUND(SUM($R24,$AE24,$AH24),2))) -> 79.82 | AJ24: =IF(ISERROR(IF($AF24="","",VLOOKUP(AI24,TRANSMUTATION_TABLE,4,TRUE))),"",IF($AF24="","",VLOOKUP(AI24,TRANSMUTATION_TABLE,4,TRUE))) -> 87
A25: 14 | B25: ='INPUT DATA'!B25 -> Nayanggazohann,Cedy | F25: 8 | G25: 8 | H25: 2 | I25: 9 | J25: 8 | K25: 8 | L25: 5 | P25: =IF(COUNT($F25:$O25)=0,"",SUM($F25:$O25)) -> 48 | Q25: =IF(ISERROR(IF($P25="","",ROUND(($P25/$P$10)*$Q$10,2))),"",IF($P25="","",ROUND(($P25/$P$10)*$Q$10,2))) -> 64 | R25: =IF($Q25="","",ROUND($Q25*$R$10,2)) -> 19.2 | S25: 8 | T25: 10 | U25: 5 | V25: 13 | W25: 5 | X25: 6 | AC25: =IF(COUNT($S25:$AB25)=0,"",SUM($S25:$AB25)) -> 47 | AD25: =IF(ISERROR(IF($AC25="","",ROUND(($AC25/$AC$10)*$AD$10,2))),"",IF($AC25="","",ROUND(($AC25/$AC$10)*$AD$10,2))) -> 72.31 | AE25: =IF($AD25="","",ROUND($AD25*$AE$10,2)) -> 36.16 | AF25: 34 | AG25: =IF(ISERROR(IF($AF25="","",ROUND(($AF25/$AF$10)*$AG$10,2))),"",IF($AF25="","",ROUND(($AF25/$AF$10)*$AG$10,2))) -> 68 | AH25: =IF($AG25="","",ROUND($AG25*$AH$10,2)) -> 13.6 | AI25: =IF(ISERROR(IF($AF25="","",ROUND(SUM($R25,$AE25,$AH25),2))),"",IF($AF25="","",ROUND(SUM($R25,$AE25,$AH25),2))) -> 68.96 | AJ25: =IF(ISERROR(IF($AF25="","",VLOOKUP(AI25,TRANSMUTATION_TABLE,4,TRUE))),"",IF($AF25="","",VLOOKUP(AI25,TRANSMUTATION_TABLE,4,TRUE))) -> 80
A26: 15 | B26: ='INPUT DATA'!B26 -> Quiambao, Harvin Miranda | F26: 9 | G26: 11 | H26: 10 | I26: 8 | J26: 10 | K26: 10 | L26: 7 | P26: =IF(COUNT($F26:$O26)=0,"",SUM($F26:$O26)) -> 65 | Q26: =IF(ISERROR(IF($P26="","",ROUND(($P26/$P$10)*$Q$10,2))),"",IF($P26="","",ROUND(($P26/$P$10)*$Q$10,2))) -> 86.67 | R26: =IF($Q26="","",ROUND($Q26*$R$10,2)) -> 26 | S26: 7 | T26: 10 | U26: 8 | V26: 15 | W26: 8 | X26: 9 | AC26: =IF(COUNT($S26:$AB26)=0,"",SUM($S26:$AB26)) -> 57 | AD26: =IF(ISERROR(IF($AC26="","",ROUND(($AC26/$AC$10)*$AD$10,2))),"",IF($AC26="","",ROUND(($AC26/$AC$10)*$AD$10,2))) -> 87.69 | AE26: =IF($AD26="","",ROUND($AD26*$AE$10,2)) -> 43.85 | AF26: 45 | AG26: =IF(ISERROR(IF($AF26="","",ROUND(($AF26/$AF$10)*$AG$10,2))),"",IF($AF26="","",ROUND(($AF26/$AF$10)*$AG$10,2))) -> 90 | AH26: =IF($AG26="","",ROUND($AG26*$AH$10,2)) -> 18 | AI26: =IF(ISERROR(IF($AF26="","",ROUND(SUM($R26,$AE26,$AH26),2))),"",IF($AF26="","",ROUND(SUM($R26,$AE26,$AH26),2))) -> 87.85 | AJ26: =IF(ISERROR(IF($AF26="","",VLOOKUP(AI26,TRANSMUTATION_TABLE,4,TRUE))),"",IF($AF26="","",VLOOKUP(AI26,TRANSMUTATION_TABLE,4,TRUE))) -> 92
A27: 16 | B27: ='INPUT DATA'!B27 -> Reyes Mhon Vincent Corpuz | F27: 8 | G27: 5 | H27: 2 | I27: 10 | J27: 9 | K27: 7 | L27: 9 | P27: =IF(COUNT($F27:$O27)=0,"",SUM($F27:$O27)) -> 50 | Q27: =IF(ISERROR(IF($P27="","",ROUND(($P27/$P$10)*$Q$10,2))),"",IF($P27="","",ROUND(($P27/$P$10)*$Q$10,2))) -> 66.67 | R27: =IF($Q27="","",ROUND($Q27*$R$10,2)) -> 20 | S27: 6 | T27: 10 | U27: 9 | V27: 12 | W27: 10 | X27: 9 | AC27: =IF(COUNT($S27:$AB27)=0,"",SUM($S27:$AB27)) -> 56 | AD27: =IF(ISERROR(IF($AC27="","",ROUND(($AC27/$AC$10)*$AD$10,2))),"",IF($AC27="","",ROUND(($AC27/$AC$10)*$AD$10,2))) -> 86.15 | AE27: =IF($AD27="","",ROUND($AD27*$AE$10,2)) -> 43.08 | AF27: 33 | AG27: =IF(ISERROR(IF($AF27="","",ROUND(($AF27/$AF$10)*$AG$10,2))),"",IF($AF27="","",ROUND(($AF27/$AF$10)*$AG$10,2))) -> 66 | AH27: =IF($AG27="","",ROUND($AG27*$AH$10,2)) -> 13.2 | AI27: =IF(ISERROR(IF($AF27="","",ROUND(SUM($R27,$AE27,$AH27),2))),"",IF($AF27="","",ROUND(SUM($R27,$AE27,$AH27),2))) -> 76.28 | AJ27: =IF(ISERROR(IF($AF27="","",VLOOKUP(AI27,TRANSMUTATION_TABLE,4,TRUE))),"",IF($AF27="","",VLOOKUP(AI27,TRANSMUTATION_TABLE,4,TRUE))) -> 85
A28: 17 | B28: ='INPUT DATA'!B28 -> Meneje, Gelo S. | F28: 8 | G28: 10 | H28: 10 | I28: 9 | J28: 9 | K28: 10 | L28: 6 | P28: =IF(COUNT($F28:$O28)=0,"",SUM($F28:$O28)) -> 62 | Q28: =IF(ISERROR(IF($P28="","",ROUND(($P28/$P$10)*$Q$10,2))),"",IF($P28="","",ROUND(($P28/$P$10)*$Q$10,2))) -> 82.67 | R28: =IF($Q28="","",ROUND($Q28*$R$10,2)) -> 24.8 | S28: 8 | T28: 10 | U28: 8 | V28: 14 | W28: 6 | X28: 10 | AC28: =IF(COUNT($S28:$AB28)=0,"",SUM($S28:$AB28)) -> 56 | AD28: =IF(ISERROR(IF($AC28="","",ROUND(($AC28/$AC$10)*$AD$10,2))),"",IF($AC28="","",ROUND(($AC28/$AC$10)*$AD$10,2))) -> 86.15 | AE28: =IF($AD28="","",ROUND($AD28*$AE$10,2)) -> 43.08 | AF28: 30 | AG28: =IF(ISERROR(IF($AF28="","",ROUND(($AF28/$AF$10)*$AG$10,2))),"",IF($AF28="","",ROUND(($AF28/$AF$10)*$AG$10,2))) -> 60 | AH28: =IF($AG28="","",ROUND($AG28*$AH$10,2)) -> 12 | AI28: =IF(ISERROR(IF($AF28="","",ROUND(SUM($R28,$AE28,$AH28),2))),"",IF($AF28="","",ROUND(SUM($R28,$AE28,$AH28),2))) -> 79.88 | AJ28: =IF(ISERROR(IF($AF28="","",VLOOKUP(AI28,TRANSMUTATION_TABLE,4,TRUE))),"",IF($AF28="","",VLOOKUP(AI28,TRANSMUTATION_TABLE,4,TRUE))) -> 87
A29: 18 | B29: ='INPUT DATA'!B29 -> Serrano, Aaron Kiel Dabu | F29: 8 | G29: 12 | H29: 8 | I29: 10 | J29: 9 | K29: 10 | L29: 6 | P29: =IF(COUNT($F29:$O29)=0,"",SUM($F29:$O29)) -> 63 | Q29: =IF(ISERROR(IF($P29="","",ROUND(($P29/$P$10)*$Q$10,2))),"",IF($P29="","",ROUND(($P29/$P$10)*$Q$10,2))) -> 84 | R29: =IF($Q29="","",ROUND($Q29*$R$10,2)) -> 25.2 | S29: 8 | T29: 10 | U29: 9 | V29: 12 | W29: 9 | X29: 9 | AC29: =IF(COUNT($S29:$AB29)=0,"",SUM($S29:$AB29)) -> 57 | AD29: =IF(ISERROR(IF($AC29="","",ROUND(($AC29/$AC$10)*$AD$10,2))),"",IF($AC29="","",ROUND(($AC29/$AC$10)*$AD$10,2))) -> 87.69 | AE29: =IF($AD29="","",ROUND($AD29*$AE$10,2)) -> 43.85 | AF29: 38 | AG29: =IF(ISERROR(IF($AF29="","",ROUND(($AF29/$AF$10)*$AG$10,2))),"",IF($AF29="","",ROUND(($AF29/$AF$10)*$AG$10,2))) -> 76 | AH29: =IF($AG29="","",ROUND($AG29*$AH$10,2)) -> 15.2 | AI29: =IF(ISERROR(IF($AF29="","",ROUND(SUM($R29,$AE29,$AH29),2))),"",IF($AF29="","",ROUND(SUM($R29,$AE29,$AH29),2))) -> 84.25 | AJ29: =IF(ISERROR(IF($AF29="","",VLOOKUP(AI29,TRANSMUTATION_TABLE,4,TRUE))),"",IF($AF29="","",VLOOKUP(AI29,TRANSMUTATION_TABLE,4,TRUE))) -> 90
A30: 19 | B30: ='INPUT DATA'!B30 -> Villamayon, Jasper Supang | F30: 8 | G30: 9 | H30: 7 | I30: 10 | J30: 9 | K30: 2 | L30: 7 | P30: =IF(COUNT($F30:$O30)=0,"",SUM($F30:$O30)) -> 52 | Q30: =IF(ISERROR(IF($P30="","",ROUND(($P30/$P$10)*$Q$10,2))),"",IF($P30="","",ROUND(($P30/$P$10)*$Q$10,2))) -> 69.33 | R30: =IF($Q30="","",ROUND($Q30*$R$10,2)) -> 20.8 | S30: 7 | T30: 10 | U30: 9 | V30: 12 | W30: 6 | X30: 9 | AC30: =IF(COUNT($S30:$AB30)=0,"",SUM($S30:$AB30)) -> 53 | AD30: =IF(ISERROR(IF($AC30="","",ROUND(($AC30/$AC$10)*$AD$10,2))),"",IF($AC30="","",ROUND(($AC30/$AC$10)*$AD$10,2))) -> 81.54 | AE30: =IF($AD30="","",ROUND($AD30*$AE$10,2)) -> 40.77 | AF30: 24 | AG30: =IF(ISERROR(IF($AF30="","",ROUND(($AF30/$AF$10)*$AG$10,2))),"",IF($AF30="","",ROUND(($AF30/$AF$10)*$AG$10,2))) -> 48 | AH30: =IF($AG30="","",ROUND($AG30*$AH$10,2)) -> 9.6 | AI30: =IF(ISERROR(IF($AF30="","",ROUND(SUM($R30,$AE30,$AH30),2))),"",IF($AF30="","",ROUND(SUM($R30,$AE30,$AH30),2))) -> 71.17 | AJ30: =IF(ISERROR(IF($AF30="","",VLOOKUP(AI30,TRANSMUTATION_TABLE,4,TRUE))),"",IF($AF30="","",VLOOKUP(AI30,TRANSMUTATION_TABLE,4,TRUE))) -> 81
A31: 20 | B31: ='INPUT DATA'!B31 -> Vistar, C-Jay Gomaga | F31: 7 | G31: 3 | H31: 5 | I31: 7 | J31: 7 | K31: 2 | L31: 5 | P31: =IF(COUNT($F31:$O31)=0,"",SUM($F31:$O31)) -> 36 | Q31: =IF(ISERROR(IF($P31="","",ROUND(($P31/$P$10)*$Q$10,2))),"",IF($P31="","",ROUND(($P31/$P$10)*$Q$10,2))) -> 48 | R31: =IF($Q31="","",ROUND($Q31*$R$10,2)) -> 14.4 | S31: 8 | T31: 10 | U31: 9 | V31: 13 | W31: 5 | X31: 9 | AC31: =IF(COUNT($S31:$AB31)=0,"",SUM($S31:$AB31)) -> 54 | AD31: =IF(ISERROR(IF($AC31="","",ROUND(($AC31/$AC$10)*$AD$10,2))),"",IF($AC31="","",ROUND(($AC31/$AC$10)*$AD$10,2))) -> 83.08 | AE31: =IF($AD31="","",ROUND($AD31*$AE$10,2)) -> 41.54 | AF31: 12 | AG31: =IF(ISERROR(IF($AF31="","",ROUND(($AF31/$AF$10)*$AG$10,2))),"",IF($AF31="","",ROUND(($AF31/$AF$10)*$AG$10,2))) -> 24 | AH31: =IF($AG31="","",ROUND($AG31*$AH$10,2)) -> 4.8 | AI31: =IF(ISERROR(IF($AF31="","",ROUND(SUM($R31,$AE31,$AH31),2))),"",IF($AF31="","",ROUND(SUM($R31,$AE31,$AH31),2))) -> 60.74 | AJ31: =IF(ISERROR(IF($AF31="","",VLOOKUP(AI31,TRANSMUTATION_TABLE,4,TRUE))),"",IF($AF31="","",VLOOKUP(AI31,TRANSMUTATION_TABLE,4,TRUE))) -> 75
A32: 21 | B32: ='INPUT DATA'!B32 -> Zapata, Xed Yuan Arcilla | F32: 10 | G32: 9 | H32: 9 | I32: 10 | J32: 9 | K32: 10 | L32: 8 | P32: =IF(COUNT($F32:$O32)=0,"",SUM($F32:$O32)) -> 65 | Q32: =IF(ISERROR(IF($P32="","",ROUND(($P32/$P$10)*$Q$10,2))),"",IF($P32="","",ROUND(($P32/$P$10)*$Q$10,2))) -> 86.67 | R32: =IF($Q32="","",ROUND($Q32*$R$10,2)) -> 26 | S32: 9 | T32: 10 | U32: 8 | V32: 15 | W32: 10 | X32: 9 | AC32: =IF(COUNT($S32:$AB32)=0,"",SUM($S32:$AB32)) -> 61 | AD32: =IF(ISERROR(IF($AC32="","",ROUND(($AC32/$AC$10)*$AD$10,2))),"",IF($AC32="","",ROUND(($AC32/$AC$10)*$AD$10,2))) -> 93.85 | AE32: =IF($AD32="","",ROUND($AD32*$AE$10,2)) -> 46.93 | AF32: 42 | AG32: =IF(ISERROR(IF($AF32="","",ROUND(($AF32/$AF$10)*$AG$10,2))),"",IF($AF32="","",ROUND(($AF32/$AF$10)*$AG$10,2))) -> 84 | AH32: =IF($AG32="","",ROUND($AG32*$AH$10,2)) -> 16.8 | AI32: =IF(ISERROR(IF($AF32="","",ROUND(SUM($R32,$AE32,$AH32),2))),"",IF($AF32="","",ROUND(SUM($R32,$AE32,$AH32),2))) -> 89.73 | AJ32: =IF(ISERROR(IF($AF32="","",VLOOKUP(AI32,TRANSMUTATION_TABLE,4,TRUE))),"",IF($AF32="","",VLOOKUP(AI32,TRANSMUTATION_TABLE,4,TRUE))) -> 93
A33: 22 | B33: ='INPUT DATA'!B33 -> Cardenio, John Henry | F33: 5 | G33: 5 | H33: 5 | I33: 5 | J33: 7 | K33: 9 | L33: 5 | P33: =IF(COUNT($F33:$O33)=0,"",SUM($F33:$O33)) -> 41 | Q33: =IF(ISERROR(IF($P33="","",ROUND(($P33/$P$10)*$Q$10,2))),"",IF($P33="","",ROUND(($P33/$P$10)*$Q$10,2))) -> 54.67 | R33: =IF($Q33="","",ROUND($Q33*$R$10,2)) -> 16.4 | S33: 5 | T33: 5 | U33: 5 | V33: 9 | W33: 8 | X33: 9 | AC33: =IF(COUNT($S33:$AB33)=0,"",SUM($S33:$AB33)) -> 41 | AD33: =IF(ISERROR(IF($AC33="","",ROUND(($AC33/$AC$10)*$AD$10,2))),"",IF($AC33="","",ROUND(($AC33/$AC$10)*$AD$10,2))) -> 63.08 | AE33: =IF($AD33="","",ROUND($AD33*$AE$10,2)) -> 31.54 | AF33: 32 | AG33: =IF(ISERROR(IF($AF33="","",ROUND(($AF33/$AF$10)*$AG$10,2))),"",IF($AF33="","",ROUND(($AF33/$AF$10)*$AG$10,2))) -> 64 | AH33: =IF($AG33="","",ROUND($AG33*$AH$10,2)) -> 12.8 | AI33: =IF(ISERROR(IF($AF33="","",ROUND(SUM($R33,$AE33,$AH33),2))),"",IF($AF33="","",ROUND(SUM($R33,$AE33,$AH33),2))) -> 60.74 | AJ33: =IF(ISERROR(IF($AF33="","",VLOOKUP(AI33,TRANSMUTATION_TABLE,4,TRUE))),"",IF($AF33="","",VLOOKUP(AI33,TRANSMUTATION_TABLE,4,TRUE))) -> 75
A34: 23 | B34: ='INPUT DATA'!B34 -> 0 | P34: =IF(COUNT($F34:$O34)=0,"",SUM($F34:$O34)) | Q34: =IF(ISERROR(IF($P34="","",ROUND(($P34/$P$10)*$Q$10,2))),"",IF($P34="","",ROUND(($P34/$P$10)*$Q$10,2))) | R34: =IF($Q34="","",ROUND($Q34*$R$10,2)) | AC34: =IF(COUNT($S34:$AB34)=0,"",SUM($S34:$AB34)) | AD34: =IF(ISERROR(IF($AC34="","",ROUND(($AC34/$AC$10)*$AD$10,2))),"",IF($AC34="","",ROUND(($AC34/$AC$10)*$AD$10,2))) | AE34: =IF($AD34="","",ROUND($AD34*$AE$10,2)) | AG34: =IF(ISERROR(IF($AF34="","",ROUND(($AF34/$AF$10)*$AG$10,2))),"",IF($AF34="","",ROUND(($AF34/$AF$10)*$AG$10,2))) | AH34: =IF($AG34="","",ROUND($AG34*$AH$10,2)) | AI34: =IF(ISERROR(IF($AF34="","",ROUND(SUM($R34,$AE34,$AH34),2))),"",IF($AF34="","",ROUND(SUM($R34,$AE34,$AH34),2))) | AJ34: =IF(ISERROR(IF($AF34="","",VLOOKUP(AI34,TRANSMUTATION_TABLE,4,TRUE))),"",IF($AF34="","",VLOOKUP(AI34,TRANSMUTATION_TABLE,4,TRUE)))
A35: 24 | B35: ='INPUT DATA'!B35 -> 0 | P35: =IF(COUNT($F35:$O35)=0,"",SUM($F35:$O35)) | Q35: =IF(ISERROR(IF($P35="","",ROUND(($P35/$P$10)*$Q$10,2))),"",IF($P35="","",ROUND(($P35/$P$10)*$Q$10,2))) | R35: =IF($Q35="","",ROUND($Q35*$R$10,2)) | AC35: =IF(COUNT($S35:$AB35)=0,"",SUM($S35:$AB35)) | AD35: =IF(ISERROR(IF($AC35="","",ROUND(($AC35/$AC$10)*$AD$10,2))),"",IF($AC35="","",ROUND(($AC35/$AC$10)*$AD$10,2))) | AE35: =IF($AD35="","",ROUND($AD35*$AE$10,2)) | AG35: =IF(ISERROR(IF($AF35="","",ROUND(($AF35/$AF$10)*$AG$10,2))),"",IF($AF35="","",ROUND(($AF35/$AF$10)*$AG$10,2))) | AH35: =IF($AG35="","",ROUND($AG35*$AH$10,2)) | AI35: =IF(ISERROR(IF($AF35="","",ROUND(SUM($R35,$AE35,$AH35),2))),"",IF($AF35="","",ROUND(SUM($R35,$AE35,$AH35),2))) | AJ35: =IF(ISERROR(IF($AF35="","",VLOOKUP(AI35,TRANSMUTATION_TABLE,4,TRUE))),"",IF($AF35="","",VLOOKUP(AI35,TRANSMUTATION_TABLE,4,TRUE)))
A36: 25 | B36: ='INPUT DATA'!B36 -> 0 | P36: =IF(COUNT($F36:$O36)=0,"",SUM($F36:$O36)) | Q36: =IF(ISERROR(IF($P36="","",ROUND(($P36/$P$10)*$Q$10,2))),"",IF($P36="","",ROUND(($P36/$P$10)*$Q$10,2))) | R36: =IF($Q36="","",ROUND($Q36*$R$10,2)) | AC36: =IF(COUNT($S36:$AB36)=0,"",SUM($S36:$AB36)) | AD36: =IF(ISERROR(IF($AC36="","",ROUND(($AC36/$AC$10)*$AD$10,2))),"",IF($AC36="","",ROUND(($AC36/$AC$10)*$AD$10,2))) | AE36: =IF($AD36="","",ROUND($AD36*$AE$10,2)) | AG36: =IF(ISERROR(IF($AF36="","",ROUND(($AF36/$AF$10)*$AG$10,2))),"",IF($AF36="","",ROUND(($AF36/$AF$10)*$AG$10,2))) | AH36: =IF($AG36="","",ROUND($AG36*$AH$10,2)) | AI36: =IF(ISERROR(IF($AF36="","",ROUND(SUM($R36,$AE36,$AH36),2))),"",IF($AF36="","",ROUND(SUM($R36,$AE36,$AH36),2))) | AJ36: =IF(ISERROR(IF($AF36="","",VLOOKUP(AI36,TRANSMUTATION_TABLE,4,TRUE))),"",IF($AF36="","",VLOOKUP(AI36,TRANSMUTATION_TABLE,4,TRUE)))
A37: 26 | B37: ='INPUT DATA'!B37 -> 0 | P37: =IF(COUNT($F37:$O37)=0,"",SUM($F37:$O37)) | Q37: =IF(ISERROR(IF($P37="","",ROUND(($P37/$P$10)*$Q$10,2))),"",IF($P37="","",ROUND(($P37/$P$10)*$Q$10,2))) | R37: =IF($Q37="","",ROUND($Q37*$R$10,2)) | AC37: =IF(COUNT($S37:$AB37)=0,"",SUM($S37:$AB37)) | AD37: =IF(ISERROR(IF($AC37="","",ROUND(($AC37/$AC$10)*$AD$10,2))),"",IF($AC37="","",ROUND(($AC37/$AC$10)*$AD$10,2))) | AE37: =IF($AD37="","",ROUND($AD37*$AE$10,2)) | AG37: =IF(ISERROR(IF($AF37="","",ROUND(($AF37/$AF$10)*$AG$10,2))),"",IF($AF37="","",ROUND(($AF37/$AF$10)*$AG$10,2))) | AH37: =IF($AG37="","",ROUND($AG37*$AH$10,2)) | AI37: =IF(ISERROR(IF($AF37="","",ROUND(SUM($R37,$AE37,$AH37),2))),"",IF($AF37="","",ROUND(SUM($R37,$AE37,$AH37),2))) | AJ37: =IF(ISERROR(IF($AF37="","",VLOOKUP(AI37,TRANSMUTATION_TABLE,4,TRUE))),"",IF($AF37="","",VLOOKUP(AI37,TRANSMUTATION_TABLE,4,TRUE)))
A38: 27 | B38: ='INPUT DATA'!B38 -> 0 | P38: =IF(COUNT($F38:$O38)=0,"",SUM($F38:$O38)) | Q38: =IF(ISERROR(IF($P38="","",ROUND(($P38/$P$10)*$Q$10,2))),"",IF($P38="","",ROUND(($P38/$P$10)*$Q$10,2))) | R38: =IF($Q38="","",ROUND($Q38*$R$10,2)) | AC38: =IF(COUNT($S38:$AB38)=0,"",SUM($S38:$AB38)) | AD38: =IF(ISERROR(IF($AC38="","",ROUND(($AC38/$AC$10)*$AD$10,2))),"",IF($AC38="","",ROUND(($AC38/$AC$10)*$AD$10,2))) | AE38: =IF($AD38="","",ROUND($AD38*$AE$10,2)) | AG38: =IF(ISERROR(IF($AF38="","",ROUND(($AF38/$AF$10)*$AG$10,2))),"",IF($AF38="","",ROUND(($AF38/$AF$10)*$AG$10,2))) | AH38: =IF($AG38="","",ROUND($AG38*$AH$10,2)) | AI38: =IF(ISERROR(IF($AF38="","",ROUND(SUM($R38,$AE38,$AH38),2))),"",IF($AF38="","",ROUND(SUM($R38,$AE38,$AH38),2))) | AJ38: =IF(ISERROR(IF($AF38="","",VLOOKUP(AI38,TRANSMUTATION_TABLE,4,TRUE))),"",IF($AF38="","",VLOOKUP(AI38,TRANSMUTATION_TABLE,4,TRUE)))
A39: 28 | B39: ='INPUT DATA'!B39 -> 0 | P39: =IF(COUNT($F39:$O39)=0,"",SUM($F39:$O39)) | Q39: =IF(ISERROR(IF($P39="","",ROUND(($P39/$P$10)*$Q$10,2))),"",IF($P39="","",ROUND(($P39/$P$10)*$Q$10,2))) | R39: =IF($Q39="","",ROUND($Q39*$R$10,2)) | AC39: =IF(COUNT($S39:$AB39)=0,"",SUM($S39:$AB39)) | AD39: =IF(ISERROR(IF($AC39="","",ROUND(($AC39/$AC$10)*$AD$10,2))),"",IF($AC39="","",ROUND(($AC39/$AC$10)*$AD$10,2))) | AE39: =IF($AD39="","",ROUND($AD39*$AE$10,2)) | AG39: =IF(ISERROR(IF($AF39="","",ROUND(($AF39/$AF$10)*$AG$10,2))),"",IF($AF39="","",ROUND(($AF39/$AF$10)*$AG$10,2))) | AH39: =IF($AG39="","",ROUND($AG39*$AH$10,2)) | AI39: =IF(ISERROR(IF($AF39="","",ROUND(SUM($R39,$AE39,$AH39),2))),"",IF($AF39="","",ROUND(SUM($R39,$AE39,$AH39),2))) | AJ39: =IF(ISERROR(IF($AF39="","",VLOOKUP(AI39,TRANSMUTATION_TABLE,4,TRUE))),"",IF($AF39="","",VLOOKUP(AI39,TRANSMUTATION_TABLE,4,TRUE)))
A40: 29 | B40: ='INPUT DATA'!B40 -> 0 | P40: =IF(COUNT($F40:$O40)=0,"",SUM($F40:$O40)) | Q40: =IF(ISERROR(IF($P40="","",ROUND(($P40/$P$10)*$Q$10,2))),"",IF($P40="","",ROUND(($P40/$P$10)*$Q$10,2))) | R40: =IF($Q40="","",ROUND($Q40*$R$10,2)) | AC40: =IF(COUNT($S40:$AB40)=0,"",SUM($S40:$AB40)) | AD40: =IF(ISERROR(IF($AC40="","",ROUND(($AC40/$AC$10)*$AD$10,2))),"",IF($AC40="","",ROUND(($AC40/$AC$10)*$AD$10,2))) | AE40: =IF($AD40="","",ROUND($AD40*$AE$10,2)) | AG40: =IF(ISERROR(IF($AF40="","",ROUND(($AF40/$AF$10)*$AG$10,2))),"",IF($AF40="","",ROUND(($AF40/$AF$10)*$AG$10,2))) | AH40: =IF($AG40="","",ROUND($AG40*$AH$10,2)) | AI40: =IF(ISERROR(IF($AF40="","",ROUND(SUM($R40,$AE40,$AH40),2))),"",IF($AF40="","",ROUND(SUM($R40,$AE40,$AH40),2))) | AJ40: =IF(ISERROR(IF($AF40="","",VLOOKUP(AI40,TRANSMUTATION_TABLE,4,TRUE))),"",IF($AF40="","",VLOOKUP(AI40,TRANSMUTATION_TABLE,4,TRUE)))
A41: 30 | B41: ='INPUT DATA'!B41 -> 0 | P41: =IF(COUNT($F41:$O41)=0,"",SUM($F41:$O41)) | Q41: =IF(ISERROR(IF($P41="","",ROUND(($P41/$P$10)*$Q$10,2))),"",IF($P41="","",ROUND(($P41/$P$10)*$Q$10,2))) | R41: =IF($Q41="","",ROUND($Q41*$R$10,2)) | AC41: =IF(COUNT($S41:$AB41)=0,"",SUM($S41:$AB41)) | AD41: =IF(ISERROR(IF($AC41="","",ROUND(($AC41/$AC$10)*$AD$10,2))),"",IF($AC41="","",ROUND(($AC41/$AC$10)*$AD$10,2))) | AE41: =IF($AD41="","",ROUND($AD41*$AE$10,2)) | AG41: =IF(ISERROR(IF($AF41="","",ROUND(($AF41/$AF$10)*$AG$10,2))),"",IF($AF41="","",ROUND(($AF41/$AF$10)*$AG$10,2))) | AH41: =IF($AG41="","",ROUND($AG41*$AH$10,2)) | AI41: =IF(ISERROR(IF($AF41="","",ROUND(SUM($R41,$AE41,$AH41),2))),"",IF($AF41="","",ROUND(SUM($R41,$AE41,$AH41),2))) | AJ41: =IF(ISERROR(IF($AF41="","",VLOOKUP(AI41,TRANSMUTATION_TABLE,4,TRUE))),"",IF($AF41="","",VLOOKUP(AI41,TRANSMUTATION_TABLE,4,TRUE)))
A42: 31 | B42: ='INPUT DATA'!B42 -> 0 | P42: =IF(COUNT($F42:$O42)=0,"",SUM($F42:$O42)) | Q42: =IF(ISERROR(IF($P42="","",ROUND(($P42/$P$10)*$Q$10,2))),"",IF($P42="","",ROUND(($P42/$P$10)*$Q$10,2))) | R42: =IF($Q42="","",ROUND($Q42*$R$10,2)) | AC42: =IF(COUNT($S42:$AB42)=0,"",SUM($S42:$AB42)) | AD42: =IF(ISERROR(IF($AC42="","",ROUND(($AC42/$AC$10)*$AD$10,2))),"",IF($AC42="","",ROUND(($AC42/$AC$10)*$AD$10,2))) | AE42: =IF($AD42="","",ROUND($AD42*$AE$10,2)) | AG42: =IF(ISERROR(IF($AF42="","",ROUND(($AF42/$AF$10)*$AG$10,2))),"",IF($AF42="","",ROUND(($AF42/$AF$10)*$AG$10,2))) | AH42: =IF($AG42="","",ROUND($AG42*$AH$10,2)) | AI42: =IF(ISERROR(IF($AF42="","",ROUND(SUM($R42,$AE42,$AH42),2))),"",IF($AF42="","",ROUND(SUM($R42,$AE42,$AH42),2))) | AJ42: =IF(ISERROR(IF($AF42="","",VLOOKUP(AI42,TRANSMUTATION_TABLE,4,TRUE))),"",IF($AF42="","",VLOOKUP(AI42,TRANSMUTATION_TABLE,4,TRUE)))
A43: 32 | B43: ='INPUT DATA'!B43 -> 0 | P43: =IF(COUNT($F43:$O43)=0,"",SUM($F43:$O43)) | Q43: =IF(ISERROR(IF($P43="","",ROUND(($P43/$P$10)*$Q$10,2))),"",IF($P43="","",ROUND(($P43/$P$10)*$Q$10,2))) | R43: =IF($Q43="","",ROUND($Q43*$R$10,2)) | AC43: =IF(COUNT($S43:$AB43)=0,"",SUM($S43:$AB43)) | AD43: =IF(ISERROR(IF($AC43="","",ROUND(($AC43/$AC$10)*$AD$10,2))),"",IF($AC43="","",ROUND(($AC43/$AC$10)*$AD$10,2))) | AE43: =IF($AD43="","",ROUND($AD43*$AE$10,2)) | AG43: =IF(ISERROR(IF($AF43="","",ROUND(($AF43/$AF$10)*$AG$10,2))),"",IF($AF43="","",ROUND(($AF43/$AF$10)*$AG$10,2))) | AH43: =IF($AG43="","",ROUND($AG43*$AH$10,2)) | AI43: =IF(ISERROR(IF($AF43="","",ROUND(SUM($R43,$AE43,$AH43),2))),"",IF($AF43="","",ROUND(SUM($R43,$AE43,$AH43),2))) | AJ43: =IF(ISERROR(IF($AF43="","",VLOOKUP(AI43,TRANSMUTATION_TABLE,4,TRUE))),"",IF($AF43="","",VLOOKUP(AI43,TRANSMUTATION_TABLE,4,TRUE)))
...

Sheet Esp-Q2
A1: Official E-Class Record in K to 12 Curriculum
C4: REGION | G4: ='INPUT DATA'!G4 -> III | L4: DIVISION | O4: ='INPUT DATA'!O4 -> CITY OF SAN FDO. | T4: DISTRICT | X4: ='INPUT DATA'!X4 -> NORTH
B5: SCHOOL NAME | G5: ='INPUT DATA'!G5 -> TELABASTAGAN INTEGRATED SCHOOL | T5: SCHOOL ID | X5: ='INPUT DATA'!X5 -> 500144 | AD5: SCHOOL YEAR | AG5: ='INPUT DATA'!AG5 -> 2025-2026
A7: SECOND QUARTER | F7: GRADE & SECTION: | K7: ='INPUT DATA'!K7 -> V-MAGSAYSAY | Q7: TEACHER: | S7: ='INPUT DATA'!S7 -> ADELIA M. MANARANG | AC7: SUBJECT: | AG7: ='INPUT DATA'!AG7 -> EDUKASYON SA PAGPAPAKATAO
B8: LEARNERS' NAMES | F8: WRITTEN WORKS (30%) | S8: PERFORMANCE TASKS (50%) | AF8: QUARTERLY ASSESSMENT (20%) | AI8: Initial | AJ8: Quarterly
F9: 1 | G9: 2 | H9: 3 | I9: 4 | J9: 5 | K9: 6 | L9: 7 | M9: 8 | N9: 9 | O9: 10 | P9: Total | Q9: PS | R9: WS | S9: 1 | T9: 2 | U9: 3 | V9: 4 | W9: 5 | X9: 6 | Y9: 7 | Z9: 8 | AA9: 9 | AB9: 10 | AC9: Total | AD9: PS | AE9: WS | AF9: 1 | AG9: PS | AH9: WS | AI9: Grade | AJ9: Grade
B10: HIGHEST POSSIBLE SCORE | F10: 10 | G10: 10 | H10: 15 | I10: 10 | J10: 10 | K10: 10 | L10: 10 | P10: =IF(COUNT($F10:$O10)=0,"",SUM($F10:$O10)) -> 75 | Q10: 100 | R10: 0.3 | S10: 20 | T10: 10 | U10: 10 | V10: 20 | W10: 20 | X10: 10 | AC10: =IF(COUNT($S10:$AB10)=0,"",SUM($S10:$AB10)) -> 90 | AD10: 100 | AE10: 0.5 | AF10: 50 | AG10: 100 | AH10: 0.2
B11: MALE
A12: 1 | B12: ='INPUT DATA'!B12 -> Abawag, Jasmin | F12: 8 | G12: 9 | H12: 15 | I12: 10 | J12: 10 | K12: 7 | L12: 8 | P12: =IF(COUNT($F12:$O12)=0,"",SUM($F12:$O12)) -> 67 | Q12: =IF(ISERROR(IF($P12="","",ROUND(($P12/$P$10)*$Q$10,2))),"",IF($P12="","",ROUND(($P12/$P$10)*$Q$10,2))) -> 89.33 | R12: =IF($Q12="","",ROUND($Q12*$R$10,2)) -> 26.8 | S12: 20 | T12: 7 | U12: 8 | V12: 20 | W12: 15 | X12: 7 | AC12: =IF(COUNT($S12:$AB12)=0,"",SUM($S12:$AB12)) -> 77 | AD12: =IF(ISERROR(IF($AC12="","",ROUND(($AC12/$AC$10)*$AD$10,2))),"",IF($AC12="","",ROUND(($AC12/$AC$10)*$AD$10,2))) -> 85.56 | AE12: =IF($AD12="","",ROUND($AD12*$AE$10,2)) -> 42.78 | AF12: 48 | AG12: =IF(ISERROR(IF($AF12="","",ROUND(($AF12/$AF$10)*$AG$10,2))),"",IF($AF12="","",ROUND(($AF12/$AF$10)*$AG$10,2))) -> 96 | AH12: =IF($AG12="","",ROUND($AG12*$AH$10,2)) -> 19.2 | AI12: =IF(ISERROR(IF($AF12="","",ROUND(SUM($R12,$AE12,$AH12),2))),"",IF($AF12="","",ROUND(SUM($R12,$AE12,$AH12),2))) -> 88.78 | AJ12: =IF(ISERROR(IF($AF12="","",VLOOKUP(AI12,TRANSMUTATION_TABLE,4,TRUE))),"",IF($AF12="","",VLOOKUP(AI12,TRANSMUTATION_TABLE,4,TRUE))) -> 92
A13: 2 | B13: ='INPUT DATA'!B13 -> Baluyot Frias Jan Xevier | F13: 7 | G13: 9 | H13: 15 | I13: 5 | J13: 10 | K13: 8 | L13: 6 | P13: =IF(COUNT($F13:$O13)=0,"",SUM($F13:$O13)) -> 60 | Q13: =IF(ISERROR(IF($P13="","",ROUND(($P13/$P$10)*$Q$10,2))),"",IF($P13="","",ROUND(($P13/$P$10)*$Q$10,2))) -> 80 | R13: =IF($Q13="","",ROUND($Q13*$R$10,2)) -> 24 | S13: 17 | T13: 10 | U13: 5 | V13: 17 | W13: 10 | X13: 6 | AC13: =IF(COUNT($S13:$AB13)=0,"",SUM($S13:$AB13)) -> 65 | AD13: =IF(ISERROR(IF($AC13="","",ROUND(($AC13/$AC$10)*$AD$10,2))),"",IF($AC13="","",ROUND(($AC13/$AC$10)*$AD$10,2))) -> 72.22 | AE13: =IF($AD13="","",ROUND($AD13*$AE$10,2)) -> 36.11 | AF13: 46 | AG13: =IF(ISERROR(IF($AF13="","",ROUND(($AF13/$AF$10)*$AG$10,2))),"",IF($AF13="","",ROUND(($AF13/$AF$10)*$AG$10,2))) -> 92 | AH13: =IF($AG13="","",ROUND($AG13*$AH$10,2)) -> 18.4 | AI13: =IF(ISERROR(IF($AF13="","",ROUND(SUM($R13,$AE13,$AH13),2))),"",IF($AF13="","",ROUND(SUM($R13,$AE13,$AH13),2))) -> 78.51 | AJ13: =IF(ISERROR(IF($AF13="","",VLOOKUP(AI13,TRANSMUTATION_TABLE,4,TRUE))),"",IF($AF13="","",VLOOKUP(AI13,TRANSMUTATION_TABLE,4,TRUE))) -> 86
A14: 3 | B14: ='INPUT DATA'!B14 -> Batislaon,Aeron Carreon | F14: 8 | G14: 10 | H14: 5 | I14: 9 | J14: 9 | K14: 7 | L14: 7 | P14: =IF(COUNT($F14:$O14)=0,"",SUM($F14:$O14)) -> 55 | Q14: =IF(ISERROR(IF($P14="","",ROUND(($P14/$P$10)*$Q$10,2))),"",IF($P14="","",ROUND(($P14/$P$10)*$Q$10,2))) -> 73.33 | R14: =IF($Q14="","",ROUND($Q14*$R$10,2)) -> 22 | S14: 16 | T14: 10 | U14: 8 | V14: 10 | W14: 14 | X14: 9 | AC14: =IF(COUNT($S14:$AB14)=0,"",SUM($S14:$AB14)) -> 67 | AD14: =IF(ISERROR(IF($AC14="","",ROUND(($AC14/$AC$10)*$AD$10,2))),"",IF($AC14="","",ROUND(($AC14/$AC$10)*$AD$10,2))) -> 74.44 | AE14: =IF($AD14="","",ROUND($AD14*$AE$10,2)) -> 37.22 | AF14: 47 | AG14: =IF(ISERROR(IF($AF14="","",ROUND(($AF14/$AF$10)*$AG$10,2))),"",IF($AF14="","",ROUND(($AF14/$AF$10)*$AG$10,2))) -> 94 | AH14: =IF($AG14="","",ROUND($AG14*$AH$10,2)) -> 18.8 | AI14: =IF(ISERROR(IF($AF14="","",ROUND(SUM($R14,$AE14,$AH14),2))),"",IF($AF14="","",ROUND(SUM($R14,$AE14,$AH14),2))) -> 78.02 | AJ14: =IF(ISERROR(IF($AF14="","",VLOOKUP(AI14,TRANSMUTATION_TABLE,4,TRUE))),"",IF($AF14="","",VLOOKUP(AI14,TRANSMUTATION_TABLE,4,TRUE))) -> 86
A15: 4 | B15: ='INPUT DATA'!B15 -> Bernardo Kurt Michael Riosa | F15: 7 | G15: 9 | H15: 12 | I15: 8 | J15: 6 | K15: 6 | L15: 7 | P15: =IF(COUNT($F15:$O15)=0,"",SUM($F15:$O15)) -> 55 | Q15: =IF(ISERROR(IF($P15="","",ROUND(($P15/$P$10)*$Q$10,2))),"",IF($P15="","",ROUND(($P15/$P$10)*$Q$10,2))) -> 73.33 | R15: =IF($Q15="","",ROUND($Q15*$R$10,2)) -> 22 | S15: 18 | T15: 5 | U15: 7 | V15: 10 | W15: 16 | X15: 9 | AC15: =IF(COUNT($S15:$AB15)=0,"",SUM($S15:$AB15)) -> 65 | AD15: =IF(ISERROR(IF($AC15="","",ROUND(($AC15/$AC$10)*$AD$10,2))),"",IF($AC15="","",ROUND(($AC15/$AC$10)*$AD$10,2))) -> 72.22 | AE15: =IF($AD15="","",ROUND($AD15*$AE$10,2)) -> 36.11 | AF15: 41 | AG15: =IF(ISERROR(IF($AF15="","",ROUND(($AF15/$AF$10)*$AG$10,2))),"",IF($AF15="","",ROUND(($AF15/$AF$10)*$AG$10,2))) -> 82 | AH15: =IF($AG15="","",ROUND($AG15*$AH$10,2)) -> 16.4 | AI15: =IF(ISERROR(IF($AF15="","",ROUND(SUM($R15,$AE15,$AH15),2))),"",IF($AF15="","",ROUND(SUM($R15,$AE15,$AH15),2))) -> 74.51 | AJ15: =IF(ISERROR(IF($AF15="","",VLOOKUP(AI15,TRANSMUTATION_TABLE,4,TRUE))),"",IF($AF15="","",VLOOKUP(AI15,TRANSMUTATION_TABLE,4,TRUE))) -> 84
A16: 5 | B16: ='INPUT DATA'!B16 -> Buan, Cyrus Arvee Giongco | F16: 7 | G16: 5 | H16: 12 | I16: 7 | J16: 9 | K16: 6 | L16: 6 | P16: =IF(COUNT($F16:$O16)=0,"",SUM($F16:$O16)) -> 52 | Q16: =IF(ISERROR(IF($P16="","",ROUND(($P16/$P$10)*$Q$10,2))),"",IF($P16="","",ROUND(($P16/$P$10)*$Q$10,2))) -> 69.33 | R16: =IF($Q16="","",ROUND($Q16*$R$10,2)) -> 20.8 | S16: 10 | T16: 5 | U16: 7 | V16: 10 | W16: 17 | X16: 8 | AC16: =IF(COUNT($S16:$AB16)=0,"",SUM($S16:$AB16)) -> 57 | AD16: =IF(ISERROR(IF($AC16="","",ROUND(($AC16/$AC$10)*$AD$10,2))),"",IF($AC16="","",ROUND(($AC16/$AC$10)*$AD$10,2))) -> 63.33 | AE16: =IF($AD16="","",ROUND($AD16*$AE$10,2)) -> 31.67 | AF16: 42 | AG16: =IF(ISERROR(IF($AF16="","",ROUND(($AF16/$AF$10)*$AG$10,2))),"",IF($AF16="","",ROUND(($AF16/$AF$10)*$AG$10,2))) -> 84 | AH16: =IF($AG16="","",ROUND($AG16*$AH$10,2)) -> 16.8 | AI16: =IF(ISERROR(IF($AF16="","",ROUND(SUM($R16,$AE16,$AH16),2))),"",IF($AF16="","",ROUND(SUM($R16,$AE16,$AH16),2))) -> 69.27 | AJ16: =IF(ISERROR(IF($AF16="","",VLOOKUP(AI16,TRANSMUTATION_TABLE,4,TRUE))),"",IF($AF16="","",VLOOKUP(AI16,TRANSMUTATION_TABLE,4,TRUE))) -> 80
A17: 6 | B17: ='INPUT DATA'!B17 -> Cunanan, Prince Carl | F17: 8 | G17: 10 | H17: 10 | I17: 8 | J17: 8 | K17: 7 | L17: 8 | P17: =IF(COUNT($F17:$O17)=0,"",SUM($F17:$O17)) -> 59 | Q17: =IF(ISERROR(IF($P17="","",ROUND(($P17/$P$10)*$Q$10,2))),"",IF($P17="","",ROUND(($P17/$P$10)*$Q$10,2))) -> 78.67 | R17: =IF($Q17="","",ROUND($Q17*$R$10,2)) -> 23.6 | S17: 17 | T17: 5 | U17: 7 | V17: 10 | W17: 18 | X17: 9 | AC17: =IF(COUNT($S17:$AB17)=0,"",SUM($S17:$AB17)) -> 66 | AD17: =IF(ISERROR(IF($AC17="","",ROUND(($AC17/$AC$10)*$AD$10,2))),"",IF($AC17="","",ROUND(($AC17/$AC$10)*$AD$10,2))) -> 73.33 | AE17: =IF($AD17="","",ROUND($AD17*$AE$10,2)) -> 36.67 | AF17: 44 | AG17: =IF(ISERROR(IF($AF17="","",ROUND(($AF17/$AF$10)*$AG$10,2))),"",IF($AF17="","",ROUND(($AF17/$AF$10)*$AG$10,2))) -> 88 | AH17: =IF($AG17="","",ROUND($AG17*$AH$10,2)) -> 17.6 | AI17: =IF(ISERROR(IF($AF17="","",ROUND(SUM($R17,$AE17,$AH17),2))),"",IF($AF17="","",ROUND(SUM($R17,$AE17,$AH17),2))) -> 77.87 | AJ17: =IF(ISERROR(IF($AF17="","",VLOOKUP(AI17,TRANSMUTATION_TABLE,4,TRUE))),"",IF($AF17="","",VLOOKUP(AI17,TRANSMUTATION_TABLE,4,TRUE))) -> 86
A18: 7 | B18: ='INPUT DATA'!B18 -> Goingco, Drake Calvin Bautista | F18: 9 | G18: 10 | H18: 13 | I18: 8 | J18: 7 | K18: 8 | L18: 9 | P18: =IF(COUNT($F18:$O18)=0,"",SUM($F18:$O18)) -> 64 | Q18: =IF(ISERROR(IF($P18="","",ROUND(($P18/$P$10)*$Q$10,2))),"",IF($P18="","",ROUND(($P18/$P$10)*$Q$10,2))) -> 85.33 | R18: =IF($Q18="","",ROUND($Q18*$R$10,2)) -> 25.6 | S18: 17 | T18: 10 | U18: 9 | V18: 18 | W18: 19 | X18: 10 | AC18: =IF(COUNT($S18:$AB18)=0,"",SUM($S18:$AB18)) -> 83 | AD18: =IF(ISERROR(IF($AC18="","",ROUND(($AC18/$AC$10)*$AD$10,2))),"",IF($AC18="","",ROUND(($AC18/$AC$10)*$AD$10,2))) -> 92.22 | AE18: =IF($AD18="","",ROUND($AD18*$AE$10,2)) -> 46.11 | AF18: 50 | AG18: =IF(ISERROR(IF($AF18="","",ROUND(($AF18/$AF$10)*$AG$10,2))),"",IF($AF18="","",ROUND(($AF18/$AF$10)*$AG$10,2))) -> 100 | AH18: =IF($AG18="","",ROUND($AG18*$AH$10,2)) -> 20 | AI18: =IF(ISERROR(IF($AF18="","",ROUND(SUM($R18,$AE18,$AH18),2))),"",IF($AF18="","",ROUND(SUM($R18,$AE18,$AH18),2))) -> 91.71 | AJ18: =IF(ISERROR(IF($AF18="","",VLOOKUP(AI18,TRANSMUTATION_TABLE,4,TRUE))),"",IF($AF18="","",VLOOKUP(AI18,TRANSMUTATION_TABLE,4,TRUE))) -> 94
A19: 8 | B19: ='INPUT DATA'!B19 -> Infante, James Mendez | D19: 0 | F19: 6 | G19: 9 | H19: 4 | I19: 7 | J19: 10 | K19: 7 | L19: 7 | P19: =IF(COUNT($F19:$O19)=0,"",SUM($F19:$O19)) -> 50 | Q19: =IF(ISERROR(IF($P19="","",ROUND(($P19/$P$10)*$Q$10,2))),"",IF($P19="","",ROUND(($P19/$P$10)*$Q$10,2))) -> 66.67 | R19: =IF($Q19="","",ROUND($Q19*$R$10,2)) -> 20 | S19: 10 | T19: 5 | U19: 7 | V19: 10 | W19: 16 | X19: 9 | AC19: =IF(COUNT($S19:$AB19)=0,"",SUM($S19:$AB19)) -> 57 | AD19: =IF(ISERROR(IF($AC19="","",ROUND(($AC19/$AC$10)*$AD$10,2))),"",IF($AC19="","",ROUND(($AC19/$AC$10)*$AD$10,2))) -> 63.33 | AE19: =IF($AD19="","",ROUND($AD19*$AE$10,2)) -> 31.67 | AF19: 44 | AG19: =IF(ISERROR(IF($AF19="","",ROUND(($AF19/$AF$10)*$AG$10,2))),"",IF($AF19="","",ROUND(($AF19/$AF$10)*$AG$10,2))) -> 88 | AH19: =IF($AG19="","",ROUND($AG19*$AH$10,2)) -> 17.6 | AI19: =IF(ISERROR(IF($AF19="","",ROUND(SUM($R19,$AE19,$AH19),2))),"",IF($AF19="","",ROUND(SUM($R19,$AE19,$AH19),2))) -> 69.27 | AJ19: =IF(ISERROR(IF($AF19="","",VLOOKUP(AI19,TRANSMUTATION_TABLE,4,TRUE))),"",IF($AF19="","",VLOOKUP(AI19,TRANSMUTATION_TABLE,4,TRUE))) -> 80
A20: 9 | B20: ='INPUT DATA'!B20 -> Lacson John Red Hernandez | F20: 7 | G20: 9 | H20: 9 | I20: 5 | J20: 9 | K20: 7 | L20: 6 | P20: =IF(COUNT($F20:$O20)=0,"",SUM($F20:$O20)) -> 52 | Q20: =IF(ISERROR(IF($P20="","",ROUND(($P20/$P$10)*$Q$10,2))),"",IF($P20="","",ROUND(($P20/$P$10)*$Q$10,2))) -> 69.33 | R20: =IF($Q20="","",ROUND($Q20*$R$10,2)) -> 20.8 | S20: 20 | T20: 8 | U20: 7 | V20: 10 | W20: 17 | X20: 9 | AC20: =IF(COUNT($S20:$AB20)=0,"",SUM($S20:$AB20)) -> 71 | AD20: =IF(ISERROR(IF($AC20="","",ROUND(($AC20/$AC$10)*$AD$10,2))),"",IF($AC20="","",ROUND(($AC20/$AC$10)*$AD$10,2))) -> 78.89 | AE20: =IF($AD20="","",ROUND($AD20*$AE$10,2)) -> 39.45 | AF20: 40 | AG20: =IF(ISERROR(IF($AF20="","",ROUND(($AF20/$AF$10)*$AG$10,2))),"",IF($AF20="","",ROUND(($AF20/$AF$10)*$AG$10,2))) -> 80 | AH20: =IF($AG20="","",ROUND($AG20*$AH$10,2)) -> 16 | AI20: =IF(ISERROR(IF($AF20="","",ROUND(SUM($R20,$AE20,$AH20),2))),"",IF($AF20="","",ROUND(SUM($R20,$AE20,$AH20),2))) -> 76.25 | AJ20: =IF(ISERROR(IF($AF20="","",VLOOKUP(AI20,TRANSMUTATION_TABLE,4,TRUE))),"",IF($AF20="","",VLOOKUP(AI20,TRANSMUTATION_TABLE,4,TRUE))) -> 85
A21: 10 | B21: ='INPUT DATA'!B21 -> Limin,Jaslan Mangalindan | F21: 7 | G21: 9 | H21: 14 | I21: 5 | J21: 8 | K21: 7 | L21: 6 | P21: =IF(COUNT($F21:$O21)=0,"",SUM($F21:$O21)) -> 56 | Q21: =IF(ISERROR(IF($P21="","",ROUND(($P21/$P$10)*$Q$10,2))),"",IF($P21="","",ROUND(($P21/$P$10)*$Q$10,2))) -> 74.67 | R21: =IF($Q21="","",ROUND($Q21*$R$10,2)) -> 22.4 | S21: 10 | T21: 5 | U21: 8 | V21: 10 | W21: 17 | X21: 8 | AC21: =IF(COUNT($S21:$AB21)=0,"",SUM($S21:$AB21)) -> 58 | AD21: =IF(ISERROR(IF($AC21="","",ROUND(($AC21/$AC$10)*$AD$10,2))),"",IF($AC21="","",ROUND(($AC21/$AC$10)*$AD$10,2))) -> 64.44 | AE21: =IF($AD21="","",ROUND($AD21*$AE$10,2)) -> 32.22 | AF21: 47 | AG21: =IF(ISERROR(IF($AF21="","",ROUND(($AF21/$AF$10)*$AG$10,2))),"",IF($AF21="","",ROUND(($AF21/$AF$10)*$AG$10,2))) -> 94 | AH21: =IF($AG21="","",ROUND($AG21*$AH$10,2)) -> 18.8 | AI21: =IF(ISERROR(IF($AF21="","",ROUND(SUM($R21,$AE21,$AH21),2))),"",IF($AF21="","",ROUND(SUM($R21,$AE21,$AH21),2))) -> 73.42 | AJ21: =IF(ISERROR(IF($AF21="","",VLOOKUP(AI21,TRANSMUTATION_TABLE,4,TRUE))),"",IF($AF21="","",VLOOKUP(AI21,TRANSMUTATION_TABLE,4,TRUE))) -> 83
A22: 11 | B22: ='INPUT DATA'!B22 -> Lusung, Yuan Lein Rodriguez | D22: 0 | F22: 8 | G22: 9 | H22: 15 | I22: 8 | J22: 10 | K22: 8 | L22: 9 | P22: =IF(COUNT($F22:$O22)=0,"",SUM($F22:$O22)) -> 67 | Q22: =IF(ISERROR(IF($P22="","",ROUND(($P22/$P$10)*$Q$10,2))),"",IF($P22="","",ROUND(($P22/$P$10)*$Q$10,2))) -> 89.33 | R22: =IF($Q22="","",ROUND($Q22*$R$10,2)) -> 26.8 | S22: 18 | T22: 5 | U22: 8 | V22: 20 | W22: 19 | X22: 9 | AC22: =IF(COUNT($S22:$AB22)=0,"",SUM($S22:$AB22)) -> 79 | AD22: =IF(ISERROR(IF($AC22="","",ROUND(($AC22/$AC$10)*$AD$10,2))),"",IF($AC22="","",ROUND(($AC22/$AC$10)*$AD$10,2))) -> 87.78 | AE22: =IF($AD22="","",ROUND($AD22*$AE$10,2)) -> 43.89 | AF22: 46 | AG22: =IF(ISERROR(IF($AF22="","",ROUND(($AF22/$AF$10)*$AG$10,2))),"",IF($AF22="","",ROUND(($AF22/$AF$10)*$AG$10,2))) -> 92 | AH22: =IF($AG22="","",ROUND($AG22*$AH$10,2)) -> 18.4 | AI22: =IF(ISERROR(IF($AF22="","",ROUND(SUM($R22,$AE22,$AH22),2))),"",IF($AF22="","",ROUND(SUM($R22,$AE22,$AH22),2))) -> 89.09 | AJ22: =IF(ISERROR(IF($AF22="","",VLOOKUP(AI22,TRANSMUTATION_TABLE,4,TRUE))),"",IF($AF22="","",VLOOKUP(AI22,TRANSMUTATION_TABLE,4,TRUE))) -> 93
A23: 12 | B23: ='INPUT DATA'!B23 -> Macaspac, Matteo Dho Arcilla | F23: 8 | G23: 9 | H23: 13 | I23: 8 | J23: 9 | K23: 8 | L23: 8 | P23: =IF(COUNT($F23:$O23)=0,"",SUM($F23:$O23)) -> 63 | Q23: =IF(ISERROR(IF($P23="","",ROUND(($P23/$P$10)*$Q$10,2))),"",IF($P23="","",ROUND(($P23/$P$10)*$Q$10,2))) -> 84 | R23: =IF($Q23="","",ROUND($Q23*$R$10,2)) -> 25.2 | S23: 19 | T23: 8 | U23: 8 | V23: 20 | W23: 17 | X23: 9 | AC23: =IF(COUNT($S23:$AB23)=0,"",SUM($S23:$AB23)) -> 81 | AD23: =IF(ISERROR(IF($AC23="","",ROUND(($AC23/$AC$10)*$AD$10,2))),"",IF($AC23="","",ROUND(($AC23/$AC$10)*$AD$10,2))) -> 90 | AE23: =IF($AD23="","",ROUND($AD23*$AE$10,2)) -> 45 | AF23: 40 | AG23: =IF(ISERROR(IF($AF23="","",ROUND(($AF23/$AF$10)*$AG$10,2))),"",IF($AF23="","",ROUND(($AF23/$AF$10)*$AG$10,2))) -> 80 | AH23: =IF($AG23="","",ROUND($AG23*$AH$10,2)) -> 16 | AI23: =IF(ISERROR(IF($AF23="","",ROUND(SUM($R23,$AE23,$AH23),2))),"",IF($AF23="","",ROUND(SUM($R23,$AE23,$AH23),2))) -> 86.2 | AJ23: =IF(ISERROR(IF($AF23="","",VLOOKUP(AI23,TRANSMUTATION_TABLE,4,TRUE))),"",IF($AF23="","",VLOOKUP(AI23,TRANSMUTATION_TABLE,4,TRUE))) -> 91
A24: 13 | B24: ='INPUT DATA'!B24 -> Miranda, Franz | F24: 8 | G24: 9 | H24: 11 | I24: 6 | J24: 9 | K24: 8 | L24: 9 | P24: =IF(COUNT($F24:$O24)=0,"",SUM($F24:$O24)) -> 60 | Q24: =IF(ISERROR(IF($P24="","",ROUND(($P24/$P$10)*$Q$10,2))),"",IF($P24="","",ROUND(($P24/$P$10)*$Q$10,2))) -> 80 | R24: =IF($Q24="","",ROUND($Q24*$R$10,2)) -> 24 | S24: 18 | T24: 10 | U24: 8 | V24: 20 | W24: 19 | X24: 9 | AC24: =IF(COUNT($S24:$AB24)=0,"",SUM($S24:$AB24)) -> 84 | AD24: =IF(ISERROR(IF($AC24="","",ROUND(($AC24/$AC$10)*$AD$10,2))),"",IF($AC24="","",ROUND(($AC24/$AC$10)*$AD$10,2))) -> 93.33 | AE24: =IF($AD24="","",ROUND($AD24*$AE$10,2)) -> 46.67 | AF24: 43 | AG24: =IF(ISERROR(IF($AF24="","",ROUND(($AF24/$AF$10)*$AG$10,2))),"",IF($AF24="","",ROUND(($AF24/$AF$10)*$AG$10,2))) -> 86 | AH24: =IF($AG24="","",ROUND($AG24*$AH$10,2)) -> 17.2 | AI24: =IF(ISERROR(IF($AF24="","",ROUND(SUM($R24,$AE24,$AH24),2))),"",IF($AF24="","",ROUND(SUM($R24,$AE24,$AH24),2))) -> 87.87 | AJ24: =IF(ISERROR(IF($AF24="","",VLOOKUP(AI24,TRANSMUTATION_TABLE,4,TRUE))),"",IF($AF24="","",VLOOKUP(AI24,TRANSMUTATION_TABLE,4,TRUE))) -> 92
A25: 14 | B25: ='INPUT DATA'!B25 -> Nayanggazohann,Cedy | F25: 7 | G25: 10 | H25: 10 | I25: 9 | J25: 10 | K25: 7 | L25: 7 | P25: =IF(COUNT($F25:$O25)=0,"",SUM($F25:$O25)) -> 60 | Q25: =IF(ISERROR(IF($P25="","",ROUND(($P25/$P$10)*$Q$10,2))),"",IF($P25="","",ROUND(($P25/$P$10)*$Q$10,2))) -> 80 | R25: =IF($Q25="","",ROUND($Q25*$R$10,2)) -> 24 | S25: 20 | T25: 5 | U25: 8 | V25: 18 | W25: 10 | X25: 7 | AC25: =IF(COUNT($S25:$AB25)=0,"",SUM($S25:$AB25)) -> 68 | AD25: =IF(ISERROR(IF($AC25="","",ROUND(($AC25/$AC$10)*$AD$10,2))),"",IF($AC25="","",ROUND(($AC25/$AC$10)*$AD$10,2))) -> 75.56 | AE25: =IF($AD25="","",ROUND($AD25*$AE$10,2)) -> 37.78 | AF25: 45 | AG25: =IF(ISERROR(IF($AF25="","",ROUND(($AF25/$AF$10)*$AG$10,2))),"",IF($AF25="","",ROUND(($AF25/$AF$10)*$AG$10,2))) -> 90 | AH25: =IF($AG25="","",ROUND($AG25*$AH$10,2)) -> 18 | AI25: =IF(ISERROR(IF($AF25="","",ROUND(SUM($R25,$AE25,$AH25),2))),"",IF($AF25="","",ROUND(SUM($R25,$AE25,$AH25),2))) -> 79.78 | AJ25: =IF(ISERROR(IF($AF25="","",VLOOKUP(AI25,TRANSMUTATION_TABLE,4,TRUE))),"",IF($AF25="","",VLOOKUP(AI25,TRANSMUTATION_TABLE,4,TRUE))) -> 87
A26: 15 | B26: ='INPUT DATA'!B26 -> Quiambao, Harvin Miranda | F26: 8 | G26: 10 | H26: 15 | I26: 9 | J26: 10 | K26: 9 | L26: 9 | P26: =IF(COUNT($F26:$O26)=0,"",SUM($F26:$O26)) -> 70 | Q26: =IF(ISERROR(IF($P26="","",ROUND(($P26/$P$10)*$Q$10,2))),"",IF($P26="","",ROUND(($P26/$P$10)*$Q$10,2))) -> 93.33 | R26: =IF($Q26="","",ROUND($Q26*$R$10,2)) -> 28 | S26: 20 | T26: 9 | U26: 9 | V26: 10 | W26: 18 | X26: 9 | AC26: =IF(COUNT($S26:$AB26)=0,"",SUM($S26:$AB26)) -> 75 | AD26: =IF(ISERROR(IF($AC26="","",ROUND(($AC26/$AC$10)*$AD$10,2))),"",IF($AC26="","",ROUND(($AC26/$AC$10)*$AD$10,2))) -> 83.33 | AE26: =IF($AD26="","",ROUND($AD26*$AE$10,2)) -> 41.67 | AF26: 48 | AG26: =IF(ISERROR(IF($AF26="","",ROUND(($AF26/$AF$10)*$AG$10,2))),"",IF($AF26="","",ROUND(($AF26/$AF$10)*$AG$10,2))) -> 96 | AH26: =IF($AG26="","",ROUND($AG26*$AH$10,2)) -> 19.2 | AI26: =IF(ISERROR(IF($AF26="","",ROUND(SUM($R26,$AE26,$AH26),2))),"",IF($AF26="","",ROUND(SUM($R26,$AE26,$AH26),2))) -> 88.87 | AJ26: =IF(ISERROR(IF($AF26="","",VLOOKUP(AI26,TRANSMUTATION_TABLE,4,TRUE))),"",IF($AF26="","",VLOOKUP(AI26,TRANSMUTATION_TABLE,4,TRUE))) -> 93
A27: 16 | B27: ='INPUT DATA'!B27 -> Reyes Mhon Vincent Corpuz | F27: 7 | G27: 8 | H27: 12 | I27: 9 | J27: 6 | K27: 7 | L27: 7 | P27: =IF(COUNT($F27:$O27)=0,"",SUM($F27:$O27)) -> 56 | Q27: =IF(ISERROR(IF($P27="","",ROUND(($P27/$P$10)*$Q$10,2))),"",IF($P27="","",ROUND(($P27/$P$10)*$Q$10,2))) -> 74.67 | R27: =IF($Q27="","",ROUND($Q27*$R$10,2)) -> 22.4 | S27: 10 | T27: 5 | U27: 7 | V27: 19 | W27: 19 | X27: 9 | AC27: =IF(COUNT($S27:$AB27)=0,"",SUM($S27:$AB27)) -> 69 | AD27: =IF(ISERROR(IF($AC27="","",ROUND(($AC27/$AC$10)*$AD$10,2))),"",IF($AC27="","",ROUND(($AC27/$AC$10)*$AD$10,2))) -> 76.67 | AE27: =IF($AD27="","",ROUND($AD27*$AE$10,2)) -> 38.34 | AF27: 45 | AG27: =IF(ISERROR(IF($AF27="","",ROUND(($AF27/$AF$10)*$AG$10,2))),"",IF($AF27="","",ROUND(($AF27/$AF$10)*$AG$10,2))) -> 90 | AH27: =IF($AG27="","",ROUND($AG27*$AH$10,2)) -> 18 | AI27: =IF(ISERROR(IF($AF27="","",ROUND(SUM($R27,$AE27,$AH27),2))),"",IF($AF27="","",ROUND(SUM($R27,$AE27,$AH27),2))) -> 78.74 | AJ27: =IF(ISERROR(IF($AF27="","",VLOOKUP(AI27,TRANSMUTATION_TABLE,4,TRUE))),"",IF($AF27="","",VLOOKUP(AI27,TRANSMUTATION_TABLE,4,TRUE))) -> 86
A28: 17 | B28: ='INPUT DATA'!B28 -> Meneje, Gelo S. | F28: 8 | G28: 9 | H28: 14 | I28: 8 | J28: 3 | K28: 7 | L28: 8 | P28: =IF(COUNT($F28:$O28)=0,"",SUM($F28:$O28)) -> 57 | Q28: =IF(ISERROR(IF($P28="","",ROUND(($P28/$P$10)*$Q$10,2))),"",IF($P28="","",ROUND(($P28/$P$10)*$Q$10,2))) -> 76 | R28: =IF($Q28="","",ROUND($Q28*$R$10,2)) -> 22.8 | S28: 20 | T28: 5 | U28: 8 | V28: 19 | W28: 17 | X28: 9 | AC28: =IF(COUNT($S28:$AB28)=0,"",SUM($S28:$AB28)) -> 78 | AD28: =IF(ISERROR(IF($AC28="","",ROUND(($AC28/$AC$10)*$AD$10,2))),"",IF($AC28="","",ROUND(($AC28/$AC$10)*$AD$10,2))) -> 86.67 | AE28: =IF($AD28="","",ROUND($AD28*$AE$10,2)) -> 43.34 | AF28: 45 | AG28: =IF(ISERROR(IF($AF28="","",ROUND(($AF28/$AF$10)*$AG$10,2))),"",IF($AF28="","",ROUND(($AF28/$AF$10)*$AG$10,2))) -> 90 | AH28: =IF($AG28="","",ROUND($AG28*$AH$10,2)) -> 18 | AI28: =IF(ISERROR(IF($AF28="","",ROUND(SUM($R28,$AE28,$AH28),2))),"",IF($AF28="","",ROUND(SUM($R28,$AE28,$AH28),2))) -> 84.14 | AJ28: =IF(ISERROR(IF($AF28="","",VLOOKUP(AI28,TRANSMUTATION_TABLE,4,TRUE))),"",IF($AF28="","",VLOOKUP(AI28,TRANSMUTATION_TABLE,4,TRUE))) -> 90
A29: 18 | B29: ='INPUT DATA'!B29 -> Serrano, Aaron Kiel Dabu | F29: 8 | G29: 10 | H29: 14 | I29: 10 | J29: 10 | K29: 7 | L29: 7 | P29: =IF(COUNT($F29:$O29)=0,"",SUM($F29:$O29)) -> 66 | Q29: =IF(ISERROR(IF($P29="","",ROUND(($P29/$P$10)*$Q$10,2))),"",IF($P29="","",ROUND(($P29/$P$10)*$Q$10,2))) -> 88 | R29: =IF($Q29="","",ROUND($Q29*$R$10,2)) -> 26.4 | S29: 20 | T29: 10 | U29: 7 | V29: 10 | W29: 18 | X29: 9 | AC29: =IF(COUNT($S29:$AB29)=0,"",SUM($S29:$AB29)) -> 74 | AD29: =IF(ISERROR(IF($AC29="","",ROUND(($AC29/$AC$10)*$AD$10,2))),"",IF($AC29="","",ROUND(($AC29/$AC$10)*$AD$10,2))) -> 82.22 | AE29: =IF($AD29="","",ROUND($AD29*$AE$10,2)) -> 41.11 | AF29: 49 | AG29: =IF(ISERROR(IF($AF29="","",ROUND(($AF29/$AF$10)*$AG$10,2))),"",IF($AF29="","",ROUND(($AF29/$AF$10)*$AG$10,2))) -> 98 | AH29: =IF($AG29="","",ROUND($AG29*$AH$10,2)) -> 19.6 | AI29: =IF(ISERROR(IF($AF29="","",ROUND(SUM($R29,$AE29,$AH29),2))),"",IF($AF29="","",ROUND(SUM($R29,$AE29,$AH29),2))) -> 87.11 | AJ29: =IF(ISERROR(IF($AF29="","",VLOOKUP(AI29,TRANSMUTATION_TABLE,4,TRUE))),"",IF($AF29="","",VLOOKUP(AI29,TRANSMUTATION_TABLE,4,TRUE))) -> 91
A30: 19 | B30: ='INPUT DATA'!B30 -> Villamayon, Jasper Supang | F30: 8 | G30: 10 | H30: 13 | I30: 7 | J30: 6 | K30: 6 | L30: 5 | P30: =IF(COUNT($F30:$O30)=0,"",SUM($F30:$O30)) -> 55 | Q30: =IF(ISERROR(IF($P30="","",ROUND(($P30/$P$10)*$Q$10,2))),"",IF($P30="","",ROUND(($P30/$P$10)*$Q$10,2))) -> 73.33 | R30: =IF($Q30="","",ROUND($Q30*$R$10,2)) -> 22 | S30: 10 | T30: 5 | U30: 7 | V30: 10 | W30: 18 | X30: 8 | AC30: =IF(COUNT($S30:$AB30)=0,"",SUM($S30:$AB30)) -> 58 | AD30: =IF(ISERROR(IF($AC30="","",ROUND(($AC30/$AC$10)*$AD$10,2))),"",IF($AC30="","",ROUND(($AC30/$AC$10)*$AD$10,2))) -> 64.44 | AE30: =IF($AD30="","",ROUND($AD30*$AE$10,2)) -> 32.22 | AF30: 40 | AG30: =IF(ISERROR(IF($AF30="","",ROUND(($AF30/$AF$10)*$AG$10,2))),"",IF($AF30="","",ROUND(($AF30/$AF$10)*$AG$10,2))) -> 80 | AH30: =IF($AG30="","",ROUND($AG30*$AH$10,2)) -> 16 | AI30: =IF(ISERROR(IF($AF30="","",ROUND(SUM($R30,$AE30,$AH30),2))),"",IF($AF30="","",ROUND(SUM($R30,$AE30,$AH30),2))) -> 70.22 | AJ30: =IF(ISERROR(IF($AF30="","",VLOOKUP(AI30,TRANSMUTATION_TABLE,4,TRUE))),"",IF($AF30="","",VLOOKUP(AI30,TRANSMUTATION_TABLE,4,TRUE))) -> 81
